Workbook

Sheet ApprovedBudget
A1: Approved Budget - Monthly OPEX
A3: Department | B3: Cost Center | C3: Account / line | D3: CAPEX/OPEX | E3: Jan | F3: Feb | G3: Mar | H3: Apr | I3: May | J3: Jun | K3: Jul | L3: Aug | M3: Sep | N3: Oct | O3: Nov | P3: Dec | Q3: FY Total
A4: OPEX - Payroll
A5: Sales and Marketing | B5: Sales and Marketing | C5: Payroll | D5: OPEX | E5: 880387.75 | F5: 880387.75 | G5: 880387.75 | H5: 880387.75 | I5: 880387.75 | J5: 880387.75 | K5: 880387.75 | L5: 880387.75 | M5: 923100.26 | N5: 923100.26 | O5: 1179375.3 | P5: 1179375.3 | Q5: =SUM(E5:P5) -> 11248053
A6: Customer Success | B6: Customer Success | C6: Payroll | D6: OPEX | E6: 125860 | F6: 125860 | G6: 125860 | H6: 125860 | I6: 151032 | J6: 151032 | K6: 151032 | L6: 151032 | M6: 151032 | N6: 151032 | O6: 125860 | P6: 125860 | Q6: =SUM(E6:P6) -> 1661352
A7: Supply Chain | B7: Warehouse | C7: Payroll | D7: OPEX | E7: 250020 | F7: 250020 | G7: 250020 | H7: 250020 | I7: 250020 | J7: 250020 | K7: 250020 | L7: 250020 | M7: 277360 | N7: 277360 | O7: 523420 | P7: 523420 | Q7: =SUM(E7:P7) -> 3601720
A8: Aftersales | B8: Aftersales | C8: Payroll | D8: OPEX | E8: 40117.875 | F8: 40117.875 | G8: 40117.875 | H8: 40117.875 | I8: 40117.875 | J8: 40117.875 | K8: 40117.875 | L8: 40117.875 | M8: 53490.5 | N8: 53490.5 | O8: 93608.375 | P8: 93608.375 | Q8: =SUM(E8:P8) -> 615140.75
A9: Product | B9: Product | C9: Payroll | D9: OPEX | E9: 40117.875 | F9: 40117.875 | G9: 40117.875 | H9: 40117.875 | I9: 40117.875 | J9: 40117.875 | K9: 40117.875 | L9: 40117.875 | M9: 53490.5 | N9: 53490.5 | O9: 93608.375 | P9: 93608.375 | Q9: 615140.75
A10: RideBox | B10: RideBox | C10: Payroll | D10: OPEX | E10: 0 | F10: 0 | G10: 0 | H10: 0 | I10: 125860 | J10: 226548 | K10: 276892 | L10: 302064 | M10: 377580 | N10: 402752 | O10: 478268 | P10: 553784 | Q10: =SUM(E10:P10) -> 2743748
A11: Technology | B11: Technology | C11: Payroll | D11: OPEX | E11: 631987.45 | F11: 631987.45 | G11: 631987.45 | H11: 696587.45 | I11: 890387.45 | J11: 1277987.5 | K11: 1536387.5 | L11: 1794787.5 | M11: 1859387.5 | N11: 2053187.5 | O11: 2053187.5 | P11: 2053187.5 | Q11: =SUM(E11:P11) -> 16111049
A12: Finance and Accounting | B12: Finance and Accounting | C12: Payroll | D12: OPEX | E12: 633750 | F12: 633750 | G12: 974464.29 | H12: 340714.29 | I12: 390964.29 | J12: 390964.29 | K12: 390964.29 | L12: 390964.29 | M12: 390964.29 | N12: 441214.29 | O12: 441214.29 | P12: 441214.29 | Q12: =SUM(E12:P12) -> 5861142.9
A13: Admin | B13: Admin | C13: Payroll | D13: OPEX | E13: 57000 | F13: 57000 | G13: 57000 | H13: 57000 | I13: 61750 | J13: 61750 | K13: 61750 | L13: 61750 | M13: 61750 | N13: 61750 | O13: 61750 | P13: 61750 | Q13: =SUM(E13:P13) -> 722000
A14: HR | B14: HR | C14: Payroll | D14: OPEX | E14: 154375 | F14: 154375 | G14: 154375 | H14: 154375 | I14: 154375 | J14: 154375 | K14: 154375 | L14: 154375 | M14: 154375 | N14: 154375 | O14: 154375 | P14: 154375 | Q14: =SUM(E14:P14) -> 1852500
A15: Compliance and Risk | B15: Compliance and Risk | C15: Payroll | D15: OPEX | E15: 109326.4 | F15: 109326.4 | G15: 109326.4 | H15: 109326.4 | I15: 153993.07 | J15: 214659.73 | K15: 214659.73 | L15: 275326.4 | M15: 275326.4 | N15: 275326.4 | O15: 335993.07 | P15: 335993.07 | Q15: =SUM(E15:P15) -> 2518583.5
C16: TOTAL OPEX - Payroll | E16: =SUM(E5:E15) -> 2922942.4 | F16: =SUM(F5:F15) -> 2922942.4 | G16: =SUM(G5:G15) -> 3263656.6 | H16: =SUM(H5:H15) -> 2694506.6 | I16: =SUM(I5:I15) -> 3139005.3 | J16: =SUM(J5:J15) -> 3687960 | K16: =SUM(K5:K15) -> 3996704 | L16: =SUM(L5:L15) -> 4340942.6 | ... P16: =SUM(P5:P15) -> 5616175.8 | Q16: =SUM(E16:P16) -> 47550430
A18: OPEX - Non-payroll
A19: Sales and Marketing | B19: Sales | C19: CRM / sales pipeline tool | D19: OPEX | E19: 2000 | F19: 2000 | G19: 2000 | H19: 2000 | I19: 2000 | J19: 2000 | K19: 2000 | L19: 2000 | M19: 2000 | N19: 2000 | O19: 2000 | P19: 2000 | Q19: =SUM(E19:P19) -> 24000
A20: Sales and Marketing | B20: Sales | C20: Canva | D20: OPEX | E20: 1000 | F20: 1000 | G20: 1000 | H20: 1000 | I20: 1000 | J20: 1000 | K20: 1000 | L20: 1000 | M20: 1000 | N20: 1000 | O20: 1000 | P20: 1000 | Q20: =SUM(E20:P20) -> 12000
A21: Sales and Marketing | B21: Sales | C21: Lemlist | D21: OPEX | E21: 6000 | F21: 6000 | G21: 6000 | H21: 6000 | I21: 6000 | J21: 6000 | K21: 6000 | L21: 6000 | M21: 6000 | N21: 6000 | O21: 6000 | P21: 6000 | Q21: =SUM(E21:P21) -> 72000
A22: Sales and Marketing | B22: Sales | C22: Digital Ads | D22: OPEX | E22: 20000 | F22: 20000 | G22: 20000 | H22: 20000 | I22: 20000 | J22: 20000 | K22: 20000 | L22: 20000 | M22: 20000 | N22: 20000 | O22: 20000 | P22: 20000 | Q22: =SUM(E22:P22) -> 240000
A23: Sales and Marketing | B23: Marketing | C23: Marketing Collaterals | D23: OPEX | E23: 15000 | F23: 15000 | G23: 15000 | H23: 15000 | I23: 15000 | J23: 15000 | K23: 15000 | L23: 15000 | M23: 15000 | N23: 15000 | O23: 15000 | P23: 15000 | Q23: =SUM(E23:P23) -> 180000
A24: Sales and Marketing | B24: Marketing | C24: Media Subscriptions | D24: OPEX | E24: 5000 | F24: 5000 | G24: 5000 | H24: 5000 | I24: 25000 | J24: 5000 | K24: 5000 | L24: 5000 | M24: 5000 | N24: 5000 | O24: 5000 | P24: 5000 | Q24: =SUM(E24:P24) -> 80000
A25: Sales and Marketing | B25: Marketing | C25: Tools & Equipments | D25: OPEX | E25: - | F25: - | G25: - | H25: - | I25: 100000 | J25: - | K25: - | L25: - | M25: - | N25: - | O25: - | P25: - | Q25: =SUM(E25:P25) -> 100000
A26: Sales and Marketing | B26: Marketing | C26: Lead generation giveaways | D26: OPEX | E26: 26340 | F26: 26340 | G26: 26340 | H26: 26340 | I26: 26340 | J26: 26340 | K26: 26340 | L26: 26340 | M26: 26340 | N26: 26340 | O26: 26340 | P26: 26340 | Q26: =SUM(E26:P26) -> 316080
A27: Sales and Marketing | B27: Marketing | C27: Rider onboarding Kit | D27: OPEX | E27: 13800 | F27: 21000 | G27: 33000 | H27: 45000 | I27: 66000 | J27: 78000 | K27: 84000 | L27: 99000 | M27: 75000 | N27: 120000 | O27: 270000 | P27: 180000 | Q27: =SUM(E27:P27) -> 1084800
A28: Sales and Marketing | B28: Marketing | C28: Representation | D28: OPEX | E28: 30000 | F28: 30000 | G28: 30000 | H28: 30000 | I28: 30000 | J28: 30000 | K28: 30000 | L28: 30000 | M28: 30000 | N28: 30000 | O28: 30000 | P28: 30000 | Q28: =SUM(E28:P28) -> 360000
A29: Sales and Marketing | B29: Marketing | C29: Events Budget | E29: 100000 | F29: 100000 | G29: 100000 | H29: 100000 | I29: 100000 | J29: 100000 | K29: 100000 | L29: 100000 | M29: 100000 | N29: 100000 | O29: 100000 | P29: 100000 | Q29: =SUM(E29:P29) -> 1200000
A30: Sales and Marketing | B30: Marketing | C30: Helmet | E30: 50600 | F30: 77000 | G30: 121000 | H30: 165000 | I30: 242000 | J30: 286000 | K30: 308000 | L30: 363000 | M30: 275000 | N30: 440000 | O30: 990000 | P30: 660000 | Q30: =SUM(E30:P30) -> 3977600
A31: Sales and Marketing | B31: Marketing | C31: Longsleeves | D31: OPEX | E31: 25300 | F31: 38500 | G31: 60500 | H31: 82500 | I31: 121000 | J31: 143000 | K31: 154000 | L31: 181500 | M31: 137500 | N31: 220000 | O31: 495000 | P31: 330000 | Q31: =SUM(E31:P31) -> 1988800
A32: Sales and Marketing | B32: Marketing | C32: Miscellaneous | D32: OPEX | E32: 20000 | F32: 20000 | G32: 20000 | H32: 20000 | I32: 20000 | J32: 20000 | K32: 20000 | L32: 20000 | M32: 20000 | N32: 20000 | O32: 20000 | P32: 20000 | Q32: =SUM(E32:P32) -> 240000
C33: Subtotal - Sales and Marketing | E33: =SUM(E19:E32) -> 315040 | F33: =SUM(F19:F32) -> 361840 | G33: =SUM(G19:G32) -> 439840 | H33: =SUM(H19:H32) -> 517840 | I33: =SUM(I19:I32) -> 774340 | J33: =SUM(J19:J32) -> 732340 | K33: =SUM(K19:K32) -> 771340 | L33: =SUM(L19:L32) -> 868840 | ... P33: =SUM(P19:P32) -> 1395340 | Q33: =SUM(E33:P33) -> 9875280
A34: Customer Success | B34: Customer Success | C34: CRM | D34: OPEX | E34: - | F34: - | G34: - | H34: - | I34: - | J34: - | K34: - | L34: - | M34: 350000 | N34: - | O34: - | P34: - | Q34: =SUM(E34:P34) -> 350000
A35: Customer Success | B35: Customer Success | C35: AI Agent allowance | E35: 22500 | F35: 22500 | G35: 22500 | H35: 22500 | I35: 22500 | J35: 22500 | K35: 22500 | L35: 22500 | M35: 22500 | N35: 22500 | O35: 22500 | P35: 22500 | Q35: =SUM(E35:P35) -> 270000
A36: Customer Success | B36: Customer Success | C36: Manpower Agency | E36: 40000 | F36: 40000 | G36: 40000 | H36: 40000 | I36: 40000 | J36: 40000 | K36: 40000 | L36: 40000 | M36: 40000 | N36: 40000 | O36: 40000 | P36: 40000 | Q36: =SUM(E36:P36) -> 480000
A37: Customer Success | B37: Customer Success | C37: Miscellaneous | D37: OPEX | E37: 5000 | F37: 5000 | G37: 5000 | H37: 5000 | I37: 5000 | J37: 5000 | K37: 5000 | L37: 5000 | M37: 5000 | N37: 5000 | O37: 5000 | P37: 5000 | Q37: =SUM(E37:P37) -> 60000
C38: Subtotal - Customer Success | E38: =SUM(E34:E37) -> 67500 | F38: =SUM(F34:F37) -> 67500 | G38: =SUM(G34:G37) -> 67500 | H38: =SUM(H34:H37) -> 67500 | I38: =SUM(I34:I37) -> 67500 | J38: =SUM(J34:J37) -> 67500 | K38: =SUM(K34:K37) -> 67500 | L38: =SUM(L34:L37) -> 67500 | ... P38: =SUM(P34:P37) -> 67500 | Q38: =SUM(E38:P38) -> 1160000
A39: Supply Chain | B39: Procurement | C39: Electricity - battery charging | D39: OPEX | E39: 2579 | F39: 3967 | G39: 7340 | H39: 7411 | I39: 7855 | J39: 7983 | K39: 8238 | L39: 8338 | M39: 8448 | N39: 8820 | O39: 11167 | P39: 11332 | Q39: =SUM(E39:P39) -> 93478
A40: Supply Chain | B40: Warehouse | C40: Warehouse rent | D40: OPEX | E40: 240306 | F40: 228698 | G40: 228698 | H40: 228698 | I40: 686097 | J40: 686092 | K40: 686092 | L40: 686092 | M40: 686092 | N40: 686092 | O40: 686092 | P40: 686092 | Q40: =SUM(E40:P40) -> 6415141
A41: Supply Chain | B41: Warehouse | C41: Guard salary | D41: OPEX | E41: 134572 | F41: 128071 | G41: 128071 | H41: 128071 | I41: 384214 | J41: 384212 | K41: 384212 | L41: 384212 | M41: 384212 | N41: 384212 | O41: 384212 | P41: 384212 | Q41: =SUM(E41:P41) -> 3592483
A42: Supply Chain | B42: Warehouse | C42: Electricity / water / internet | D42: OPEX | E42: 48061 | F42: 45740 | G42: 45740 | H42: 45740 | I42: 137219 | J42: 137218 | K42: 137218 | L42: 137218 | M42: 137218 | N42: 137218 | O42: 137218 | P42: 137218 | Q42: =SUM(E42:P42) -> 1283026
...

Sheet HC
A1: Department | E1: Jan-2026 | F1: Feb-2026 | G1: Mar-2026 | H1: Apr-2026 | I1: May-2026 | J1: Jun-2026 | K1: Jul-2026 | L1: Aug-2026 | M1: Sep-2026 | N1: Oct-2026 | O1: Nov-2026 | P1: Dec-2026
A2: Sales & Marketing | E2: 8 | F2: 8 | G2: 8 | H2: 8 | I2: 8 | J2: 8 | K2: 8 | L2: 8 | M2: 9 | N2: 9 | O2: 17 | P2: 17 | Q2: Adjust less 2 for Augmentation
A3: AfterSales Center | E3: 3 | F3: 3 | G3: 3 | H3: 3 | I3: 3 | J3: 3 | K3: 3 | L3: 3 | M3: 4 | N3: 4 | O3: 7 | P3: 7
A4: Supply Chain | E4: 3 | F4: 3 | G4: 3 | H4: 3 | I4: 3 | J4: 3 | K4: 3 | L4: 3 | M4: 4 | N4: 4 | O4: 13 | P4: 13 | Q4: Adjust less 2 for Augmentation
A5: Customer Support | E5: 5 | F5: 5 | G5: 5 | H5: 5 | I5: 6 | J5: 6 | K5: 6 | L5: 6 | M5: 6 | N5: 6 | O5: 5 | P5: 5
A7: Station Deployment Lead | B7: Ridebox tribe | C7: Rollout | D7: Now | I7: 1 | J7: 1 | K7: 1 | L7: 1 | M7: 1 | N7: 1 | O7: 1 | P7: 1
A8: RB Service Lead | B8: Ridebox tribe | C8: Service Center | D8: Now | I8: 1 | J8: 1 | K8: 1 | L8: 1 | M8: 1 | N8: 1 | O8: 1 | P8: 1
A9: Station Deployment Manager | B9: Ridebox tribe | C9: Rollout | D9: M2 | I9: 1 | J9: 1 | K9: 1 | L9: 1 | M9: 1 | N9: 1 | O9: 1 | P9: 1
A10: Commercial Ops Lead | B10: Ridebox tribe | C10: Billing & Admin | D10: M2 | I10: 1 | J10: 1 | K10: 1 | L10: 1 | M10: 1 | N10: 1 | O10: 1 | P10: 1
A11: Partners Squad Lead | B11: Ridebox tribe | C11: Billing & Admin | D11: M2 | I11: 1 | J11: 1 | K11: 1 | L11: 1 | M11: 1 | N11: 1 | O11: 1 | P11: 1
A12: RB Network Lead | B12: Ridebox tribe | C12: Monitoring & Field Ops | D12: M2 | J12: 1 | K12: 1 | L12: 1 | M12: 1 | N12: 1 | O12: 1 | P12: 1
A13: Site BD | B13: Ridebox tribe | C13: Rollout | D13: M2 | J13: 1 | K13: 1 | L13: 1 | M13: 1 | N13: 1 | O13: 1 | P13: 1
A14: Site Engineer | B14: Ridebox tribe | C14: Rollout | D14: M2 | J14: 1 | K14: 1 | L14: 1 | M14: 2 | N14: 2 | O14: 2 | P14: 2
A15: Ops Manager | B15: Ridebox tribe | C15: Monitoring & Field Ops | D15: M2 | J15: 1 | K15: 1 | L15: 1 | M15: 1 | N15: 1 | O15: 1 | P15: 1
A16: Network Ops | B16: Ridebox tribe | C16: Monitoring & Field Ops | D16: M3 | K16: 1 | L16: 1 | M16: 1 | N16: 1 | O16: 1 | P16: 1
A17: Field Technician | B17: Ridebox tribe | C17: Monitoring & Field Ops | D17: M3 | K17: 1 | L17: 1 | M17: 1 | N17: 2 | O17: 2 | P17: 2
A18: Battery Technician | B18: Ridebox tribe | C18: Service Center | D18: M3 | L18: 1 | M18: 1 | N18: 1 | O18: 2 | P18: 2
A19: Site Ops | B19: Ridebox tribe | C19: Monitoring & Field Ops | D19: M3 | M19: 1 | N19: 1 | O19: 1 | P19: 1
A20: Hardware Technician | B20: Ridebox tribe | C20: Service Center | D20: M3 | M20: 1 | N20: 1 | O20: 1 | P20: 1
A21: Parts & Inventory | B21: Ridebox tribe | C21: Service Center | D21: M4 | O21: 1 | P21: 1
A22: Billing Analyst | B22: Ridebox tribe | C22: Billing & Admin | D22: M4 | O22: 1 | P22: 1
A23: Site Admin | B23: Ridebox tribe | C23: Billing & Admin | D23: M4 | P23: 1
A24: Business Dev | B24: Ridebox tribe | C24: Billing & Admin | D24: M4 | P24: 1
A25: Partner Integrations | B25: Ridebox tribe | C25: Billing & Admin | D25: M4 | P25: 1
A32: Product Lead | B32: Tech chapter | C32: Tech Build | D32: M2 | I32: 1 | J32: 1 | K32: 1 | L32: 1 | M32: 1 | N32: 1 | O32: 1 | P32: 1
A33: App Lead | B33: Tech chapter | C33: Tech Build | D33: M2 | I33: 1 | J33: 1 | K33: 1 | L33: 1 | M33: 1 | N33: 1 | O33: 1 | P33: 1
A34: Technical Program Manager | B34: Tech chapter | C34: Tech Build | D34: M2 | I34: 1 | J34: 1 | K34: 1 | L34: 1 | M34: 1 | N34: 1 | O34: 1 | P34: 1
A35: Embedded & IoT Engineer | B35: Tech chapter | C35: Tech Build | D35: M2 | J35: 1 | K35: 2 | L35: 2 | M35: 2 | N35: 2 | O35: 2 | P35: 2
A36: Backend Engineer | B36: Tech chapter | C36: Tech Build | D36: M2 | J36: 1 | K36: 1 | L36: 2 | M36: 2 | N36: 2 | O36: 2 | P36: 2
A37: QA Lead | B37: Tech chapter | C37: Tech Build | D37: M3 | K37: 1 | L37: 1 | M37: 1 | N37: 1 | O37: 1 | P37: 1
A38: iOS Engineer | B38: Tech chapter | C38: Tech Build | D38: M3 | K38: 1 | L38: 1 | M38: 1 | N38: 1 | O38: 1 | P38: 1
A39: Android Engineer | B39: Tech chapter | C39: Tech Build | D39: M3 | K39: 1 | L39: 1 | M39: 1 | N39: 1 | O39: 1 | P39: 1
A40: Frontend Engineer | B40: Tech chapter | C40: Tech Build | D40: M3 | L40: 1 | M40: 1 | N40: 1 | O40: 1 | P40: 1
A41: QA Engineer | B41: Tech chapter | C41: Tech Build | D41: M4 | N41: 3 | O41: 3 | P41: 3
A42: Technical Support Eng. (L2) | B42: Tech chapter | C42: Tech Ops | D42: Now | H42: 1 | I42: 1 | J42: 1 | K42: 1 | L42: 1 | M42: 1 | N42: 1 | O42: 1 | P42: 1
A43: NOC Lead | B43: Tech chapter | C43: Tech Ops | D43: M2 | J43: 1 | K43: 1 | L43: 1 | M43: 1 | N43: 1 | O43: 1 | P43: 1
A44: DevOps / Cloud Engineer | B44: Tech chapter | C44: Tech Ops | D44: M2 | J44: 1 | K44: 1 | L44: 1 | M44: 1 | N44: 1 | O44: 1 | P44: 1
A45: Reliability Engineer | B45: Tech chapter | C45: Tech Ops | D45: M3 | L45: 1 | M45: 1 | N45: 1 | O45: 1 | P45: 1
A47: IT Manager | B47: IT Ops | C47: IT Ops | D47: M2 | J47: 1 | K47: 1 | L47: 1 | M47: 1 | N47: 1 | O47: 1 | P47: 1
A48: IT Support Specialist | B48: IT Ops | C48: IT Ops | D48: M2 | J48: 1 | K48: 1 | L48: 1 | M48: 1 | N48: 1 | O48: 1 | P48: 1
...

Sheet FX Variance (CAPEX USD)
A1: CAPEX FX Variance - USD imports (budget P60.00 vs actual ~P61.30)
E3: 61.7
A4: RFP No. | B4: Item | C4: USD | D4: Budget @60.00 (PHP) | E4: Actual @61.30 (PHP) | F4: FX Variance (PHP)
A5: RFP-OPS2026-0071 | B5: Taizhou Okla - CBU e-motorcycles | C5: 138124.8 | D5: =C5*60 -> 8287488 | E5: =C5*61.3 -> 8467050.2 | F5: =E5-D5 -> 179562.24
A6: RFP-OPS2026-0072 | B6: Guangzhou Yunku - battery-swap lockers | C6: 55200 | D6: =C6*60 -> 3312000 | E6: =C6*61.3 -> 3383760 | F6: =E6-D6 -> 71760
A7: RFP-OPS2026-0073 | B7: Taizhou Okla - spare parts | C7: 11076.63 | D7: =C7*60 -> 664597.8 | E7: =C7*61.3 -> 678997.42 | F7: =E7-D7 -> 14399.619
B8: TOTAL | C8: =SUM(C5:C7) -> 204401.43 | D8: =SUM(D5:D7) -> 12264086 | E8: =SUM(E5:E7) -> 12529808 | F8: =SUM(F5:F7) -> 265721.86

Sheet DP Monitoring
A1: Downpayment / Supplier Monitoring - balance to settle & completion tracking
A4: Vendor | B4: Item | C4: Project Location | D4: Receipt Date | E4: Date Paid | F4: Status | G4: % Paid | H4: Downpayment Paid (PHP) | I4: Balance to Settle (PHP) | J4: Total Contract (PHP) | K4: per site installation | L4: Remarks
A5: STM Builders and Trading Corp | B5: BSS install - 3 ATP sites (Alfamart) | C5: Malabon / Jordan Plaines / Santolan | D5: 4/24/2026 | E5: 5/29/2026 | F5: PAID | G5: 50% | H5: 31167 | I5: 31167 | J5: 62334 | K5: =J5/3 -> 20778 | L5: 40% + 10% milestones (=50%); acceptance/turnover
A6: STM Builders and Trading Corp | B6: BSS install - ATP Poblacion | C6: Poblacion, Mandaluyong | D6: 4/14/2026 | E6: 5/29/2026 | F6: PAID | G6: 50% | H6: 10389 | I6: 10389 | J6: 20778 | K6: =J6 -> 20778 | L6: 40% + 10% milestones (=50%); acceptance/turnover
A7: STM Builders and Trading Corp | B7: Feeder System Outdoor - 6 ATP sites | C7: 6 ATP sites | D7: 5/21/2026 | E7: 5/29/2026 | F7: PAID | G7: 50% | H7: 56334 | I7: 56334 | J7: 112668 | K7: =J7/6 -> 18778 | L7: 50% downpayment; balance on completion
A8: STM Builders and Trading Corp | B8: 4 RideBox lockers deployment | C8: Century City Mall, Makati | D8: 5/21/2026 | E8: 5/29/2026 | F8: PAID | G8: 50% | H8: 80917 | I8: 80917 | J8: 161834 | K8: =J8/4 -> 40458.5 | L8: 50% downpayment; balance on completion / turnover
A9: Digicore Integrated IT Solution | B9: BSS Pateros (service + electrical) | C9: Pateros | D9: 5/4/2026 | F9: PAID | G9: 100% | H9: 32949 | I9: 0 | J9: 32949 | L9: Full payment - no balance
A10: Taizhou Okla Automobile Co., Ltd | B10: OKLA CBU e-motorcycles (USD 138,124.80) | C10: Import - China (Taizhou) | D10: 6/18/2026 | F10: PAID | G10: 30% | H10: 8287488 | I10: 19337472 | J10: 27624960 | L10: Balance 70% on delivery; USD - FX applies at settlement
A11: Guangzhou Yunku Intelligent Co., Ltd | B11: Battery-swap lockers (USD 55,200) | C11: Import - China (Guangzhou) | D11: 6/18/2026 | F11: PAID | G11: 50% | H11: 3312000 | I11: 3312000 | J11: 6624000 | L11: Balance 50% on delivery; USD
A12: Taizhou Okla Automobile Co., Ltd | B12: OKLA spare parts (USD 11,076.63) | C12: Import - China (Taizhou) | D12: 6/22/2026 | F12: PAID | G12: 30% | H12: 664598 | I12: 1550729 | J12: 2215327 | L12: Balance 70% on delivery; USD
B13: TOTAL | H13: =SUM(H5:H12) -> 12475842 | I13: =SUM(I5:I12) -> 24379008 | J13: =SUM(J5:J12) -> 36854850

Sheet Purchase Orders (Approved)
A1: E88 Ventures - Purchase Orders Approved for Payment (Jan-Jun 2026)
A4: PO Number | B4: Date Issued | C4: Dept | D4: Vendor | E4: Orig. FX | F4: Amount (PHP) | G4: Activity / Purpose | H4: Status | I4: In RFP register?
A5: PO-202601-05 | B5: 01/29/2026 | D5: ThingsPh | F5: 61560 | G5: 10M requirement per site installation (70%DP) | H5: Issued to vendor | I5: NET-NEW (not in RFP)
A6: PO-202603-01 | C6: IT | D6: STM | F6: 20778 | G6: 10M requirement per site installation (70%DP) | H6: Issued to vendor | I6: NET-NEW (not in RFP)
A7: PO-TECH-202603-19 | C7: IT | D7: Digicore | F7: 42949 | G7: BSS Installations at Pateros Municipal Hall | H7: Issued to vendor | I7: NET-NEW (not in RFP)
A8: PO-TECH-202603-30 | C8: IT | D8: Claude AI | E8: US$ 150.00 | F8: 9000 | G8: Claude AI: Pro plan Individual (Monthly Subscription per Individual) | H8: Issued to vendor | I8: NET-NEW (not in RFP)
A9: PO - MKT2026-03-001 | C9: MARKETING | D9: WokzPh | F9: 4000 | G9: Battery Swap Updated Locker Stickers | H9: Issued to vendor | I9: Yes - already in RFP register
A10: PO-202601-01 | B10: 01/05/2026 | C10: MARKETING | D10: Wokz Ph | F10: 9550 | G10: A4 stickers for RideBox BSS ads promo, and pull-up banners for retail/events/dealerships. | H10: Issued to vendor | I10: Yes - already in RFP register
A11: PO-202601-02 | B11: 01/06/2025 | C11: IT | D11: TechnoClear | F11: 46704 | G11: for locker security and monitoring system to be integrated with NOC and CCTV integration to lockers (BSS Deployment) using brackets. Canopy Fabrication | H11: Issued to vendor | I11: Yes - already in RFP register
A12: PO-202601-03 | B12: 01/08/2025 | C12: MARKETING | D12: Wokz Ph | F12: 2000 | H12: Issued to vendor | I12: Yes - already in RFP register
A13: PO-202601-04 | B13: 01/12/2025 | C13: IT | D13: PC Central | F13: 20999 | G13: Video management system (vms), 24/7 monitoring systems for CCTVs | H13: Issued to vendor | I13: Yes - already in RFP register
A14: PO-HRA2026-0001 | C14: HRA | D14: EVANA BCBB ENTERPRISES | F14: 6524 | G14: Purchase of office uniform (HO, Warehouse, Retail) | H14: Issued to vendor | I14: Yes - already in RFP register
A15: PO-HRA2026-0002 | C15: HRA | D15: Microgenesis Business Systems | F15: 297000 | G15: Purchase of 5 13-inch MacBook Air: Apple M4 chip with 10-core CPU and 8-core GPU, 16GB Unified Memory, 256GB SSD | H15: Issued to vendor | I15: Yes - already in RFP register
A16: PO-HRA2026-0003 | C16: HRA | D16: Microgenesis Business Systems | F16: 12900 | G16: Purchase of 2 24-inch Samsung monitor | H16: Issued to vendor | I16: Yes - already in RFP register
A17: PO-MKTG2026-04-001 | C17: MARKETING | D17: Wokz Ph | F17: 3150 | G17: Pull up banner refills used during MoveIt event. | H17: Issued to vendor | I17: Yes - already in RFP register
A18: PO-MKTG2026-04-002 | C18: MARKETING | D18: Wokz Ph | F18: 525 | G18: Pull up banner for Flexride | H18: Issued to vendor | I18: Yes - already in RFP register
A19: PO-OPS2026-0001 | B19: 04/14/2026 | C19: OPERATIONS | D19: Guangzhou Yunku Intelligent Co., Ltd | E19: US$ 27600.00 | F19: 1656000 | G19: APRIL 2026 - YUNKU 5-DOOR LOCKERS (less 50% payment | H19: Issued to vendor | I19: Yes - already in RFP register
A20: PO-OPS2026-0002 | B20: 04/14/2026 | C20: OPERATIONS | D20: TAIZHOU OKLA AUTOMOBILE CO.,LTD | E20: US$ 33534.00 | F20: 2012040 | G20: APRIL 2026 - OKLA CBU (Less 70% Balance Payment); PAYMENT TERMS: T/T 30% IN ADVANCE PAYMENT 70% BEFORE SHIPPING ● DELIVERY TERMS: FOB NINGBO PORT, CHINA ● OTHER REMARKS: ○ All parts attached except rearview mirrors ○ OMIGO all longer seat version ○ Stencils of VIN and Motor numbers for each unit - 4 copies each motorcycle | H20: Issued to vendor | I20: Yes - already in RFP register
A21: PO-OPS2026-0003 | B21: 04/14/2026 | C21: OPERATIONS | D21: TAIZHOU OKLA AUTOMOBILE CO.,LTD | E21: US$ 4999.40 | F21: 299964 | G21: APRIL 2026 - OKLA SPARE PARTS (Less 70% Balance Payment);PAYMENT TERMS: T/T 30% IN ADVANCE PAYMENT 70% BEFORE SHIPPING ● DELIVERY TERMS: FOB NINGBO PORT, CHINA ● PACKAGING: BOXED SECURELY | H21: Issued to vendor | I21: Yes - already in RFP register
A22: PO-OPS2026-0006 | C22: OPERATIONS | D22: Guangzhou Yunku Intelligent Co., Ltd | E22: US$ 55200.00 | F22: 3312000 | G22: JUNE 2026 - YUNKU 5-DOOR LOCKERS | H22: Issued to vendor | I22: Yes - already in RFP register
A23: PO-OPS2026-0007 | C23: OPERATIONS | D23: TAIZHOU OKLA AUTOMOBILE CO.,LTD | E23: US$ 138124.80 | F23: 8287488 | G23: JUNE 2026 - OKLA CBU | H23: Issued to vendor | I23: Yes - already in RFP register
A24: PO-OPS2026-0009 | C24: OPERATIONS | D24: TAIZHOU OKLA AUTOMOBILE CO.,LTD | E24: US$ 11076.63 | F24: 664598 | G24: APRIL 2026 - OKLA SPARE PARTS | H24: Issued to vendor | I24: Yes - already in RFP register
E25: NET-NEW total (adds to actuals) | F25: =SUMIF(I5:I24,"NET*",F5:F24) -> 134287
E26: Already in RFP (do not add) | F26: =SUMIF(I5:I24,"Yes*",F5:F24) -> 16635442
E27: All approved POs | F27: =SUM(F5:F24) -> 16769729

Sheet Jan Budget vs Actual
A1: Jan Budget vs Actual - Non-payroll OPEX by Department / Cost Center (PHP)
A3: Department | B3: Cost Center | C3: Budget | D3: Actual | E3: Variance
A4: Sales and Marketing | B4: Sales | C4: =SUMIFS(ApprovedBudget!E19:E125,ApprovedBudget!$A$19:$A$125,"Sales and Marketing") -> 315040 | D4: =IF($A4<>"", SUMIFS('Detailed Receipts'!$K:$K, 'Detailed Receipts'!$A:$A, $A4, 'Detailed Receipts'!$B:$B, $B4, 'Detailed Receipts'!$D:$D, "Jan", 'Detailed Receipts'!$L:$L, "OPEX"), SUMIFS('Detailed Receipts'!$K:$K, 'Detailed Receipts'!$A:$A, MID($B4, 12, 100), 'Detailed Receipts'!$D:$D, "Jan", 'Detailed Receipts'!$L:$L, "OPEX")) -> 14534 | E4: =C4-D4 -> 300506
B5: Subtotal - Sales and Marketing | C5: =SUM(C4) -> 315040 | D5: =IF($A5<>"", SUMIFS('Detailed Receipts'!$K:$K, 'Detailed Receipts'!$A:$A, $A5, 'Detailed Receipts'!$B:$B, $B5, 'Detailed Receipts'!$D:$D, "Jan", 'Detailed Receipts'!$L:$L, "OPEX"), SUMIFS('Detailed Receipts'!$K:$K, 'Detailed Receipts'!$A:$A, MID($B5, 12, 100), 'Detailed Receipts'!$D:$D, "Jan", 'Detailed Receipts'!$L:$L, "OPEX")) -> 14534 | E5: =C5-D5 -> 300506
A6: Customer Success | B6: Customer Success | C6: =SUMIFS(ApprovedBudget!E19:E125,ApprovedBudget!$A$19:$A$125,"Customer Success",ApprovedBudget!$B$19:$B$125,"Customer Success") -> 67500 | D6: =IF($A6<>"", SUMIFS('Detailed Receipts'!$K:$K, 'Detailed Receipts'!$A:$A, $A6, 'Detailed Receipts'!$B:$B, $B6, 'Detailed Receipts'!$D:$D, "Jan", 'Detailed Receipts'!$L:$L, "OPEX"), SUMIFS('Detailed Receipts'!$K:$K, 'Detailed Receipts'!$A:$A, MID($B6, 12, 100), 'Detailed Receipts'!$D:$D, "Jan", 'Detailed Receipts'!$L:$L, "OPEX")) -> 0 | E6: =C6-D6 -> 67500
B7: Subtotal - Customer Success | C7: =SUM(C6) -> 67500 | D7: =IF($A7<>"", SUMIFS('Detailed Receipts'!$K:$K, 'Detailed Receipts'!$A:$A, $A7, 'Detailed Receipts'!$B:$B, $B7, 'Detailed Receipts'!$D:$D, "Jan", 'Detailed Receipts'!$L:$L, "OPEX"), SUMIFS('Detailed Receipts'!$K:$K, 'Detailed Receipts'!$A:$A, MID($B7, 12, 100), 'Detailed Receipts'!$D:$D, "Jan", 'Detailed Receipts'!$L:$L, "OPEX")) -> 0 | E7: =C7-D7 -> 67500
A8: Supply Chain | B8: Logistics | C8: =SUMIFS(ApprovedBudget!E19:E125,ApprovedBudget!$A$19:$A$125,"Supply Chain",ApprovedBudget!$B$19:$B$125,"Logistics") -> 14418 | D8: =IF($A8<>"", SUMIFS('Detailed Receipts'!$K:$K, 'Detailed Receipts'!$A:$A, $A8, 'Detailed Receipts'!$B:$B, $B8, 'Detailed Receipts'!$D:$D, "Jan", 'Detailed Receipts'!$L:$L, "OPEX"), SUMIFS('Detailed Receipts'!$K:$K, 'Detailed Receipts'!$A:$A, MID($B8, 12, 100), 'Detailed Receipts'!$D:$D, "Jan", 'Detailed Receipts'!$L:$L, "OPEX")) -> 0 | E8: =C8-D8 -> 14418
A9: Supply Chain | B9: Procurement | C9: =SUMIFS(ApprovedBudget!E19:E125,ApprovedBudget!$A$19:$A$125,"Supply Chain",ApprovedBudget!$B$19:$B$125,"Procurement") -> 2579 | D9: =IF($A9<>"", SUMIFS('Detailed Receipts'!$K:$K, 'Detailed Receipts'!$A:$A, $A9, 'Detailed Receipts'!$B:$B, $B9, 'Detailed Receipts'!$D:$D, "Jan", 'Detailed Receipts'!$L:$L, "OPEX"), SUMIFS('Detailed Receipts'!$K:$K, 'Detailed Receipts'!$A:$A, MID($B9, 12, 100), 'Detailed Receipts'!$D:$D, "Jan", 'Detailed Receipts'!$L:$L, "OPEX")) -> 13800 | E9: =C9-D9 -> -11221
A10: Supply Chain | B10: Retail | C10: =SUMIFS(ApprovedBudget!E19:E125,ApprovedBudget!$A$19:$A$125,"Supply Chain",ApprovedBudget!$B$19:$B$125,"Retail") -> 125000 | D10: =IF($A10<>"", SUMIFS('Detailed Receipts'!$K:$K, 'Detailed Receipts'!$A:$A, $A10, 'Detailed Receipts'!$B:$B, $B10, 'Detailed Receipts'!$D:$D, "Jan", 'Detailed Receipts'!$L:$L, "OPEX"), SUMIFS('Detailed Receipts'!$K:$K, 'Detailed Receipts'!$A:$A, MID($B10, 12, 100), 'Detailed Receipts'!$D:$D, "Jan", 'Detailed Receipts'!$L:$L, "OPEX")) -> 4275 | E10: =C10-D10 -> 120725
A11: Supply Chain | B11: Warehouse | C11: =SUMIFS(ApprovedBudget!E19:E125,ApprovedBudget!$A$19:$A$125,"Supply Chain",ApprovedBudget!$B$19:$B$125,"Warehouse") -> 459844 | D11: =IF($A11<>"", SUMIFS('Detailed Receipts'!$K:$K, 'Detailed Receipts'!$A:$A, $A11, 'Detailed Receipts'!$B:$B, $B11, 'Detailed Receipts'!$D:$D, "Jan", 'Detailed Receipts'!$L:$L, "OPEX"), SUMIFS('Detailed Receipts'!$K:$K, 'Detailed Receipts'!$A:$A, MID($B11, 12, 100), 'Detailed Receipts'!$D:$D, "Jan", 'Detailed Receipts'!$L:$L, "OPEX")) -> 265942 | E11: =C11-D11 -> 193902
B12: Subtotal - Supply Chain | C12: =SUM(C8:C11) -> 601841 | D12: =IF($A12<>"", SUMIFS('Detailed Receipts'!$K:$K, 'Detailed Receipts'!$A:$A, $A12, 'Detailed Receipts'!$B:$B, $B12, 'Detailed Receipts'!$D:$D, "Jan", 'Detailed Receipts'!$L:$L, "OPEX"), SUMIFS('Detailed Receipts'!$K:$K, 'Detailed Receipts'!$A:$A, MID($B12, 12, 100), 'Detailed Receipts'!$D:$D, "Jan", 'Detailed Receipts'!$L:$L, "OPEX")) -> 284017 | E12: =C12-D12 -> 317824
A13: Aftersales | B13: Aftersales | C13: =SUMIFS(ApprovedBudget!E19:E125,ApprovedBudget!$A$19:$A$125,"Aftersales",ApprovedBudget!$B$19:$B$125,"Aftersales") -> 28800 | D13: =IF($A13<>"", SUMIFS('Detailed Receipts'!$K:$K, 'Detailed Receipts'!$A:$A, $A13, 'Detailed Receipts'!$B:$B, $B13, 'Detailed Receipts'!$D:$D, "Jan", 'Detailed Receipts'!$L:$L, "OPEX"), SUMIFS('Detailed Receipts'!$K:$K, 'Detailed Receipts'!$A:$A, MID($B13, 12, 100), 'Detailed Receipts'!$D:$D, "Jan", 'Detailed Receipts'!$L:$L, "OPEX")) -> 0 | E13: =C13-D13 -> 28800
B14: Subtotal - Aftersales | C14: =SUM(C13) -> 28800 | D14: =IF($A14<>"", SUMIFS('Detailed Receipts'!$K:$K, 'Detailed Receipts'!$A:$A, $A14, 'Detailed Receipts'!$B:$B, $B14, 'Detailed Receipts'!$D:$D, "Jan", 'Detailed Receipts'!$L:$L, "OPEX"), SUMIFS('Detailed Receipts'!$K:$K, 'Detailed Receipts'!$A:$A, MID($B14, 12, 100), 'Detailed Receipts'!$D:$D, "Jan", 'Detailed Receipts'!$L:$L, "OPEX")) -> 0 | E14: =C14-D14 -> 28800
A15: Product | B15: Homologation & Registration | C15: =SUMIFS(ApprovedBudget!E19:E125,ApprovedBudget!$A$19:$A$125,"Product",ApprovedBudget!$B$19:$B$125,"Homologation & Registration") -> 0 | D15: =IF($A15<>"", SUMIFS('Detailed Receipts'!$K:$K, 'Detailed Receipts'!$A:$A, $A15, 'Detailed Receipts'!$B:$B, $B15, 'Detailed Receipts'!$D:$D, "Jan", 'Detailed Receipts'!$L:$L, "OPEX"), SUMIFS('Detailed Receipts'!$K:$K, 'Detailed Receipts'!$A:$A, MID($B15, 12, 100), 'Detailed Receipts'!$D:$D, "Jan", 'Detailed Receipts'!$L:$L, "OPEX")) -> 250555 | E15: =C15-D15 -> -250555
A16: Product | B16: R&D | C16: =SUMIFS(ApprovedBudget!E19:E125,ApprovedBudget!$A$19:$A$125,"Product",ApprovedBudget!$B$19:$B$125,"R&D") -> 15000 | D16: =IF($A16<>"", SUMIFS('Detailed Receipts'!$K:$K, 'Detailed Receipts'!$A:$A, $A16, 'Detailed Receipts'!$B:$B, $B16, 'Detailed Receipts'!$D:$D, "Jan", 'Detailed Receipts'!$L:$L, "OPEX"), SUMIFS('Detailed Receipts'!$K:$K, 'Detailed Receipts'!$A:$A, MID($B16, 12, 100), 'Detailed Receipts'!$D:$D, "Jan", 'Detailed Receipts'!$L:$L, "OPEX")) -> 0 | E16: =C16-D16 -> 15000
B17: Subtotal - Product | C17: =SUM(C15:C16) -> 15000 | D17: =IF($A17<>"", SUMIFS('Detailed Receipts'!$K:$K, 'Detailed Receipts'!$A:$A, $A17, 'Detailed Receipts'!$B:$B, $B17, 'Detailed Receipts'!$D:$D, "Jan", 'Detailed Receipts'!$L:$L, "OPEX"), SUMIFS('Detailed Receipts'!$K:$K, 'Detailed Receipts'!$A:$A, MID($B17, 12, 100), 'Detailed Receipts'!$D:$D, "Jan", 'Detailed Receipts'!$L:$L, "OPEX")) -> 250555 | E17: =C17-D17 -> -235555
A18: RideBox | B18: Billing & Admin | C18: =SUMIFS(ApprovedBudget!E19:E125,ApprovedBudget!$A$19:$A$125,"RideBox",ApprovedBudget!$B$19:$B$125,"RideBox") -> 0 | D18: =IF($A18<>"", SUMIFS('Detailed Receipts'!$K:$K, 'Detailed Receipts'!$A:$A, $A18, 'Detailed Receipts'!$B:$B, $B18, 'Detailed Receipts'!$D:$D, "Jan", 'Detailed Receipts'!$L:$L, "OPEX"), SUMIFS('Detailed Receipts'!$K:$K, 'Detailed Receipts'!$A:$A, MID($B18, 12, 100), 'Detailed Receipts'!$D:$D, "Jan", 'Detailed Receipts'!$L:$L, "OPEX")) -> 0 | E18: =C18-D18 -> 0
A19: RideBox | B19: Monitoring & Field Ops | C19: =SUMIFS(ApprovedBudget!E19:E125,ApprovedBudget!$A$19:$A$125,"RideBox",ApprovedBudget!$B$19:$B$125,"Monitoring & Field Ops") -> 0 | D19: =IF($A19<>"", SUMIFS('Detailed Receipts'!$K:$K, 'Detailed Receipts'!$A:$A, $A19, 'Detailed Receipts'!$B:$B, $B19, 'Detailed Receipts'!$D:$D, "Jan", 'Detailed Receipts'!$L:$L, "OPEX"), SUMIFS('Detailed Receipts'!$K:$K, 'Detailed Receipts'!$A:$A, MID($B19, 12, 100), 'Detailed Receipts'!$D:$D, "Jan", 'Detailed Receipts'!$L:$L, "OPEX")) -> 0 | E19: =C19-D19 -> 0
A20: RideBox | B20: Network Rollout | C20: =SUMIFS(ApprovedBudget!E19:E125,ApprovedBudget!$A$19:$A$125,"RideBox",ApprovedBudget!$B$19:$B$125,"Network Rollout") -> 0 | D20: =IF($A20<>"", SUMIFS('Detailed Receipts'!$K:$K, 'Detailed Receipts'!$A:$A, $A20, 'Detailed Receipts'!$B:$B, $B20, 'Detailed Receipts'!$D:$D, "Jan", 'Detailed Receipts'!$L:$L, "OPEX"), SUMIFS('Detailed Receipts'!$K:$K, 'Detailed Receipts'!$A:$A, MID($B20, 12, 100), 'Detailed Receipts'!$D:$D, "Jan", 'Detailed Receipts'!$L:$L, "OPEX")) -> 7922 | E20: =C20-D20 -> -7922
A21: RideBox | B21: Service Center | C21: =SUMIFS(ApprovedBudget!E19:E125,ApprovedBudget!$A$19:$A$125,"RideBox",ApprovedBudget!$B$19:$B$125,"Service Center") -> 0 | D21: =IF($A21<>"", SUMIFS('Detailed Receipts'!$K:$K, 'Detailed Receipts'!$A:$A, $A21, 'Detailed Receipts'!$B:$B, $B21, 'Detailed Receipts'!$D:$D, "Jan", 'Detailed Receipts'!$L:$L, "OPEX"), SUMIFS('Detailed Receipts'!$K:$K, 'Detailed Receipts'!$A:$A, MID($B21, 12, 100), 'Detailed Receipts'!$D:$D, "Jan", 'Detailed Receipts'!$L:$L, "OPEX")) -> 8308 | E21: =C21-D21 -> -8308
B22: Subtotal - RideBox | C22: =SUM(C18:C21) -> 0 | D22: =IF($A22<>"", SUMIFS('Detailed Receipts'!$K:$K, 'Detailed Receipts'!$A:$A, $A22, 'Detailed Receipts'!$B:$B, $B22, 'Detailed Receipts'!$D:$D, "Jan", 'Detailed Receipts'!$L:$L, "OPEX"), SUMIFS('Detailed Receipts'!$K:$K, 'Detailed Receipts'!$A:$A, MID($B22, 12, 100), 'Detailed Receipts'!$D:$D, "Jan", 'Detailed Receipts'!$L:$L, "OPEX")) -> 16230 | E22: =C22-D22 -> -16230
A23: Technology | B23: Technology | C23: =SUMIFS(ApprovedBudget!E19:E125,ApprovedBudget!$A$19:$A$125,"Technology") -> 0 | D23: =IF($A23<>"", SUMIFS('Detailed Receipts'!$K:$K, 'Detailed Receipts'!$A:$A, $A23, 'Detailed Receipts'!$B:$B, $B23, 'Detailed Receipts'!$D:$D, "Jan", 'Detailed Receipts'!$L:$L, "OPEX"), SUMIFS('Detailed Receipts'!$K:$K, 'Detailed Receipts'!$A:$A, MID($B23, 12, 100), 'Detailed Receipts'!$D:$D, "Jan", 'Detailed Receipts'!$L:$L, "OPEX")) -> 215926 | E23: =C23-D23 -> -215926
B24: Subtotal - Technology | C24: =SUM(C23) -> 0 | D24: =IF($A24<>"", SUMIFS('Detailed Receipts'!$K:$K, 'Detailed Receipts'!$A:$A, $A24, 'Detailed Receipts'!$B:$B, $B24, 'Detailed Receipts'!$D:$D, "Jan", 'Detailed Receipts'!$L:$L, "OPEX"), SUMIFS('Detailed Receipts'!$K:$K, 'Detailed Receipts'!$A:$A, MID($B24, 12, 100), 'Detailed Receipts'!$D:$D, "Jan", 'Detailed Receipts'!$L:$L, "OPEX")) -> 215926 | E24: =C24-D24 -> -215926
A25: Finance and Accounting | B25: Finance and Accounting | C25: =SUMIFS(ApprovedBudget!E19:E125,ApprovedBudget!$A$19:$A$125,"Finance and Accounting",ApprovedBudget!$B$19:$B$125,"Finance and Accounting") -> 46472 | D25: =IF($A25<>"", SUMIFS('Detailed Receipts'!$K:$K, 'Detailed Receipts'!$A:$A, $A25, 'Detailed Receipts'!$B:$B, $B25, 'Detailed Receipts'!$D:$D, "Jan", 'Detailed Receipts'!$L:$L, "OPEX"), SUMIFS('Detailed Receipts'!$K:$K, 'Detailed Receipts'!$A:$A, MID($B25, 12, 100), 'Detailed Receipts'!$D:$D, "Jan", 'Detailed Receipts'!$L:$L, "OPEX")) -> 367466 | E25: =C25-D25 -> -320994
B26: Subtotal - Finance and Accounting | C26: =SUM(C25) -> 46472 | D26: =IF($A26<>"", SUMIFS('Detailed Receipts'!$K:$K, 'Detailed Receipts'!$A:$A, $A26, 'Detailed Receipts'!$B:$B, $B26, 'Detailed Receipts'!$D:$D, "Jan", 'Detailed Receipts'!$L:$L, "OPEX"), SUMIFS('Detailed Receipts'!$K:$K, 'Detailed Receipts'!$A:$A, MID($B26, 12, 100), 'Detailed Receipts'!$D:$D, "Jan", 'Detailed Receipts'!$L:$L, "OPEX")) -> 367466 | E26: =C26-D26 -> -320994
A27: Admin | B27: Admin | C27: =SUMIFS(ApprovedBudget!E19:E125,ApprovedBudget!$A$19:$A$125,"Admin",ApprovedBudget!$B$19:$B$125,"Admin") -> 580893 | D27: =IF($A27<>"", SUMIFS('Detailed Receipts'!$K:$K, 'Detailed Receipts'!$A:$A, $A27, 'Detailed Receipts'!$B:$B, $B27, 'Detailed Receipts'!$D:$D, "Jan", 'Detailed Receipts'!$L:$L, "OPEX"), SUMIFS('Detailed Receipts'!$K:$K, 'Detailed Receipts'!$A:$A, MID($B27, 12, 100), 'Detailed Receipts'!$D:$D, "Jan", 'Detailed Receipts'!$L:$L, "OPEX")) -> 336277 | E27: =C27-D27 -> 244616
B28: Subtotal - Admin | C28: =SUM(C27) -> 580893 | D28: =IF($A28<>"", SUMIFS('Detailed Receipts'!$K:$K, 'Detailed Receipts'!$A:$A, $A28, 'Detailed Receipts'!$B:$B, $B28, 'Detailed Receipts'!$D:$D, "Jan", 'Detailed Receipts'!$L:$L, "OPEX"), SUMIFS('Detailed Receipts'!$K:$K, 'Detailed Receipts'!$A:$A, MID($B28, 12, 100), 'Detailed Receipts'!$D:$D, "Jan", 'Detailed Receipts'!$L:$L, "OPEX")) -> 336277 | E28: =C28-D28 -> 244616
A29: HR | B29: HR | C29: =SUMIFS(ApprovedBudget!E19:E125,ApprovedBudget!$A$19:$A$125,"HR",ApprovedBudget!$B$19:$B$125,"HR") -> 0 | D29: =IF($A29<>"", SUMIFS('Detailed Receipts'!$K:$K, 'Detailed Receipts'!$A:$A, $A29, 'Detailed Receipts'!$B:$B, $B29, 'Detailed Receipts'!$D:$D, "Jan", 'Detailed Receipts'!$L:$L, "OPEX"), SUMIFS('Detailed Receipts'!$K:$K, 'Detailed Receipts'!$A:$A, MID($B29, 12, 100), 'Detailed Receipts'!$D:$D, "Jan", 'Detailed Receipts'!$L:$L, "OPEX")) -> 12065 | E29: =C29-D29 -> -12065
B30: Subtotal - HR | C30: =SUM(C29) -> 0 | D30: =IF($A30<>"", SUMIFS('Detailed Receipts'!$K:$K, 'Detailed Receipts'!$A:$A, $A30, 'Detailed Receipts'!$B:$B, $B30, 'Detailed Receipts'!$D:$D, "Jan", 'Detailed Receipts'!$L:$L, "OPEX"), SUMIFS('Detailed Receipts'!$K:$K, 'Detailed Receipts'!$A:$A, MID($B30, 12, 100), 'Detailed Receipts'!$D:$D, "Jan", 'Detailed Receipts'!$L:$L, "OPEX")) -> 12065 | E30: =C30-D30 -> -12065
A31: Compliance and Risk | B31: Legal & notarial | C31: =SUMIFS(ApprovedBudget!E19:E125,ApprovedBudget!$A$19:$A$125,"Compliance and Risk",ApprovedBudget!$B$19:$B$125,"Legal & notarial") -> 60000 | D31: =IF($A31<>"", SUMIFS('Detailed Receipts'!$K:$K, 'Detailed Receipts'!$A:$A, $A31, 'Detailed Receipts'!$B:$B, $B31, 'Detailed Receipts'!$D:$D, "Jan", 'Detailed Receipts'!$L:$L, "OPEX"), SUMIFS('Detailed Receipts'!$K:$K, 'Detailed Receipts'!$A:$A, MID($B31, 12, 100), 'Detailed Receipts'!$D:$D, "Jan", 'Detailed Receipts'!$L:$L, "OPEX")) -> 103338 | E31: =C31-D31 -> -43338
A32: Compliance and Risk | B32: Permits & registration | C32: =SUMIFS(ApprovedBudget!E19:E125,ApprovedBudget!$A$19:$A$125,"Compliance and Risk",ApprovedBudget!$B$19:$B$125,"Permits & registration") -> 66800 | D32: =IF($A32<>"", SUMIFS('Detailed Receipts'!$K:$K, 'Detailed Receipts'!$A:$A, $A32, 'Detailed Receipts'!$B:$B, $B32, 'Detailed Receipts'!$D:$D, "Jan", 'Detailed Receipts'!$L:$L, "OPEX"), SUMIFS('Detailed Receipts'!$K:$K, 'Detailed Receipts'!$A:$A, MID($B32, 12, 100), 'Detailed Receipts'!$D:$D, "Jan", 'Detailed Receipts'!$L:$L, "OPEX")) -> 289718 | E32: =C32-D32 -> -222918
B33: Subtotal - Compliance and Risk | C33: =SUM(C31:C32) -> 126800 | D33: =IF($A33<>"", SUMIFS('Detailed Receipts'!$K:$K, 'Detailed Receipts'!$A:$A, $A33, 'Detailed Receipts'!$B:$B, $B33, 'Detailed Receipts'!$D:$D, "Jan", 'Detailed Receipts'!$L:$L, "OPEX"), SUMIFS('Detailed Receipts'!$K:$K, 'Detailed Receipts'!$A:$A, MID($B33, 12, 100), 'Detailed Receipts'!$D:$D, "Jan", 'Detailed Receipts'!$L:$L, "OPEX")) -> 393056 | E33: =C33-D33 -> -266256
B34: TOTAL OPEX | C34: =SUMIF($B4:$B33,"Subtotal*",C4:C33) -> 1782346 | D34: =SUMIF($B4:$B33,"Subtotal*",D4:D33) -> 1890126 | E34: =C34-D34 -> -107780

Sheet Feb Budget vs Actual
A1: Feb Budget vs Actual - Non-payroll OPEX by Department / Cost Center (PHP)
A3: Department | B3: Cost Center | C3: Budget | D3: Actual | E3: Variance
A4: Sales and Marketing | B4: Sales | C4: =SUMIFS(ApprovedBudget!F19:F125,ApprovedBudget!$A$19:$A$125,"Sales and Marketing") -> 361840 | D4: =IF($A4<>"", SUMIFS('Detailed Receipts'!$K:$K, 'Detailed Receipts'!$A:$A, $A4, 'Detailed Receipts'!$B:$B, $B4, 'Detailed Receipts'!$D:$D, "Feb", 'Detailed Receipts'!$L:$L, "OPEX"), SUMIFS('Detailed Receipts'!$K:$K, 'Detailed Receipts'!$A:$A, MID($B4, 12, 100), 'Detailed Receipts'!$D:$D, "Feb", 'Detailed Receipts'!$L:$L, "OPEX")) -> 11706 | E4: =C4-D4 -> 350134
B5: Subtotal - Sales and Marketing | C5: =SUM(C4) -> 361840 | D5: =IF($A5<>"", SUMIFS('Detailed Receipts'!$K:$K, 'Detailed Receipts'!$A:$A, $A5, 'Detailed Receipts'!$B:$B, $B5, 'Detailed Receipts'!$D:$D, "Feb", 'Detailed Receipts'!$L:$L, "OPEX"), SUMIFS('Detailed Receipts'!$K:$K, 'Detailed Receipts'!$A:$A, MID($B5, 12, 100), 'Detailed Receipts'!$D:$D, "Feb", 'Detailed Receipts'!$L:$L, "OPEX")) -> 11706 | E5: =C5-D5 -> 350134
A6: Customer Success | B6: Customer Success | C6: =SUMIFS(ApprovedBudget!F19:F125,ApprovedBudget!$A$19:$A$125,"Customer Success",ApprovedBudget!$B$19:$B$125,"Customer Success") -> 67500 | D6: =IF($A6<>"", SUMIFS('Detailed Receipts'!$K:$K, 'Detailed Receipts'!$A:$A, $A6, 'Detailed Receipts'!$B:$B, $B6, 'Detailed Receipts'!$D:$D, "Feb", 'Detailed Receipts'!$L:$L, "OPEX"), SUMIFS('Detailed Receipts'!$K:$K, 'Detailed Receipts'!$A:$A, MID($B6, 12, 100), 'Detailed Receipts'!$D:$D, "Feb", 'Detailed Receipts'!$L:$L, "OPEX")) -> 0 | E6: =C6-D6 -> 67500
B7: Subtotal - Customer Success | C7: =SUM(C6) -> 67500 | D7: =IF($A7<>"", SUMIFS('Detailed Receipts'!$K:$K, 'Detailed Receipts'!$A:$A, $A7, 'Detailed Receipts'!$B:$B, $B7, 'Detailed Receipts'!$D:$D, "Feb", 'Detailed Receipts'!$L:$L, "OPEX"), SUMIFS('Detailed Receipts'!$K:$K, 'Detailed Receipts'!$A:$A, MID($B7, 12, 100), 'Detailed Receipts'!$D:$D, "Feb", 'Detailed Receipts'!$L:$L, "OPEX")) -> 0 | E7: =C7-D7 -> 67500
A8: Supply Chain | B8: Logistics | C8: =SUMIFS(ApprovedBudget!F19:F125,ApprovedBudget!$A$19:$A$125,"Supply Chain",ApprovedBudget!$B$19:$B$125,"Logistics") -> 13722 | D8: =IF($A8<>"", SUMIFS('Detailed Receipts'!$K:$K, 'Detailed Receipts'!$A:$A, $A8, 'Detailed Receipts'!$B:$B, $B8, 'Detailed Receipts'!$D:$D, "Feb", 'Detailed Receipts'!$L:$L, "OPEX"), SUMIFS('Detailed Receipts'!$K:$K, 'Detailed Receipts'!$A:$A, MID($B8, 12, 100), 'Detailed Receipts'!$D:$D, "Feb", 'Detailed Receipts'!$L:$L, "OPEX")) -> 0 | E8: =C8-D8 -> 13722
A9: Supply Chain | B9: Procurement | C9: =SUMIFS(ApprovedBudget!F19:F125,ApprovedBudget!$A$19:$A$125,"Supply Chain",ApprovedBudget!$B$19:$B$125,"Procurement") -> 3967 | D9: =IF($A9<>"", SUMIFS('Detailed Receipts'!$K:$K, 'Detailed Receipts'!$A:$A, $A9, 'Detailed Receipts'!$B:$B, $B9, 'Detailed Receipts'!$D:$D, "Feb", 'Detailed Receipts'!$L:$L, "OPEX"), SUMIFS('Detailed Receipts'!$K:$K, 'Detailed Receipts'!$A:$A, MID($B9, 12, 100), 'Detailed Receipts'!$D:$D, "Feb", 'Detailed Receipts'!$L:$L, "OPEX")) -> 0 | E9: =C9-D9 -> 3967
A10: Supply Chain | B10: Retail | C10: =SUMIFS(ApprovedBudget!F19:F125,ApprovedBudget!$A$19:$A$125,"Supply Chain",ApprovedBudget!$B$19:$B$125,"Retail") -> 125000 | D10: =IF($A10<>"", SUMIFS('Detailed Receipts'!$K:$K, 'Detailed Receipts'!$A:$A, $A10, 'Detailed Receipts'!$B:$B, $B10, 'Detailed Receipts'!$D:$D, "Feb", 'Detailed Receipts'!$L:$L, "OPEX"), SUMIFS('Detailed Receipts'!$K:$K, 'Detailed Receipts'!$A:$A, MID($B10, 12, 100), 'Detailed Receipts'!$D:$D, "Feb", 'Detailed Receipts'!$L:$L, "OPEX")) -> 6932 | E10: =C10-D10 -> 118068
A11: Supply Chain | B11: Warehouse | C11: =SUMIFS(ApprovedBudget!F19:F125,ApprovedBudget!$A$19:$A$125,"Supply Chain",ApprovedBudget!$B$19:$B$125,"Warehouse") -> 437629 | D11: =IF($A11<>"", SUMIFS('Detailed Receipts'!$K:$K, 'Detailed Receipts'!$A:$A, $A11, 'Detailed Receipts'!$B:$B, $B11, 'Detailed Receipts'!$D:$D, "Feb", 'Detailed Receipts'!$L:$L, "OPEX"), SUMIFS('Detailed Receipts'!$K:$K, 'Detailed Receipts'!$A:$A, MID($B11, 12, 100), 'Detailed Receipts'!$D:$D, "Feb", 'Detailed Receipts'!$L:$L, "OPEX")) -> 665598 | E11: =C11-D11 -> -227969
B12: Subtotal - Supply Chain | C12: =SUM(C8:C11) -> 580318 | D12: =IF($A12<>"", SUMIFS('Detailed Receipts'!$K:$K, 'Detailed Receipts'!$A:$A, $A12, 'Detailed Receipts'!$B:$B, $B12, 'Detailed Receipts'!$D:$D, "Feb", 'Detailed Receipts'!$L:$L, "OPEX"), SUMIFS('Detailed Receipts'!$K:$K, 'Detailed Receipts'!$A:$A, MID($B12, 12, 100), 'Detailed Receipts'!$D:$D, "Feb", 'Detailed Receipts'!$L:$L, "OPEX")) -> 672530 | E12: =C12-D12 -> -92212
A13: Aftersales | B13: Aftersales | C13: =SUMIFS(ApprovedBudget!F19:F125,ApprovedBudget!$A$19:$A$125,"Aftersales",ApprovedBudget!$B$19:$B$125,"Aftersales") -> 36000 | D13: =IF($A13<>"", SUMIFS('Detailed Receipts'!$K:$K, 'Detailed Receipts'!$A:$A, $A13, 'Detailed Receipts'!$B:$B, $B13, 'Detailed Receipts'!$D:$D, "Feb", 'Detailed Receipts'!$L:$L, "OPEX"), SUMIFS('Detailed Receipts'!$K:$K, 'Detailed Receipts'!$A:$A, MID($B13, 12, 100), 'Detailed Receipts'!$D:$D, "Feb", 'Detailed Receipts'!$L:$L, "OPEX")) -> 1428 | E13: =C13-D13 -> 34572
B14: Subtotal - Aftersales | C14: =SUM(C13) -> 36000 | D14: =IF($A14<>"", SUMIFS('Detailed Receipts'!$K:$K, 'Detailed Receipts'!$A:$A, $A14, 'Detailed Receipts'!$B:$B, $B14, 'Detailed Receipts'!$D:$D, "Feb", 'Detailed Receipts'!$L:$L, "OPEX"), SUMIFS('Detailed Receipts'!$K:$K, 'Detailed Receipts'!$A:$A, MID($B14, 12, 100), 'Detailed Receipts'!$D:$D, "Feb", 'Detailed Receipts'!$L:$L, "OPEX")) -> 1428 | E14: =C14-D14 -> 34572
A15: Product | B15: Homologation & Registration | C15: =SUMIFS(ApprovedBudget!F19:F125,ApprovedBudget!$A$19:$A$125,"Product",ApprovedBudget!$B$19:$B$125,"Homologation & Registration") -> 0 | D15: =IF($A15<>"", SUMIFS('Detailed Receipts'!$K:$K, 'Detailed Receipts'!$A:$A, $A15, 'Detailed Receipts'!$B:$B, $B15, 'Detailed Receipts'!$D:$D, "Feb", 'Detailed Receipts'!$L:$L, "OPEX"), SUMIFS('Detailed Receipts'!$K:$K, 'Detailed Receipts'!$A:$A, MID($B15, 12, 100), 'Detailed Receipts'!$D:$D, "Feb", 'Detailed Receipts'!$L:$L, "OPEX")) -> 160346 | E15: =C15-D15 -> -160346
A16: Product | B16: R&D | C16: =SUMIFS(ApprovedBudget!F19:F125,ApprovedBudget!$A$19:$A$125,"Product",ApprovedBudget!$B$19:$B$125,"R&D") -> 15000 | D16: =IF($A16<>"", SUMIFS('Detailed Receipts'!$K:$K, 'Detailed Receipts'!$A:$A, $A16, 'Detailed Receipts'!$B:$B, $B16, 'Detailed Receipts'!$D:$D, "Feb", 'Detailed Receipts'!$L:$L, "OPEX"), SUMIFS('Detailed Receipts'!$K:$K, 'Detailed Receipts'!$A:$A, MID($B16, 12, 100), 'Detailed Receipts'!$D:$D, "Feb", 'Detailed Receipts'!$L:$L, "OPEX")) -> 0 | E16: =C16-D16 -> 15000
B17: Subtotal - Product | C17: =SUM(C15:C16) -> 15000 | D17: =IF($A17<>"", SUMIFS('Detailed Receipts'!$K:$K, 'Detailed Receipts'!$A:$A, $A17, 'Detailed Receipts'!$B:$B, $B17, 'Detailed Receipts'!$D:$D, "Feb", 'Detailed Receipts'!$L:$L, "OPEX"), SUMIFS('Detailed Receipts'!$K:$K, 'Detailed Receipts'!$A:$A, MID($B17, 12, 100), 'Detailed Receipts'!$D:$D, "Feb", 'Detailed Receipts'!$L:$L, "OPEX")) -> 160346 | E17: =C17-D17 -> -145346
A18: RideBox | B18: Billing & Admin | C18: =SUMIFS(ApprovedBudget!F19:F125,ApprovedBudget!$A$19:$A$125,"RideBox",ApprovedBudget!$B$19:$B$125,"RideBox") -> 0 | D18: =IF($A18<>"", SUMIFS('Detailed Receipts'!$K:$K, 'Detailed Receipts'!$A:$A, $A18, 'Detailed Receipts'!$B:$B, $B18, 'Detailed Receipts'!$D:$D, "Feb", 'Detailed Receipts'!$L:$L, "OPEX"), SUMIFS('Detailed Receipts'!$K:$K, 'Detailed Receipts'!$A:$A, MID($B18, 12, 100), 'Detailed Receipts'!$D:$D, "Feb", 'Detailed Receipts'!$L:$L, "OPEX")) -> 0 | E18: =C18-D18 -> 0
A19: RideBox | B19: Monitoring & Field Ops | C19: =SUMIFS(ApprovedBudget!F19:F125,ApprovedBudget!$A$19:$A$125,"RideBox",ApprovedBudget!$B$19:$B$125,"Monitoring & Field Ops") -> 0 | D19: =IF($A19<>"", SUMIFS('Detailed Receipts'!$K:$K, 'Detailed Receipts'!$A:$A, $A19, 'Detailed Receipts'!$B:$B, $B19, 'Detailed Receipts'!$D:$D, "Feb", 'Detailed Receipts'!$L:$L, "OPEX"), SUMIFS('Detailed Receipts'!$K:$K, 'Detailed Receipts'!$A:$A, MID($B19, 12, 100), 'Detailed Receipts'!$D:$D, "Feb", 'Detailed Receipts'!$L:$L, "OPEX")) -> 626590 | E19: =C19-D19 -> -626590
A20: RideBox | B20: Network Rollout | C20: =SUMIFS(ApprovedBudget!F19:F125,ApprovedBudget!$A$19:$A$125,"RideBox",ApprovedBudget!$B$19:$B$125,"Network Rollout") -> 0 | D20: =IF($A20<>"", SUMIFS('Detailed Receipts'!$K:$K, 'Detailed Receipts'!$A:$A, $A20, 'Detailed Receipts'!$B:$B, $B20, 'Detailed Receipts'!$D:$D, "Feb", 'Detailed Receipts'!$L:$L, "OPEX"), SUMIFS('Detailed Receipts'!$K:$K, 'Detailed Receipts'!$A:$A, MID($B20, 12, 100), 'Detailed Receipts'!$D:$D, "Feb", 'Detailed Receipts'!$L:$L, "OPEX")) -> 9075 | E20: =C20-D20 -> -9075
A21: RideBox | B21: Service Center | C21: =SUMIFS(ApprovedBudget!F19:F125,ApprovedBudget!$A$19:$A$125,"RideBox",ApprovedBudget!$B$19:$B$125,"Service Center") -> 0 | D21: =IF($A21<>"", SUMIFS('Detailed Receipts'!$K:$K, 'Detailed Receipts'!$A:$A, $A21, 'Detailed Receipts'!$B:$B, $B21, 'Detailed Receipts'!$D:$D, "Feb", 'Detailed Receipts'!$L:$L, "OPEX"), SUMIFS('Detailed Receipts'!$K:$K, 'Detailed Receipts'!$A:$A, MID($B21, 12, 100), 'Detailed Receipts'!$D:$D, "Feb", 'Detailed Receipts'!$L:$L, "OPEX")) -> 7172 | E21: =C21-D21 -> -7172
B22: Subtotal - RideBox | C22: =SUM(C18:C21) -> 0 | D22: =IF($A22<>"", SUMIFS('Detailed Receipts'!$K:$K, 'Detailed Receipts'!$A:$A, $A22, 'Detailed Receipts'!$B:$B, $B22, 'Detailed Receipts'!$D:$D, "Feb", 'Detailed Receipts'!$L:$L, "OPEX"), SUMIFS('Detailed Receipts'!$K:$K, 'Detailed Receipts'!$A:$A, MID($B22, 12, 100), 'Detailed Receipts'!$D:$D, "Feb", 'Detailed Receipts'!$L:$L, "OPEX")) -> 642837 | E22: =C22-D22 -> -642837
A23: Technology | B23: Technology | C23: =SUMIFS(ApprovedBudget!F19:F125,ApprovedBudget!$A$19:$A$125,"Technology") -> 0 | D23: =IF($A23<>"", SUMIFS('Detailed Receipts'!$K:$K, 'Detailed Receipts'!$A:$A, $A23, 'Detailed Receipts'!$B:$B, $B23, 'Detailed Receipts'!$D:$D, "Feb", 'Detailed Receipts'!$L:$L, "OPEX"), SUMIFS('Detailed Receipts'!$K:$K, 'Detailed Receipts'!$A:$A, MID($B23, 12, 100), 'Detailed Receipts'!$D:$D, "Feb", 'Detailed Receipts'!$L:$L, "OPEX")) -> 14314 | E23: =C23-D23 -> -14314
B24: Subtotal - Technology | C24: =SUM(C23) -> 0 | D24: =IF($A24<>"", SUMIFS('Detailed Receipts'!$K:$K, 'Detailed Receipts'!$A:$A, $A24, 'Detailed Receipts'!$B:$B, $B24, 'Detailed Receipts'!$D:$D, "Feb", 'Detailed Receipts'!$L:$L, "OPEX"), SUMIFS('Detailed Receipts'!$K:$K, 'Detailed Receipts'!$A:$A, MID($B24, 12, 100), 'Detailed Receipts'!$D:$D, "Feb", 'Detailed Receipts'!$L:$L, "OPEX")) -> 14314 | E24: =C24-D24 -> -14314
A25: Finance and Accounting | B25: Finance and Accounting | C25: =SUMIFS(ApprovedBudget!F19:F125,ApprovedBudget!$A$19:$A$125,"Finance and Accounting",ApprovedBudget!$B$19:$B$125,"Finance and Accounting") -> 46472 | D25: =IF($A25<>"", SUMIFS('Detailed Receipts'!$K:$K, 'Detailed Receipts'!$A:$A, $A25, 'Detailed Receipts'!$B:$B, $B25, 'Detailed Receipts'!$D:$D, "Feb", 'Detailed Receipts'!$L:$L, "OPEX"), SUMIFS('Detailed Receipts'!$K:$K, 'Detailed Receipts'!$A:$A, MID($B25, 12, 100), 'Detailed Receipts'!$D:$D, "Feb", 'Detailed Receipts'!$L:$L, "OPEX")) -> 33199 | E25: =C25-D25 -> 13273
B26: Subtotal - Finance and Accounting | C26: =SUM(C25) -> 46472 | D26: =IF($A26<>"", SUMIFS('Detailed Receipts'!$K:$K, 'Detailed Receipts'!$A:$A, $A26, 'Detailed Receipts'!$B:$B, $B26, 'Detailed Receipts'!$D:$D, "Feb", 'Detailed Receipts'!$L:$L, "OPEX"), SUMIFS('Detailed Receipts'!$K:$K, 'Detailed Receipts'!$A:$A, MID($B26, 12, 100), 'Detailed Receipts'!$D:$D, "Feb", 'Detailed Receipts'!$L:$L, "OPEX")) -> 33199 | E26: =C26-D26 -> 13273
A27: Admin | B27: Admin | C27: =SUMIFS(ApprovedBudget!F19:F125,ApprovedBudget!$A$19:$A$125,"Admin",ApprovedBudget!$B$19:$B$125,"Admin") -> 580893 | D27: =IF($A27<>"", SUMIFS('Detailed Receipts'!$K:$K, 'Detailed Receipts'!$A:$A, $A27, 'Detailed Receipts'!$B:$B, $B27, 'Detailed Receipts'!$D:$D, "Feb", 'Detailed Receipts'!$L:$L, "OPEX"), SUMIFS('Detailed Receipts'!$K:$K, 'Detailed Receipts'!$A:$A, MID($B27, 12, 100), 'Detailed Receipts'!$D:$D, "Feb", 'Detailed Receipts'!$L:$L, "OPEX")) -> 224889 | E27: =C27-D27 -> 356004
B28: Subtotal - Admin | C28: =SUM(C27) -> 580893 | D28: =IF($A28<>"", SUMIFS('Detailed Receipts'!$K:$K, 'Detailed Receipts'!$A:$A, $A28, 'Detailed Receipts'!$B:$B, $B28, 'Detailed Receipts'!$D:$D, "Feb", 'Detailed Receipts'!$L:$L, "OPEX"), SUMIFS('Detailed Receipts'!$K:$K, 'Detailed Receipts'!$A:$A, MID($B28, 12, 100), 'Detailed Receipts'!$D:$D, "Feb", 'Detailed Receipts'!$L:$L, "OPEX")) -> 224889 | E28: =C28-D28 -> 356004
A29: HR | B29: HR | C29: =SUMIFS(ApprovedBudget!F19:F125,ApprovedBudget!$A$19:$A$125,"HR",ApprovedBudget!$B$19:$B$125,"HR") -> 0 | D29: =IF($A29<>"", SUMIFS('Detailed Receipts'!$K:$K, 'Detailed Receipts'!$A:$A, $A29, 'Detailed Receipts'!$B:$B, $B29, 'Detailed Receipts'!$D:$D, "Feb", 'Detailed Receipts'!$L:$L, "OPEX"), SUMIFS('Detailed Receipts'!$K:$K, 'Detailed Receipts'!$A:$A, MID($B29, 12, 100), 'Detailed Receipts'!$D:$D, "Feb", 'Detailed Receipts'!$L:$L, "OPEX")) -> 72107 | E29: =C29-D29 -> -72107
B30: Subtotal - HR | C30: =SUM(C29) -> 0 | D30: =IF($A30<>"", SUMIFS('Detailed Receipts'!$K:$K, 'Detailed Receipts'!$A:$A, $A30, 'Detailed Receipts'!$B:$B, $B30, 'Detailed Receipts'!$D:$D, "Feb", 'Detailed Receipts'!$L:$L, "OPEX"), SUMIFS('Detailed Receipts'!$K:$K, 'Detailed Receipts'!$A:$A, MID($B30, 12, 100), 'Detailed Receipts'!$D:$D, "Feb", 'Detailed Receipts'!$L:$L, "OPEX")) -> 72107 | E30: =C30-D30 -> -72107
A31: Compliance and Risk | B31: Legal & notarial | C31: =SUMIFS(ApprovedBudget!F19:F125,ApprovedBudget!$A$19:$A$125,"Compliance and Risk",ApprovedBudget!$B$19:$B$125,"Legal & notarial") -> 60000 | D31: =IF($A31<>"", SUMIFS('Detailed Receipts'!$K:$K, 'Detailed Receipts'!$A:$A, $A31, 'Detailed Receipts'!$B:$B, $B31, 'Detailed Receipts'!$D:$D, "Feb", 'Detailed Receipts'!$L:$L, "OPEX"), SUMIFS('Detailed Receipts'!$K:$K, 'Detailed Receipts'!$A:$A, MID($B31, 12, 100), 'Detailed Receipts'!$D:$D, "Feb", 'Detailed Receipts'!$L:$L, "OPEX")) -> 136027 | E31: =C31-D31 -> -76027
A32: Compliance and Risk | B32: Permits & registration | C32: =SUMIFS(ApprovedBudget!F19:F125,ApprovedBudget!$A$19:$A$125,"Compliance and Risk",ApprovedBudget!$B$19:$B$125,"Permits & registration") -> 66800 | D32: =IF($A32<>"", SUMIFS('Detailed Receipts'!$K:$K, 'Detailed Receipts'!$A:$A, $A32, 'Detailed Receipts'!$B:$B, $B32, 'Detailed Receipts'!$D:$D, "Feb", 'Detailed Receipts'!$L:$L, "OPEX"), SUMIFS('Detailed Receipts'!$K:$K, 'Detailed Receipts'!$A:$A, MID($B32, 12, 100), 'Detailed Receipts'!$D:$D, "Feb", 'Detailed Receipts'!$L:$L, "OPEX")) -> 164030 | E32: =C32-D32 -> -97230
B33: Subtotal - Compliance and Risk | C33: =SUM(C31:C32) -> 126800 | D33: =IF($A33<>"", SUMIFS('Detailed Receipts'!$K:$K, 'Detailed Receipts'!$A:$A, $A33, 'Detailed Receipts'!$B:$B, $B33, 'Detailed Receipts'!$D:$D, "Feb", 'Detailed Receipts'!$L:$L, "OPEX"), SUMIFS('Detailed Receipts'!$K:$K, 'Detailed Receipts'!$A:$A, MID($B33, 12, 100), 'Detailed Receipts'!$D:$D, "Feb", 'Detailed Receipts'!$L:$L, "OPEX")) -> 300057 | E33: =C33-D33 -> -173257
B34: TOTAL OPEX | C34: =SUMIF($B4:$B33,"Subtotal*",C4:C33) -> 1814823 | D34: =SUMIF($B4:$B33,"Subtotal*",D4:D33) -> 2133413 | E34: =C34-D34 -> -318590

Sheet Mar Budget vs Actual
A1: Mar Budget vs Actual - Non-payroll OPEX by Department / Cost Center (PHP)
A3: Department | B3: Cost Center | C3: Budget | D3: Actual | E3: Variance
A4: Sales and Marketing | B4: Sales | C4: =SUMIFS(ApprovedBudget!G19:G125,ApprovedBudget!$A$19:$A$125,"Sales and Marketing") -> 439840 | D4: =IF($A4<>"", SUMIFS('Detailed Receipts'!$K:$K, 'Detailed Receipts'!$A:$A, $A4, 'Detailed Receipts'!$B:$B, $B4, 'Detailed Receipts'!$D:$D, "Mar", 'Detailed Receipts'!$L:$L, "OPEX"), SUMIFS('Detailed Receipts'!$K:$K, 'Detailed Receipts'!$A:$A, MID($B4, 12, 100), 'Detailed Receipts'!$D:$D, "Mar", 'Detailed Receipts'!$L:$L, "OPEX")) -> 10121 | E4: =C4-D4 -> 429719
B5: Subtotal - Sales and Marketing | C5: =SUM(C4) -> 439840 | D5: =IF($A5<>"", SUMIFS('Detailed Receipts'!$K:$K, 'Detailed Receipts'!$A:$A, $A5, 'Detailed Receipts'!$B:$B, $B5, 'Detailed Receipts'!$D:$D, "Mar", 'Detailed Receipts'!$L:$L, "OPEX"), SUMIFS('Detailed Receipts'!$K:$K, 'Detailed Receipts'!$A:$A, MID($B5, 12, 100), 'Detailed Receipts'!$D:$D, "Mar", 'Detailed Receipts'!$L:$L, "OPEX")) -> 10121 | E5: =C5-D5 -> 429719
A6: Customer Success | B6: Customer Success | C6: =SUMIFS(ApprovedBudget!G19:G125,ApprovedBudget!$A$19:$A$125,"Customer Success",ApprovedBudget!$B$19:$B$125,"Customer Success") -> 67500 | D6: =IF($A6<>"", SUMIFS('Detailed Receipts'!$K:$K, 'Detailed Receipts'!$A:$A, $A6, 'Detailed Receipts'!$B:$B, $B6, 'Detailed Receipts'!$D:$D, "Mar", 'Detailed Receipts'!$L:$L, "OPEX"), SUMIFS('Detailed Receipts'!$K:$K, 'Detailed Receipts'!$A:$A, MID($B6, 12, 100), 'Detailed Receipts'!$D:$D, "Mar", 'Detailed Receipts'!$L:$L, "OPEX")) -> 0 | E6: =C6-D6 -> 67500
B7: Subtotal - Customer Success | C7: =SUM(C6) -> 67500 | D7: =IF($A7<>"", SUMIFS('Detailed Receipts'!$K:$K, 'Detailed Receipts'!$A:$A, $A7, 'Detailed Receipts'!$B:$B, $B7, 'Detailed Receipts'!$D:$D, "Mar", 'Detailed Receipts'!$L:$L, "OPEX"), SUMIFS('Detailed Receipts'!$K:$K, 'Detailed Receipts'!$A:$A, MID($B7, 12, 100), 'Detailed Receipts'!$D:$D, "Mar", 'Detailed Receipts'!$L:$L, "OPEX")) -> 0 | E7: =C7-D7 -> 67500
A8: Supply Chain | B8: Logistics | C8: =SUMIFS(ApprovedBudget!G19:G125,ApprovedBudget!$A$19:$A$125,"Supply Chain",ApprovedBudget!$B$19:$B$125,"Logistics") -> 13722 | D8: =IF($A8<>"", SUMIFS('Detailed Receipts'!$K:$K, 'Detailed Receipts'!$A:$A, $A8, 'Detailed Receipts'!$B:$B, $B8, 'Detailed Receipts'!$D:$D, "Mar", 'Detailed Receipts'!$L:$L, "OPEX"), SUMIFS('Detailed Receipts'!$K:$K, 'Detailed Receipts'!$A:$A, MID($B8, 12, 100), 'Detailed Receipts'!$D:$D, "Mar", 'Detailed Receipts'!$L:$L, "OPEX")) -> 0 | E8: =C8-D8 -> 13722
A9: Supply Chain | B9: Procurement | C9: =SUMIFS(ApprovedBudget!G19:G125,ApprovedBudget!$A$19:$A$125,"Supply Chain",ApprovedBudget!$B$19:$B$125,"Procurement") -> 7340 | D9: =IF($A9<>"", SUMIFS('Detailed Receipts'!$K:$K, 'Detailed Receipts'!$A:$A, $A9, 'Detailed Receipts'!$B:$B, $B9, 'Detailed Receipts'!$D:$D, "Mar", 'Detailed Receipts'!$L:$L, "OPEX"), SUMIFS('Detailed Receipts'!$K:$K, 'Detailed Receipts'!$A:$A, MID($B9, 12, 100), 'Detailed Receipts'!$D:$D, "Mar", 'Detailed Receipts'!$L:$L, "OPEX")) -> 0 | E9: =C9-D9 -> 7340
A10: Supply Chain | B10: Retail | C10: =SUMIFS(ApprovedBudget!G19:G125,ApprovedBudget!$A$19:$A$125,"Supply Chain",ApprovedBudget!$B$19:$B$125,"Retail") -> 125000 | D10: =IF($A10<>"", SUMIFS('Detailed Receipts'!$K:$K, 'Detailed Receipts'!$A:$A, $A10, 'Detailed Receipts'!$B:$B, $B10, 'Detailed Receipts'!$D:$D, "Mar", 'Detailed Receipts'!$L:$L, "OPEX"), SUMIFS('Detailed Receipts'!$K:$K, 'Detailed Receipts'!$A:$A, MID($B10, 12, 100), 'Detailed Receipts'!$D:$D, "Mar", 'Detailed Receipts'!$L:$L, "OPEX")) -> 23074 | E10: =C10-D10 -> 101926
A11: Supply Chain | B11: Warehouse | C11: =SUMIFS(ApprovedBudget!G19:G125,ApprovedBudget!$A$19:$A$125,"Supply Chain",ApprovedBudget!$B$19:$B$125,"Warehouse") -> 437629 | D11: =IF($A11<>"", SUMIFS('Detailed Receipts'!$K:$K, 'Detailed Receipts'!$A:$A, $A11, 'Detailed Receipts'!$B:$B, $B11, 'Detailed Receipts'!$D:$D, "Mar", 'Detailed Receipts'!$L:$L, "OPEX"), SUMIFS('Detailed Receipts'!$K:$K, 'Detailed Receipts'!$A:$A, MID($B11, 12, 100), 'Detailed Receipts'!$D:$D, "Mar", 'Detailed Receipts'!$L:$L, "OPEX")) -> 389654 | E11: =C11-D11 -> 47975
B12: Subtotal - Supply Chain | C12: =SUM(C8:C11) -> 583691 | D12: =IF($A12<>"", SUMIFS('Detailed Receipts'!$K:$K, 'Detailed Receipts'!$A:$A, $A12, 'Detailed Receipts'!$B:$B, $B12, 'Detailed Receipts'!$D:$D, "Mar", 'Detailed Receipts'!$L:$L, "OPEX"), SUMIFS('Detailed Receipts'!$K:$K, 'Detailed Receipts'!$A:$A, MID($B12, 12, 100), 'Detailed Receipts'!$D:$D, "Mar", 'Detailed Receipts'!$L:$L, "OPEX")) -> 412728 | E12: =C12-D12 -> 170963
A13: Aftersales | B13: Aftersales | C13: =SUMIFS(ApprovedBudget!G19:G125,ApprovedBudget!$A$19:$A$125,"Aftersales",ApprovedBudget!$B$19:$B$125,"Aftersales") -> 48000 | D13: =IF($A13<>"", SUMIFS('Detailed Receipts'!$K:$K, 'Detailed Receipts'!$A:$A, $A13, 'Detailed Receipts'!$B:$B, $B13, 'Detailed Receipts'!$D:$D, "Mar", 'Detailed Receipts'!$L:$L, "OPEX"), SUMIFS('Detailed Receipts'!$K:$K, 'Detailed Receipts'!$A:$A, MID($B13, 12, 100), 'Detailed Receipts'!$D:$D, "Mar", 'Detailed Receipts'!$L:$L, "OPEX")) -> 0 | E13: =C13-D13 -> 48000
B14: Subtotal - Aftersales | C14: =SUM(C13) -> 48000 | D14: =IF($A14<>"", SUMIFS('Detailed Receipts'!$K:$K, 'Detailed Receipts'!$A:$A, $A14, 'Detailed Receipts'!$B:$B, $B14, 'Detailed Receipts'!$D:$D, "Mar", 'Detailed Receipts'!$L:$L, "OPEX"), SUMIFS('Detailed Receipts'!$K:$K, 'Detailed Receipts'!$A:$A, MID($B14, 12, 100), 'Detailed Receipts'!$D:$D, "Mar", 'Detailed Receipts'!$L:$L, "OPEX")) -> 0 | E14: =C14-D14 -> 48000
