Workbook

Sheet Cover
C18: FINANCIAL MODEL

Sheet Unit Econ
B2: UNIT ECONOMICS 2026
C4: R280 MC | D4: D400 MC | E4: 1 Swap Station (Energy)
B5: STATION COMPOSITION
B6: Motorcycles served / station | E6: =10 -> 10
B7: Batteries / station (2 per MC) | E7: =E6*2 -> 20
B10: DAILY REVENUE
B11: Lease revenue / day (net of battery) | C11: =('MC Drivers (NRD)'!D30*30-'Energy Drivers (RideBox)'!D11)*12/365 -> 113.0137 | D11: =('MC Drivers (NRD)'!D31*30-'Energy Drivers (RideBox)'!D11)*12/365 -> 161.44814 | E11: =E6*'MC Drivers (NRD)'!D35*12/365 -> 1614.4814
B12: Battery subscription / day | C12: ='Energy Drivers (RideBox)'!D11*12/365 -> 80.72407 | D12: ='Energy Drivers (RideBox)'!D11*12/365 -> 80.72407 | E12: =E7*'Energy Drivers (RideBox)'!D11*12/365 -> 1614.4814
B13: Total Daily Revenue | C13: =C11+C12 -> 193.73777 | D13: =D11+D12 -> 242.17221 | E13: =E11+E12 -> 3228.9628
B15: DAILY COST
B16: Asset depreciation / day | C16: =('MC Drivers (NRD)'!D45+2*'MC Drivers (NRD)'!D63)/'MC Drivers (NRD)'!D185/365 -> 25.994066 | D16: =('MC Drivers (NRD)'!D52+2*'MC Drivers (NRD)'!D63)/'MC Drivers (NRD)'!D185/365 -> 36.309266 | E16: =(E6*(('MC Drivers (NRD)'!D32*'MC Drivers (NRD)'!D45+'MC Drivers (NRD)'!D33*'MC Drivers (NRD)'!D52)+2*'MC Drivers (NRD)'!D63)/'MC Drivers (NRD)'!D185+'Energy Drivers (RideBox)'!D100/'Energy Drivers (RideBox)'!D103)/365 -> 373.49178
B17: Insurance / day | C17: =4500/365 -> 12.328767 | D17: =6500/365 -> 17.808219 | E17: =('Energy Drivers (RideBox)'!D100*'Energy Drivers (RideBox)'!D104+E7*'MC Drivers (NRD)'!D63*'MC Drivers (NRD)'!D64)/365 -> 33.269587
B18: Registration / day | C18: ='MC Drivers (NRD)'!D79/365 -> 0.79908676 | D18: ='MC Drivers (NRD)'!D79/365 -> 0.79908676
B19: Site rent / day | E19: ='Energy Drivers (RideBox)'!D29*12/365 -> 146.77104
B20: Connectivity / day | E20: =('Energy Drivers (RideBox)'!D30+E7*'Energy Drivers (RideBox)'!D14)*12/365 -> 61.643836
B21: Maintenance / day | E21: ='Energy Drivers (RideBox)'!D31*12/365 -> 5.8708415
B22: Electricity / day | E22: ='Energy Drivers (RideBox)'!D26*'Energy Drivers (RideBox)'!D19*1.1 -> 107.72885
B23: Payment gateway / day | C23: =C11*'MC Drivers (NRD)'!D80 -> 3.390411 | D23: =D11*'MC Drivers (NRD)'!D80 -> 4.8434442 | E23: =E12*'Energy Drivers (RideBox)'!D13 -> 48.434442
B24: Total Daily Cost | C24: =SUM(C16:C23) -> 42.512331 | D24: =SUM(D16:D23) -> 59.760016 | E24: =SUM(E16:E23) -> 777.21037
B26: DAILY PROFITABILITY
B27: Daily Gross Profit | C27: =C13-C24 -> 151.22544 | D27: =D13-D24 -> 182.4122 | E27: =E13-E24 -> 2451.7524
B28: Daily Gross Margin | C28: =IFERROR(C27/C13,0) -> 0.78056767 | D28: =IFERROR(D27/D13,0) -> 0.75323339 | E28: =IFERROR(E27/E13,0) -> 0.7593003
B29: Daily Cash Profit (pre-dep) | C29: =C27+C16 -> 177.2195 | D29: =D27+D16 -> 218.72146 | E29: =E27+E16 -> 2825.2442
B31: ANNUALIZED P&L (per unit) NIAT
B32: Annual Revenue | C32: =C13*365 -> 70714.286 | D32: =D13*365 -> 88392.857 | E32: =E13*365 -> 1178571.4
B33: Annual Cash Operating Cost | C33: =(C24-C16)*365 -> 6029.1667 | D33: =(D24-D16)*365 -> 8559.5238 | E33: =(E24-E16)*365 -> 147357.29
B34: EBITDA | C34: =C32-C33 -> 64685.119 | D34: =D32-D33 -> 79833.333 | E34: =E32-E33 -> 1031214.1
B35: Depreciation | C35: =C16*365 -> 9487.834 | D35: =D16*365 -> 13252.882 | E35: =E16*365 -> 136324.5
B36: EBIT (Operating Profit) | C36: =C34-C35 -> 55197.285 | D36: =D34-D35 -> 66580.451 | E36: =E34-E35 -> 894889.64
B37: Tax @ 25% | C37: =MAX(C36,0)*'MC Drivers (NRD)'!D315 -> 13799.321 | D37: =MAX(D36,0)*'MC Drivers (NRD)'!D315 -> 16645.113 | E37: =MAX(E36,0)*'MC Drivers (NRD)'!D315 -> 223722.41
B38: NIAT (Net Income After Tax) | C38: =C36-C37 -> 41397.964 | D38: =D36-D37 -> 49935.338 | E38: =E36-E37 -> 671167.23
B39: Net Margin (NIAT / Revenue) | C39: =IFERROR(C38/C32,0) -> 0.58542575 | D39: =IFERROR(D38/D32,0) -> 0.56492504 | E39: =IFERROR(E38/E32,0) -> 0.56947523
B41: PAYBACK & RETURNS
B42: Asset base (capex) | C42: ='MC Drivers (NRD)'!D45+2*'MC Drivers (NRD)'!D63 -> 94878.34 | D42: ='MC Drivers (NRD)'!D52+2*'MC Drivers (NRD)'!D63 -> 132528.82 | E42: ='Energy Drivers (RideBox)'!D100+E6*(('MC Drivers (NRD)'!D32*'MC Drivers (NRD)'!D45+'MC Drivers (NRD)'!D33*'MC Drivers (NRD)'!D52)+2*'MC Drivers (NRD)'!D63) -> 1363245
B43: Payback (years, on cash profit) | C43: =IFERROR(C42/C29/365,0) -> 1.4667723 | D43: =IFERROR(D42/D29/365,0) -> 1.6600687 | E43: =IFERROR(E42/E29/365,0) -> 1.3219805
B44: 10-yr Asset IRR | C44: =IFERROR(RATE(10,C32-C33-C37,-C42),0) -> 0.52862823 | D44: =IFERROR(RATE(10,D32-D33-D37,-D42),0) -> 0.46641936 | E44: =IFERROR(RATE(10,E32-E33-E37,-E42),0) -> 0.58646574

Sheet MC Drivers (NRD)
B2: NRD MOTORCYCLE - DRIVERS & INPUTS
B3: PHP (unless noted)
C4: Note / rate | D4: 2026 | E4: 2027 | F4: 2028 | G4: 2029 | H4: 2030 | I4: 2031 | J4: 2032 | K4: 2033 | L4: 2034 | M4: 2035 | N4: 2036
B5: OPERATING METRICS
B6: Growth Assumptions
B7: New Units Leased | E7: 0.5 | F7: 0.45 | G7: 0.31 | H7: 0.17 | I7: 0.18 | J7: 0.25 | K7: 0.182 | L7: 0.094 | M7: 0.086 | N7: 0.079
B8: Units Sold Outright | E8: 0.6 | F8: 0.6 | G8: 0.4 | H8: 0.25 | I8: 0.2 | J8: 0.25 | K8: 0.2 | L8: 0.111 | M8: 0.1 | N8: 0.0909
B9: Lease-to-Own units | E9: 0.4 | F9: 0.3 | G9: 0.3 | H9: 0.3 | I9: 0.3 | J9: 0.3 | K9: 0.3 | L9: 0.3 | M9: 0.3 | N9: 0.3
B10: Lease Churn % | C10: p.a. | D10: 0 | E10: =0.03 -> 0.03 | F10: =E10 -> 0.03 | G10: =F10 -> 0.03 | H10: =G10 -> 0.03 | I10: =H10 -> 0.03 | J10: =I10 -> 0.03 | K10: =J10 -> 0.03 | L10: =K10 -> 0.03 | M10: =L10 -> 0.03 | N10: =M10 -> 0.03
B12: Beginning Leased Fleet | C12: units | D12: =D349+D350 -> 0 | E12: =E349+E350 -> 2216 | F12: =F349+F350 -> 5374 | G12: =G349+G350 -> 9888 | H12: =H349+H350 -> 15717 | I12: =I349+I350 -> 22412 | J12: =J349+J350 -> 30197 | K12: =K349+K350 -> 39863 | ... N12: =N349+N350 -> 76246
B13: (+) New Units Leased | C13: units | D13: =D351+D352 -> 2216 | E13: =E351+E352 -> 3325 | F13: =F351+F352 -> 4821 | G13: =G351+G352 -> 6316 | H13: =H351+H352 -> 7390 | I13: =I351+I352 -> 8720 | J13: =J351+J352 -> 10900 | K13: =K351+K352 -> 12883 | ... N13: =N351+N352 -> 16516
B14: (-) Lease Churn | C14: units | D14: =D353+D354 -> 0 | E14: =E353+E354 -> -167 | F14: =F353+F354 -> -307 | G14: =G353+G354 -> -487 | H14: =H353+H354 -> -695 | I14: =I353+I354 -> -935 | J14: =J353+J354 -> -1234 | K14: =K353+K354 -> -1583 | ... N14: =N353+N354 -> -2784
B15: Ending Leased Fleet (stock) | C15: units | D15: =D355+D356 -> 2216 | E15: =E355+E356 -> 5374 | F15: =F355+F356 -> 9888 | G15: =G355+G356 -> 15717 | H15: =H355+H356 -> 22412 | I15: =I355+I356 -> 30197 | J15: =J355+J356 -> 39863 | K15: =K355+K356 -> 51163 | ... N15: =N355+N356 -> 89978
B16: Avg Leased Fleet | C16: units | D16: =D357+D358 -> 1108 | E16: =E357+E358 -> 3795 | F16: =F357+F358 -> 7631 | G16: =G357+G358 -> 12802.5 | H16: =H357+H358 -> 19064.5 | I16: =I357+I358 -> 26304.5 | J16: =J357+J358 -> 35030 | K16: =K357+K358 -> 45513 | ... N16: =N357+N358 -> 83112
B17: (+) Units Sold Outright | C17: units | D17: =D359+D360 -> 1200 | E17: =E359+E360 -> 1920 | F17: =F359+F360 -> 3072 | G17: =G359+G360 -> 4301 | H17: =H359+H360 -> 5376 | I17: =I359+I360 -> 6451 | J17: =J359+J360 -> 8064 | K17: =K359+K360 -> 9677 | ... N17: =N359+N360 -> 12901
B18: Cumulative Sold Units (owner base) | C18: units | D18: =D361+D362 -> 1200 | E18: =E361+E362 -> 3120 | F18: =F361+F362 -> 6192 | G18: =G361+G362 -> 10493 | H18: =H361+H362 -> 15869 | I18: =I361+I362 -> 22320 | J18: =J361+J362 -> 30384 | K18: =K361+K362 -> 40061 | ... N18: =N361+N362 -> 75539
B20: Lease-to-Own (L2O)
B21: L2O Term | C21: months | D21: 36 | E21: =D21 -> 36 | F21: =E21 -> 36 | G21: =F21 -> 36 | H21: =G21 -> 36 | I21: =H21 -> 36 | J21: =I21 -> 36 | K21: =J21 -> 36 | L21: =K21 -> 36 | ... N21: =M21 -> 36
B22: L2O R280 Mix % | C22: % | D22: 0.2 | E22: =$D22 -> 0.2 | F22: 0.2 | G22: 0.2 | H22: 0.2 | I22: 0.2 | J22: 0.2 | K22: 0.2 | L22: 0.2 | M22: 0.2 | N22: 0.2
B23: L2O-R280 Monthly Installment | C23: 6500/1.12 | D23: =6500/1.12 -> 5803.5714 | E23: =D23 -> 5803.5714 | F23: =E23 -> 5803.5714 | G23: =F23 -> 5803.5714 | H23: =G23 -> 5803.5714 | I23: =H23 -> 5803.5714 | J23: =I23 -> 5803.5714 | K23: =J23 -> 5803.5714 | L23: =K23 -> 5803.5714 | ... N23: =M23 -> 5803.5714
B24: L2O-D400 Monthly Installment | C24: 9000/1.12 | D24: =9000/1.12 -> 8035.7143 | E24: =D24 -> 8035.7143 | F24: =E24 -> 8035.7143 | G24: =F24 -> 8035.7143 | H24: =G24 -> 8035.7143 | I24: =H24 -> 8035.7143 | J24: =I24 -> 8035.7143 | K24: =J24 -> 8035.7143 | L24: =K24 -> 8035.7143 | ... N24: =M24 -> 8035.7143
B25: (+) New L2O Units [growth-driven] | C25: units | D25: =D363+D364 -> 200 | E25: =E363+E364 -> 280 | F25: =F363+F364 -> 364 | G25: =G363+G364 -> 473 | H25: =H363+H364 -> 615 | I25: =I363+I364 -> 799 | J25: =J363+J364 -> 1038 | K25: =K363+K364 -> 1350 | ... N25: =N363+N364 -> 2965
B26: Cumulative L2O Units placed | C26: units | D26: =D365+D366 -> 200 | E26: =E365+E366 -> 480 | F26: =F365+F366 -> 844 | G26: =G365+G366 -> 1317 | H26: =H365+H366 -> 1932 | I26: =I365+I366 -> 2731 | J26: =J365+J366 -> 3769 | K26: =K365+K366 -> 5119 | ... N26: =N365+N366 -> 12120
B27: Active L2O Contracts (within term) | C27: units | D27: =D367+D368 -> 200 | E27: =E367+E368 -> 480 | F27: =F367+F368 -> 844 | G27: =G367+G368 -> 1117 | H27: =H367+H368 -> 1452 | I27: =I367+I368 -> 1887 | J27: =J367+J368 -> 2452 | K27: =K367+K368 -> 3187 | ... N27: =N367+N368 -> 7001
B29: Lease Rates (D400 & R280)
B30: R280 - Daily Lease Rate (VAT-ex) | C30: 200/1.12 | D30: =220/1.12 -> 196.42857 | E30: =220/1.12 -> 196.42857 | F30: =220/1.12 -> 196.42857 | G30: =220/1.12 -> 196.42857 | H30: =220/1.12 -> 196.42857 | I30: =220/1.12 -> 196.42857 | J30: =220/1.12 -> 196.42857 | K30: =220/1.12 -> 196.42857 | ... N30: =220/1.12 -> 196.42857
B31: D400 - Daily Lease Rate (VAT-ex) | C31: 250/1.12 | D31: =275/1.12 -> 245.53571 | E31: =275/1.12 -> 245.53571 | F31: =275/1.12 -> 245.53571 | G31: =275/1.12 -> 245.53571 | H31: =275/1.12 -> 245.53571 | I31: =275/1.12 -> 245.53571 | J31: =275/1.12 -> 245.53571 | K31: =275/1.12 -> 245.53571 | ... N31: =275/1.12 -> 245.53571
B32: R280 - Lease Mix | C32: % | D32: 0.2 | E32: =D32 -> 0.2 | F32: =E32 -> 0.2 | G32: =F32 -> 0.2 | H32: =G32 -> 0.2 | I32: =H32 -> 0.2 | J32: =I32 -> 0.2 | K32: =J32 -> 0.2 | L32: =K32 -> 0.2 | ... N32: =M32 -> 0.2
B33: D400 - Lease Mix | C33: 1-R280 | D33: =1-D32 -> 0.8 | E33: =1-E32 -> 0.8 | F33: =1-F32 -> 0.8 | G33: =1-G32 -> 0.8 | H33: =1-H32 -> 0.8 | I33: =1-I32 -> 0.8 | J33: =1-J32 -> 0.8 | K33: =1-K32 -> 0.8 | ... N33: =1-N32 -> 0.8
B34: LSE Monthly Lease Rate - R280 (net of battery) | D34: =D381 -> 3437.5 | E34: =E381 -> 3437.5 | F34: =F381 -> 3437.5 | G34: =G381 -> 3437.5 | H34: =H381 -> 3437.5 | I34: =I381 -> 3437.5 | J34: =J381 -> 3437.5 | K34: =K381 -> 3437.5 | ... N34: =N381 -> 3437.5
B35: LSE Monthly Lease Rate - D400 (net of battery) | C35: wtd*30 - Energy batt | D35: =D382 -> 4910.7143 | E35: =E382 -> 4910.7143 | F35: =F382 -> 4910.7143 | G35: =G382 -> 4910.7143 | H35: =H382 -> 4910.7143 | I35: =I382 -> 4910.7143 | J35: =J382 -> 4910.7143 | K35: =K382 -> 4910.7143 | ... N35: =N382 -> 4910.7143
B37: PRICING & UNIT ECONOMICS (feeds Revenue & COGS)
B38: Landed Cost - Motorcycle Units
B39: R280 - FOB Unit Price (USD) | C39: USD | D39: 516 | E39: =D39 -> 516 | F39: =E39 -> 516 | G39: =F39 -> 516 | H39: =G39 -> 516 | I39: =H39 -> 516 | J39: =I39 -> 516 | K39: =J39 -> 516 | L39: =K39 -> 516 | ... N39: =M39 -> 516
B40: R280 - Unit Cost (PHP) = USD x forex | D40: =D39*D316 -> 31682.4 | E40: =E39*E316 -> 31682.4 | F40: =F39*F316 -> 31682.4 | G40: =G39*G316 -> 31682.4 | H40: =H39*H316 -> 31682.4 | I40: =I39*I316 -> 31682.4 | J40: =J39*J316 -> 31682.4 | K40: =K39*K316 -> 31682.4 | ... N40: =N39*N316 -> 31682.4
B41: R280 - Freight & Shipping | C41: PHP | D41: 1800 | E41: =D41 -> 1800 | F41: =E41 -> 1800 | G41: =F41 -> 1800 | H41: =G41 -> 1800 | I41: =H41 -> 1800 | J41: =I41 -> 1800 | K41: =J41 -> 1800 | L41: =K41 -> 1800 | ... N41: =M41 -> 1800
B42: R280 - Customs / Brokerage / Duty | C42: PHP | D42: 1500 | E42: =D42 -> 1500 | F42: =E42 -> 1500 | G42: =F42 -> 1500 | H42: =G42 -> 1500 | I42: =H42 -> 1500 | J42: =I42 -> 1500 | K42: =J42 -> 1500 | L42: =K42 -> 1500 | ... N42: =M42 -> 1500
B43: R280 - Labor / Handling / PDI | C43: PHP | D43: 1000 | E43: =D43 -> 1000 | F43: =E43 -> 1000 | G43: =F43 -> 1000 | H43: =G43 -> 1000 | I43: =H43 -> 1000 | J43: =I43 -> 1000 | K43: =J43 -> 1000 | L43: =K43 -> 1000 | ... N43: =M43 -> 1000
B44: R280 - Spareparts & Accessories | C44: 30% unit cost | D44: =D40*30% -> 9504.72 | E44: =E40*30% -> 9504.72 | F44: =F40*30% -> 9504.72 | G44: =G40*30% -> 9504.72 | H44: =H40*30% -> 9504.72 | I44: =I40*30% -> 9504.72 | J44: =J40*30% -> 9504.72 | K44: =K40*30% -> 9504.72 | ... N44: =N40*30% -> 9504.72
B45: R280 - Landed Cost (sum) | D45: =D40+D41+D42+D43+D44 -> 45487.12 | E45: =E40+E41+E42+E43+E44 -> 45487.12 | F45: =F40+F41+F42+F43+F44 -> 45487.12 | G45: =G40+G41+G42+G43+G44 -> 45487.12 | H45: =H40+H41+H42+H43+H44 -> 45487.12 | I45: =I40+I41+I42+I43+I44 -> 45487.12 | J45: =J40+J41+J42+J43+J44 -> 45487.12 | K45: =K40+K41+K42+K43+K44 -> 45487.12 | ... N45: =N40+N41+N42+N43+N44 -> 45487.12
...

Sheet Energy Drivers (RideBox)
B2: RIDEBOX ENERGY - DRIVERS & INPUTS
B3: PHP (unless noted)
C4: Note / rate | D4: 2026 | E4: 2027 | F4: 2028 | G4: 2029 | H4: 2030 | I4: 2031 | J4: 2032 | K4: 2033 | L4: 2034 | M4: 2035 | N4: 2036
B5: OPERATING METRICS
B6: Network Build - Lockers
B7: Lockers Deployed - by D400/R280 active base | C7: units | D7: =D157 -> 363 | E7: =E157 -> 536 | F7: =F157 -> 795 | G7: =G157 -> 1039 | H7: =H157 -> 1241 | I7: =I157 -> 1467 | J7: =J157 -> 1829 | K7: =K157 -> 2172 | ... N7: =N157 -> 2825
B8: Cumulative Lockers - by D400/R280 active base | C8: units | D8: =D158 -> 363 | E8: =E158 -> 899 | F8: =F158 -> 1694 | G8: =G158 -> 2733 | H8: =H158 -> 3974 | I8: =I158 -> 5441 | J8: =J158 -> 7270 | K8: =K158 -> 9442 | ... N8: =N158 -> 17253
B10: ENERGY RATES & ARPU (feeds Revenue)
B11: Battery Subscription per leased MC / mo | C11: PHP/mo | D11: =2750/1.12 -> 2455.3571 | E11: =2750/1.12 -> 2455.3571 | F11: =E11 -> 2455.3571 | G11: =F11 -> 2455.3571 | H11: =G11 -> 2455.3571 | I11: =H11 -> 2455.3571 | J11: =I11 -> 2455.3571 | K11: =J11 -> 2455.3571 | L11: =K11 -> 2455.3571 | M11: =L11 -> 2455.3571 | N11: =M11 -> 2455.3571
B12: Load / Prepaid per sold+L2O MC / mo | C12: PHP/mo | D12: =880/1.12 -> 785.71429 | E12: =880/1.12 -> 785.71429 | F12: =E12 -> 785.71429 | G12: =F12 -> 785.71429 | H12: =G12 -> 785.71429 | I12: =H12 -> 785.71429 | J12: =I12 -> 785.71429 | K12: =J12 -> 785.71429 | L12: =K12 -> 785.71429 | M12: =L12 -> 785.71429 | N12: =M12 -> 785.71429
B13: Battery Payment Gateway % | C13: % | D13: 0.03 | E13: =D13 -> 0.03 | F13: =E13 -> 0.03 | G13: =F13 -> 0.03 | H13: =G13 -> 0.03 | I13: =H13 -> 0.03 | J13: =I13 -> 0.03 | K13: =J13 -> 0.03 | L13: =K13 -> 0.03 | ... N13: =M13 -> 0.03
B14: Battery Connectivity per battery / mo | C14: PHP/mo | D14: =100/1.12 -> 89.285714 | E14: =D14 -> 89.285714 | F14: =E14 -> 89.285714 | G14: =F14 -> 89.285714 | H14: =G14 -> 89.285714 | I14: =H14 -> 89.285714 | J14: =I14 -> 89.285714 | K14: =J14 -> 89.285714 | L14: =K14 -> 89.285714 | ... N14: =M14 -> 89.285714
B16: OPERATING COST RATES
B17: Locker Electricity
B18: kWh per battery | C18: 73.6*26/1000 | D18: =73.6*26/1000 -> 1.9136 | E18: =73.6*26/1000 -> 1.9136 | F18: =73.6*26/1000 -> 1.9136 | G18: =73.6*26/1000 -> 1.9136 | H18: =73.6*26/1000 -> 1.9136 | I18: =73.6*26/1000 -> 1.9136 | J18: =73.6*26/1000 -> 1.9136 | K18: =73.6*26/1000 -> 1.9136 | ... N18: =73.6*26/1000 -> 1.9136
B19: Cost per kWh | C19: PHP | D19: =14.33/1.12 -> 12.794643 | E19: =D19 -> 12.794643 | F19: =E19 -> 12.794643 | G19: =F19 -> 12.794643 | H19: =G19 -> 12.794643 | I19: =H19 -> 12.794643 | J19: =I19 -> 12.794643 | K19: =J19 -> 12.794643 | L19: =K19 -> 12.794643 | ... N19: =M19 -> 12.794643
B20: Operating hours / day | C20: hrs | D20: 14 | E20: =D20 -> 14 | F20: =E20 -> 14 | G20: =F20 -> 14 | H20: =G20 -> 14 | I20: =H20 -> 14 | J20: =I20 -> 14 | K20: =J20 -> 14 | L20: =K20 -> 14 | ... N20: =M20 -> 14
B21: Avg remaining charge of depleted batt | C21: 2/6 | D21: 0 | E21: =2/6 -> 0.33333333 | F21: =2/6 -> 0.33333333 | G21: =2/6 -> 0.33333333 | H21: =2/6 -> 0.33333333 | I21: =2/6 -> 0.33333333 | J21: =2/6 -> 0.33333333 | K21: =2/6 -> 0.33333333 | L21: =2/6 -> 0.33333333 | ... N21: =2/6 -> 0.33333333
B22: Assumed full charge time | C22: hrs | D22: 5 | E22: =D22 -> 5 | F22: =E22 -> 5 | G22: =F22 -> 5 | H22: =G22 -> 5 | I22: =H22 -> 5 | J22: =I22 -> 5 | K22: =J22 -> 5 | L22: =K22 -> 5 | ... N22: =M22 -> 5
B23: Recharge time / battery | C23: (1-rem)*time | D23: =(1-D21)*D22 -> 5 | E23: =(1-E21)*E22 -> 3.3333333 | F23: =(1-F21)*F22 -> 3.3333333 | G23: =(1-G21)*G22 -> 3.3333333 | H23: =(1-H21)*H22 -> 3.3333333 | I23: =(1-I21)*I22 -> 3.3333333 | J23: =(1-J21)*J22 -> 3.3333333 | K23: =(1-K21)*K22 -> 3.3333333 | ... N23: =(1-N21)*N22 -> 3.3333333
B24: Max swaps / battery / day | D24: =ROUNDDOWN(D20/D23,0) -> 2 | E24: =ROUNDDOWN(E20/E23,0) -> 4 | F24: =ROUNDDOWN(F20/F23,0) -> 4 | G24: =ROUNDDOWN(G20/G23,0) -> 4 | H24: =ROUNDDOWN(H20/H23,0) -> 4 | I24: =ROUNDDOWN(I20/I23,0) -> 4 | J24: =ROUNDDOWN(J20/J23,0) -> 4 | K24: =ROUNDDOWN(K20/K23,0) -> 4 | ... N24: =ROUNDDOWN(N20/N23,0) -> 4
B25: Projected swaps / locker / day | C25: 4*max*0.5 | D25: =4*D24*0.5 -> 4 | E25: =4*E24*0.5 -> 8 | F25: =4*F24*0.5 -> 8 | G25: =4*G24*0.5 -> 8 | H25: =4*H24*0.5 -> 8 | I25: =4*I24*0.5 -> 8 | J25: =4*J24*0.5 -> 8 | K25: =4*K24*0.5 -> 8 | ... N25: =4*N24*0.5 -> 8
B26: kWh generated / locker / day | D26: =D18*D25*(1-D21) -> 7.6544 | E26: =E18*E25*(1-E21) -> 10.205867 | F26: =F18*F25*(1-F21) -> 10.205867 | G26: =G18*G25*(1-G21) -> 10.205867 | H26: =H18*H25*(1-H21) -> 10.205867 | I26: =I18*I25*(1-I21) -> 10.205867 | J26: =J18*J25*(1-J21) -> 10.205867 | K26: =K18*K25*(1-K21) -> 10.205867 | ... N26: =N18*N25*(1-N21) -> 10.205867
B28: Locker OPEX Rates
B29: Locker Rent / site / mo | C29: PHP | D29: =5000/1.12 -> 4464.2857 | E29: =D29 -> 4464.2857 | F29: =E29 -> 4464.2857 | G29: =F29 -> 4464.2857 | H29: =G29 -> 4464.2857 | I29: =H29 -> 4464.2857 | J29: =I29 -> 4464.2857 | K29: =J29 -> 4464.2857 | L29: =K29 -> 4464.2857 | ... N29: =M29 -> 4464.2857
B30: Locker Connectivity / site / mo | C30: PHP | D30: =100/1.12 -> 89.285714 | E30: =D30 -> 89.285714 | F30: =E30 -> 89.285714 | G30: =F30 -> 89.285714 | H30: =G30 -> 89.285714 | I30: =H30 -> 89.285714 | J30: =I30 -> 89.285714 | K30: =J30 -> 89.285714 | L30: =K30 -> 89.285714 | ... N30: =M30 -> 89.285714
B31: Locker Maintenance / site / mo | C31: PHP | D31: =200/1.12 -> 178.57143 | E31: =D31 -> 178.57143 | F31: =E31 -> 178.57143 | G31: =F31 -> 178.57143 | H31: =G31 -> 178.57143 | I31: =H31 -> 178.57143 | J31: =I31 -> 178.57143 | K31: =J31 -> 178.57143 | L31: =K31 -> 178.57143 | ... N31: =M31 -> 178.57143
B32: Metrohub Rent / site / mo | C32: PHP | D32: 0 | E32: =D32 -> 0 | F32: =E32 -> 0 | G32: =F32 -> 0 | H32: =G32 -> 0 | I32: =H32 -> 0 | J32: =I32 -> 0 | K32: =J32 -> 0 | L32: =K32 -> 0 | ... N32: =M32 -> 0
B33: Metrohub Connectivity / site / mo | C33: PHP | D33: 0 | E33: =D33 -> 0 | F33: =E33 -> 0 | G33: =F33 -> 0 | H33: =G33 -> 0 | I33: =H33 -> 0 | J33: =I33 -> 0 | K33: =J33 -> 0 | L33: =K33 -> 0 | ... N33: =M33 -> 0
B34: Metrohub Maintenance / site / mo | C34: PHP | D34: 0 | E34: =D34 -> 0 | F34: =E34 -> 0 | G34: =F34 -> 0 | H34: =G34 -> 0 | I34: =H34 -> 0 | J34: =I34 -> 0 | K34: =J34 -> 0 | L34: =K34 -> 0 | ... N34: =M34 -> 0
B35: Metrohub Electricity / site / mo | C35: PHP | D35: 0 | E35: =D35 -> 0 | F35: =E35 -> 0 | G35: =F35 -> 0 | H35: =G35 -> 0 | I35: =H35 -> 0 | J35: =I35 -> 0 | K35: =J35 -> 0 | L35: =K35 -> 0 | ... N35: =M35 -> 0
B37: OPERATING EXPENSES (OPEX)
B38: Headcount & Salaries
B39: Headcount growth % p.a. (applied to each dept) | C39: 0.1
B40: Site Coverage per Manager | C40: lockers | D40: 0 | E40: =D40 -> 0 | F40: =E40 -> 0 | G40: =F40 -> 0 | H40: =G40 -> 0 | I40: =H40 -> 0 | J40: =I40 -> 0 | K40: =J40 -> 0 | L40: =K40 -> 0 | ... N40: =M40 -> 0
B41: Lockers per Field Tech | C41: lockers | D41: 0 | E41: =D41 -> 0 | F41: =E41 -> 0 | G41: =F41 -> 0 | H41: =G41 -> 0 | I41: =H41 -> 0 | J41: =I41 -> 0 | K41: =J41 -> 0 | L41: =K41 -> 0 | ... N41: =M41 -> 0
B42: Salary growth follows MC Salary Escalation (shared assumption)
B43: • Sales & Marketing | C43: HC | D43: 2 | E43: =D43*(1+$C$39) -> 2.2 | F43: =E43*(1+$C$39) -> 2.42 | G43: =F43*(1+$C$39) -> 2.662 | H43: =G43*(1+$C$39) -> 2.9282 | I43: =H43*(1+$C$39) -> 3.22102 | J43: =I43*(1+$C$39) -> 3.543122 | K43: =J43*(1+$C$39) -> 3.8974342 | L43: =K43*(1+$C$39) -> 4.2871776 | ... N43: =M43*(1+$C$39) -> 5.1874849
C44: PHP/mo | D44: 108250 | E44: =D44*(1+'MC Drivers (NRD)'!E89) -> 113662.5 | F44: =E44*(1+'MC Drivers (NRD)'!F89) -> 119345.62 | G44: =F44*(1+'MC Drivers (NRD)'!G89) -> 125312.91 | H44: =G44*(1+'MC Drivers (NRD)'!H89) -> 131578.55 | I44: =H44*(1+'MC Drivers (NRD)'!I89) -> 138157.48 | J44: =I44*(1+'MC Drivers (NRD)'!J89) -> 145065.35 | K44: =J44*(1+'MC Drivers (NRD)'!K89) -> 152318.62 | L44: =K44*(1+'MC Drivers (NRD)'!L89) -> 159934.55 | ... N44: =M44*(1+'MC Drivers (NRD)'!N89) -> 176327.84
C45: 13 | D45: =D43*D44*$C45 -> 2814500 | E45: =E43*E44*$C45 -> 3250747.5 | F45: =F43*F44*$C45 -> 3754613.4 | G45: =G43*G44*$C45 -> 4336578.4 | H45: =H43*H44*$C45 -> 5008748.1 | I45: =I43*I44*$C45 -> 5785104 | J45: =J43*J44*$C45 -> 6681795.2 | K45: =K43*K44*$C45 -> 7717473.4 | ... N45: =N43*N44*$C45 -> 11891074
...

Sheet NRD MC P&L
B2: NRD MOTORCYCLE - PROFIT & LOSS
B3: All figures in PHP Millions (unless noted)
D4: 2026 | E4: 2027 | F4: 2028 | G4: 2029 | H4: 2030 | I4: 2031 | J4: 2032 | K4: 2033 | L4: 2034 | M4: 2035 | N4: 2036
B5: REVENUE
B6: Lease Revenue (LSE, net of battery) | D6: ='MC Drivers (NRD)'!D15*'MC Drivers (NRD)'!D32*'MC Drivers (NRD)'!D34*12+'MC Drivers (NRD)'!D15*'MC Drivers (NRD)'!D33*'MC Drivers (NRD)'!D35*12 -> 1.2275057e+08 | E6: ='MC Drivers (NRD)'!E15*'MC Drivers (NRD)'!E32*'MC Drivers (NRD)'!E34*12+'MC Drivers (NRD)'!E15*'MC Drivers (NRD)'!E33*'MC Drivers (NRD)'!E35*12 -> 2.9768121e+08 | F6: ='MC Drivers (NRD)'!F15*'MC Drivers (NRD)'!F32*'MC Drivers (NRD)'!F34*12+'MC Drivers (NRD)'!F15*'MC Drivers (NRD)'!F33*'MC Drivers (NRD)'!F35*12 -> 5.4772457e+08 | G6: ='MC Drivers (NRD)'!G15*'MC Drivers (NRD)'!G32*'MC Drivers (NRD)'!G34*12+'MC Drivers (NRD)'!G15*'MC Drivers (NRD)'!G33*'MC Drivers (NRD)'!G35*12 -> 8.7060954e+08 | H6: ='MC Drivers (NRD)'!H15*'MC Drivers (NRD)'!H32*'MC Drivers (NRD)'!H34*12+'MC Drivers (NRD)'!H15*'MC Drivers (NRD)'!H33*'MC Drivers (NRD)'!H35*12 -> 1241464714 | I6: ='MC Drivers (NRD)'!I15*'MC Drivers (NRD)'!I32*'MC Drivers (NRD)'!I34*12+'MC Drivers (NRD)'!I15*'MC Drivers (NRD)'!I33*'MC Drivers (NRD)'!I35*12 -> 1672698107 | J6: ='MC Drivers (NRD)'!J15*'MC Drivers (NRD)'!J32*'MC Drivers (NRD)'!J34*12+'MC Drivers (NRD)'!J15*'MC Drivers (NRD)'!J33*'MC Drivers (NRD)'!J35*12 -> 2208125464 | K6: ='MC Drivers (NRD)'!K15*'MC Drivers (NRD)'!K32*'MC Drivers (NRD)'!K34*12+'MC Drivers (NRD)'!K15*'MC Drivers (NRD)'!K33*'MC Drivers (NRD)'!K35*12 -> 2834064750 | ... N6: ='MC Drivers (NRD)'!N15*'MC Drivers (NRD)'!N32*'MC Drivers (NRD)'!N34*12+'MC Drivers (NRD)'!N15*'MC Drivers (NRD)'!N33*'MC Drivers (NRD)'!N35*12 -> 4984138500
B7: Outright Sale Revenue | D7: ='MC Drivers (NRD)'!D17*'MC Drivers (NRD)'!D53*'MC Drivers (NRD)'!D71*(1-'MC Drivers (NRD)'!D73)+'MC Drivers (NRD)'!D17*'MC Drivers (NRD)'!D54*'MC Drivers (NRD)'!D72*(1-'MC Drivers (NRD)'!D73) -> 1.8899807e+08 | E7: ='MC Drivers (NRD)'!E17*'MC Drivers (NRD)'!E53*'MC Drivers (NRD)'!E71*(1-'MC Drivers (NRD)'!E73)+'MC Drivers (NRD)'!E17*'MC Drivers (NRD)'!E54*'MC Drivers (NRD)'!E72*(1-'MC Drivers (NRD)'!E73) -> 3.0239691e+08 | F7: ='MC Drivers (NRD)'!F17*'MC Drivers (NRD)'!F53*'MC Drivers (NRD)'!F71*(1-'MC Drivers (NRD)'!F73)+'MC Drivers (NRD)'!F17*'MC Drivers (NRD)'!F54*'MC Drivers (NRD)'!F72*(1-'MC Drivers (NRD)'!F73) -> 483835061 | G7: ='MC Drivers (NRD)'!G17*'MC Drivers (NRD)'!G53*'MC Drivers (NRD)'!G71*(1-'MC Drivers (NRD)'!G73)+'MC Drivers (NRD)'!G17*'MC Drivers (NRD)'!G54*'MC Drivers (NRD)'!G72*(1-'MC Drivers (NRD)'!G73) -> 677400585 | H7: ='MC Drivers (NRD)'!H17*'MC Drivers (NRD)'!H53*'MC Drivers (NRD)'!H71*(1-'MC Drivers (NRD)'!H73)+'MC Drivers (NRD)'!H17*'MC Drivers (NRD)'!H54*'MC Drivers (NRD)'!H72*(1-'MC Drivers (NRD)'!H73) -> 8.4671136e+08 | I7: ='MC Drivers (NRD)'!I17*'MC Drivers (NRD)'!I53*'MC Drivers (NRD)'!I71*(1-'MC Drivers (NRD)'!I73)+'MC Drivers (NRD)'!I17*'MC Drivers (NRD)'!I54*'MC Drivers (NRD)'!I72*(1-'MC Drivers (NRD)'!I73) -> 1016022128 | J7: ='MC Drivers (NRD)'!J17*'MC Drivers (NRD)'!J53*'MC Drivers (NRD)'!J71*(1-'MC Drivers (NRD)'!J73)+'MC Drivers (NRD)'!J17*'MC Drivers (NRD)'!J54*'MC Drivers (NRD)'!J72*(1-'MC Drivers (NRD)'!J73) -> 1270067035 | K7: ='MC Drivers (NRD)'!K17*'MC Drivers (NRD)'!K53*'MC Drivers (NRD)'!K71*(1-'MC Drivers (NRD)'!K73)+'MC Drivers (NRD)'!K17*'MC Drivers (NRD)'!K54*'MC Drivers (NRD)'!K72*(1-'MC Drivers (NRD)'!K73) -> 1524111942 | ... N7: ='MC Drivers (NRD)'!N17*'MC Drivers (NRD)'!N53*'MC Drivers (NRD)'!N71*(1-'MC Drivers (NRD)'!N73)+'MC Drivers (NRD)'!N17*'MC Drivers (NRD)'!N54*'MC Drivers (NRD)'!N72*(1-'MC Drivers (NRD)'!N73) -> 2031886758
B8: Lease-to-Own Revenue | D8: ='MC Drivers (NRD)'!D27*'MC Drivers (NRD)'!D22*'MC Drivers (NRD)'!D23*12+'MC Drivers (NRD)'!D27*(1-'MC Drivers (NRD)'!D22)*'MC Drivers (NRD)'!D24*12 -> 18214286 | E8: ='MC Drivers (NRD)'!E27*'MC Drivers (NRD)'!E22*'MC Drivers (NRD)'!E23*12+'MC Drivers (NRD)'!E27*(1-'MC Drivers (NRD)'!E22)*'MC Drivers (NRD)'!E24*12 -> 43714286 | F8: ='MC Drivers (NRD)'!F27*'MC Drivers (NRD)'!F22*'MC Drivers (NRD)'!F23*12+'MC Drivers (NRD)'!F27*(1-'MC Drivers (NRD)'!F22)*'MC Drivers (NRD)'!F24*12 -> 76864286 | G8: ='MC Drivers (NRD)'!G27*'MC Drivers (NRD)'!G22*'MC Drivers (NRD)'!G23*12+'MC Drivers (NRD)'!G27*(1-'MC Drivers (NRD)'!G22)*'MC Drivers (NRD)'!G24*12 -> 1.0172679e+08 | H8: ='MC Drivers (NRD)'!H27*'MC Drivers (NRD)'!H22*'MC Drivers (NRD)'!H23*12+'MC Drivers (NRD)'!H27*(1-'MC Drivers (NRD)'!H22)*'MC Drivers (NRD)'!H24*12 -> 1.3223571e+08 | I8: ='MC Drivers (NRD)'!I27*'MC Drivers (NRD)'!I22*'MC Drivers (NRD)'!I23*12+'MC Drivers (NRD)'!I27*(1-'MC Drivers (NRD)'!I22)*'MC Drivers (NRD)'!I24*12 -> 1.7185179e+08 | J8: ='MC Drivers (NRD)'!J27*'MC Drivers (NRD)'!J22*'MC Drivers (NRD)'!J23*12+'MC Drivers (NRD)'!J27*(1-'MC Drivers (NRD)'!J22)*'MC Drivers (NRD)'!J24*12 -> 2.2330714e+08 | K8: ='MC Drivers (NRD)'!K27*'MC Drivers (NRD)'!K22*'MC Drivers (NRD)'!K23*12+'MC Drivers (NRD)'!K27*(1-'MC Drivers (NRD)'!K22)*'MC Drivers (NRD)'!K24*12 -> 2.9024464e+08 | ... N8: ='MC Drivers (NRD)'!N27*'MC Drivers (NRD)'!N22*'MC Drivers (NRD)'!N23*12+'MC Drivers (NRD)'!N27*(1-'MC Drivers (NRD)'!N22)*'MC Drivers (NRD)'!N24*12 -> 6.3759107e+08
B9: Aftersales Service Revenue | D9: =D7*'MC Drivers (NRD)'!D76 -> 18899807 | E9: =E7*'MC Drivers (NRD)'!E76 -> 30239691 | F9: =F7*'MC Drivers (NRD)'!F76 -> 48383506 | G9: =G7*'MC Drivers (NRD)'!G76 -> 67740058 | H9: =H7*'MC Drivers (NRD)'!H76 -> 84671136 | I9: =I7*'MC Drivers (NRD)'!I76 -> 1.0160221e+08 | J9: =J7*'MC Drivers (NRD)'!J76 -> 1.270067e+08 | K9: =K7*'MC Drivers (NRD)'!K76 -> 1.5241119e+08 | ... N9: =N7*'MC Drivers (NRD)'!N76 -> 2.0318868e+08
B10: Total Revenue | D10: =SUM(D6:D9) -> 3.4886273e+08 | E10: =SUM(E6:E9) -> 6.740321e+08 | F10: =SUM(F6:F9) -> 1156807424 | G10: =SUM(G6:G9) -> 1717476965 | H10: =SUM(H6:H9) -> 2305082921 | I10: =SUM(I6:I9) -> 2962174234 | J10: =SUM(J6:J9) -> 3828506346 | K10: =SUM(K6:K9) -> 4800832529 | ... N10: =SUM(N6:N9) -> 7856805006
B12: COST OF SALES
B13: MC Insurance | D13: =-'MC Drivers (NRD)'!D15*'MC Drivers (NRD)'!D78*12 -> -9299285.7 | E13: =-'MC Drivers (NRD)'!E15*'MC Drivers (NRD)'!E78*12 -> -22551607 | F13: =-'MC Drivers (NRD)'!F15*'MC Drivers (NRD)'!F78*12 -> -41494286 | G13: =-'MC Drivers (NRD)'!G15*'MC Drivers (NRD)'!G78*12 -> -65955268 | H13: =-'MC Drivers (NRD)'!H15*'MC Drivers (NRD)'!H78*12 -> -94050357 | I13: =-'MC Drivers (NRD)'!I15*'MC Drivers (NRD)'!I78*12 -> -1.2671955e+08 | J13: =-'MC Drivers (NRD)'!J15*'MC Drivers (NRD)'!J78*12 -> -1.6728223e+08 | K13: =-'MC Drivers (NRD)'!K15*'MC Drivers (NRD)'!K78*12 -> -214701875 | ... N13: =-'MC Drivers (NRD)'!N15*'MC Drivers (NRD)'!N78*12 -> -377586250
B14: Battery Insurance | D14: =-'MC Drivers (NRD)'!D221 -> -2189018.9 | E14: =-'MC Drivers (NRD)'!E221 -> -5308568.3 | F14: =-'MC Drivers (NRD)'!F221 -> -9767607.7 | G14: =-'MC Drivers (NRD)'!G221 -> -15525636 | H14: =-'MC Drivers (NRD)'!H221 -> -22139120 | I14: =-'MC Drivers (NRD)'!I221 -> -29829333 | J14: =-'MC Drivers (NRD)'!J221 -> -39377644 | K14: =-'MC Drivers (NRD)'!K221 -> -50540060 | ... N14: =-'MC Drivers (NRD)'!N221 -> -88882464
B15: MC Registration | D15: =-('MC Drivers (NRD)'!D13+'MC Drivers (NRD)'!D17+'MC Drivers (NRD)'!D25)*'MC Drivers (NRD)'!D79 -> -1054666.7 | E15: =-('MC Drivers (NRD)'!E13+'MC Drivers (NRD)'!E17+'MC Drivers (NRD)'!E25)*'MC Drivers (NRD)'!E79 -> -1611458.3 | F15: =-('MC Drivers (NRD)'!F13+'MC Drivers (NRD)'!F17+'MC Drivers (NRD)'!F25)*'MC Drivers (NRD)'!F79 -> -2408291.7 | G15: =-('MC Drivers (NRD)'!G13+'MC Drivers (NRD)'!G17+'MC Drivers (NRD)'!G25)*'MC Drivers (NRD)'!G79 -> -3234583.3 | H15: =-('MC Drivers (NRD)'!H13+'MC Drivers (NRD)'!H17+'MC Drivers (NRD)'!H25)*'MC Drivers (NRD)'!H79 -> -3902791.7 | I15: =-('MC Drivers (NRD)'!I13+'MC Drivers (NRD)'!I17+'MC Drivers (NRD)'!I25)*'MC Drivers (NRD)'!I79 -> -4657916.7 | J15: =-('MC Drivers (NRD)'!J13+'MC Drivers (NRD)'!J17+'MC Drivers (NRD)'!J25)*'MC Drivers (NRD)'!J79 -> -5833916.7 | K15: =-('MC Drivers (NRD)'!K13+'MC Drivers (NRD)'!K17+'MC Drivers (NRD)'!K25)*'MC Drivers (NRD)'!K79 -> -6973750 | ... N15: =-('MC Drivers (NRD)'!N13+'MC Drivers (NRD)'!N17+'MC Drivers (NRD)'!N25)*'MC Drivers (NRD)'!N79 -> -9444750
B16: Cost of Motorcycle Sales | D16: =-('MC Drivers (NRD)'!D17*'MC Drivers (NRD)'!D53*'MC Drivers (NRD)'!D67+'MC Drivers (NRD)'!D17*'MC Drivers (NRD)'!D54*'MC Drivers (NRD)'!D68) -> -1.4999847e+08 | E16: =-('MC Drivers (NRD)'!E17*'MC Drivers (NRD)'!E53*'MC Drivers (NRD)'!E67+'MC Drivers (NRD)'!E17*'MC Drivers (NRD)'!E54*'MC Drivers (NRD)'!E68) -> -2.3999755e+08 | F16: =-('MC Drivers (NRD)'!F17*'MC Drivers (NRD)'!F53*'MC Drivers (NRD)'!F67+'MC Drivers (NRD)'!F17*'MC Drivers (NRD)'!F54*'MC Drivers (NRD)'!F68) -> -3.8399608e+08 | G16: =-('MC Drivers (NRD)'!G17*'MC Drivers (NRD)'!G53*'MC Drivers (NRD)'!G67+'MC Drivers (NRD)'!G17*'MC Drivers (NRD)'!G54*'MC Drivers (NRD)'!G68) -> -5.3761951e+08 | H16: =-('MC Drivers (NRD)'!H17*'MC Drivers (NRD)'!H53*'MC Drivers (NRD)'!H67+'MC Drivers (NRD)'!H17*'MC Drivers (NRD)'!H54*'MC Drivers (NRD)'!H68) -> -6.7199314e+08 | I16: =-('MC Drivers (NRD)'!I17*'MC Drivers (NRD)'!I53*'MC Drivers (NRD)'!I67+'MC Drivers (NRD)'!I17*'MC Drivers (NRD)'!I54*'MC Drivers (NRD)'!I68) -> -8.0636677e+08 | J16: =-('MC Drivers (NRD)'!J17*'MC Drivers (NRD)'!J53*'MC Drivers (NRD)'!J67+'MC Drivers (NRD)'!J17*'MC Drivers (NRD)'!J54*'MC Drivers (NRD)'!J68) -> -1007989710 | K16: =-('MC Drivers (NRD)'!K17*'MC Drivers (NRD)'!K53*'MC Drivers (NRD)'!K67+'MC Drivers (NRD)'!K17*'MC Drivers (NRD)'!K54*'MC Drivers (NRD)'!K68) -> -1209612652 | ... N16: =-('MC Drivers (NRD)'!N17*'MC Drivers (NRD)'!N53*'MC Drivers (NRD)'!N67+'MC Drivers (NRD)'!N17*'MC Drivers (NRD)'!N54*'MC Drivers (NRD)'!N68) -> -1612608538
B17: Aftersales COGS | D17: =-D9*'MC Drivers (NRD)'!D77 -> -7559922.8 | E17: =-E9*'MC Drivers (NRD)'!E77 -> -12095877 | F17: =-F9*'MC Drivers (NRD)'!F77 -> -19353402 | G17: =-G9*'MC Drivers (NRD)'!G77 -> -27096023 | H17: =-H9*'MC Drivers (NRD)'!H77 -> -33868454 | I17: =-I9*'MC Drivers (NRD)'!I77 -> -40640885 | J17: =-J9*'MC Drivers (NRD)'!J77 -> -50802681 | K17: =-K9*'MC Drivers (NRD)'!K77 -> -60964478 | ... N17: =-N9*'MC Drivers (NRD)'!N77 -> -81275470
B18: Lease Payment Gateway | D18: =-(D6+D8)*'MC Drivers (NRD)'!D80 -> -4228945.7 | E18: =-(E6+E8)*'MC Drivers (NRD)'!E80 -> -10241865 | F18: =-(F6+F8)*'MC Drivers (NRD)'!F80 -> -18737666 | G18: =-(G6+G8)*'MC Drivers (NRD)'!G80 -> -29170090 | H18: =-(H6+H8)*'MC Drivers (NRD)'!H80 -> -41211013 | I18: =-(I6+I8)*'MC Drivers (NRD)'!I80 -> -55336497 | J18: =-(J6+J8)*'MC Drivers (NRD)'!J80 -> -72942978 | K18: =-(K6+K8)*'MC Drivers (NRD)'!K80 -> -93729282 | ... N18: =-(N6+N8)*'MC Drivers (NRD)'!N80 -> -1.6865189e+08
B19: Total Cost of Sales | D19: =SUM(D13:D18) -> -1.7433031e+08 | E19: =SUM(E13:E18) -> -2.9180693e+08 | F19: =SUM(F13:F18) -> -4.7575733e+08 | G19: =SUM(G13:G18) -> -6.7860111e+08 | H19: =SUM(H13:H18) -> -8.6716488e+08 | I19: =SUM(I13:I18) -> -1063550954 | J19: =SUM(J13:J18) -> -1344229163 | K19: =SUM(K13:K18) -> -1636522096 | ... N19: =SUM(N13:N18) -> -2338449360
B20: GROSS PROFIT | D20: =D10+D19 -> 1.7453243e+08 | E20: =E10+E19 -> 382225179 | F20: =F10+F19 -> 6.8105009e+08 | G20: =G10+G19 -> 1038875853 | H20: =H10+H19 -> 1437918044 | I20: =I10+I19 -> 1898623280 | J20: =J10+J19 -> 2484277183 | K20: =K10+K19 -> 3164310432 | ... N20: =N10+N19 -> 5518355646
B21: GP margin | D21: =IFERROR(D20/D10,0) -> 0.50028968 | E21: =IFERROR(E20/E10,0) -> 0.56707266 | F21: =IFERROR(F20/F10,0) -> 0.58873247 | G21: =IFERROR(G20/G10,0) -> 0.60488488 | H21: =IFERROR(H20/H10,0) -> 0.62380317 | I21: =IFERROR(I20/I10,0) -> 0.64095598 | J21: =IFERROR(J20/J10,0) -> 0.6488894 | K21: =IFERROR(K20/K10,0) -> 0.65911702 | ... N21: =IFERROR(N20/N10,0) -> 0.70236637
B23: OPERATING EXPENSES
B24: Salaries | D24: =-'MC Drivers (NRD)'!D135 -> -54684968 | E24: =-'MC Drivers (NRD)'!E135 -> -63161138 | F24: =-'MC Drivers (NRD)'!F135 -> -72951114 | G24: =-'MC Drivers (NRD)'!G135 -> -84258537 | H24: =-'MC Drivers (NRD)'!H135 -> -97318610 | I24: =-'MC Drivers (NRD)'!I135 -> -1.12403e+08 | J24: =-'MC Drivers (NRD)'!J135 -> -1.2982546e+08 | K24: =-'MC Drivers (NRD)'!K135 -> -1.4994841e+08 | ... N24: =-'MC Drivers (NRD)'!N135 -> -2.3104033e+08
B25: Employee Benefits | D25: =-'MC Drivers (NRD)'!D136 -> -5468496.8 | E25: =-'MC Drivers (NRD)'!E136 -> -6316113.8 | F25: =-'MC Drivers (NRD)'!F136 -> -7295111.4 | G25: =-'MC Drivers (NRD)'!G136 -> -8425853.7 | H25: =-'MC Drivers (NRD)'!H136 -> -9731861 | I25: =-'MC Drivers (NRD)'!I136 -> -11240300 | J25: =-'MC Drivers (NRD)'!J136 -> -12982546 | K25: =-'MC Drivers (NRD)'!K136 -> -14994841 | ... N25: =-'MC Drivers (NRD)'!N136 -> -23104033
B26: Sales Commission | D26: =-D7*'MC Drivers (NRD)'!D81 -> -3779961.4 | E26: =-E7*'MC Drivers (NRD)'!E81 -> -6047938.3 | F26: =-F7*'MC Drivers (NRD)'!F81 -> -9676701.2 | G26: =-G7*'MC Drivers (NRD)'!G81 -> -13548012 | H26: =-H7*'MC Drivers (NRD)'!H81 -> -16934227 | I26: =-I7*'MC Drivers (NRD)'!I81 -> -20320443 | J26: =-J7*'MC Drivers (NRD)'!J81 -> -25401341 | K26: =-K7*'MC Drivers (NRD)'!K81 -> -30482239 | ... N26: =-N7*'MC Drivers (NRD)'!N81 -> -40637735
B27: Rent - Head Office | D27: =-'MC Drivers (NRD)'!D142 -> -1714285.7 | E27: =-'MC Drivers (NRD)'!E142 -> -1800000 | F27: =-'MC Drivers (NRD)'!F142 -> -1890000 | G27: =-'MC Drivers (NRD)'!G142 -> -1984500 | H27: =-'MC Drivers (NRD)'!H142 -> -2083725 | I27: =-'MC Drivers (NRD)'!I142 -> -2187911.2 | J27: =-'MC Drivers (NRD)'!J142 -> -2297306.8 | K27: =-'MC Drivers (NRD)'!K142 -> -2412172.2 | ... N27: =-'MC Drivers (NRD)'!N142 -> -2792390.8
B28: Rent - Warehouse | D28: =-'MC Drivers (NRD)'!D145 -> -2235535.7 | E28: =-'MC Drivers (NRD)'!E145 -> -2347312.5 | F28: =-'MC Drivers (NRD)'!F145 -> -2464678.1 | G28: =-'MC Drivers (NRD)'!G145 -> -2587912 | H28: =-'MC Drivers (NRD)'!H145 -> -5434615.3 | I28: =-'MC Drivers (NRD)'!I145 -> -5706346 | J28: =-'MC Drivers (NRD)'!J145 -> -5991663.3 | K28: =-'MC Drivers (NRD)'!K145 -> -6291246.5 | ... N28: =-'MC Drivers (NRD)'!N145 -> -7282904.2
B29: Rent - Showroom / Store Room | D29: =-'MC Drivers (NRD)'!D148 -> -910714.29 | E29: =-'MC Drivers (NRD)'!E148 -> -956250 | F29: =-'MC Drivers (NRD)'!F148 -> -2008125 | G29: =-'MC Drivers (NRD)'!G148 -> -2108531.2 | H29: =-'MC Drivers (NRD)'!H148 -> -3320936.7 | I29: =-'MC Drivers (NRD)'!I148 -> -3486983.6 | J29: =-'MC Drivers (NRD)'!J148 -> -4881777 | K29: =-'MC Drivers (NRD)'!K148 -> -5125865.8 | ... N29: =-'MC Drivers (NRD)'!N148 -> -8900745.6
B30: Utilities (all locations) | D30: =-'MC Drivers (NRD)'!D170 -> -1221428.6 | E30: =-'MC Drivers (NRD)'!E170 -> -1282500 | F30: =-'MC Drivers (NRD)'!F170 -> -1630125 | G30: =-'MC Drivers (NRD)'!G170 -> -1711631.2 | H30: =-'MC Drivers (NRD)'!H170 -> -2630702.8 | I30: =-'MC Drivers (NRD)'!I170 -> -2762238 | J30: =-'MC Drivers (NRD)'!J170 -> -3244945.9 | K30: =-'MC Drivers (NRD)'!K170 -> -3407193.2 | ... N30: =-'MC Drivers (NRD)'!N170 -> -4781969.2
B31: Marketing | D31: =-D10*'MC Drivers (NRD)'!D82 -> -6977254.7 | E31: =-E10*'MC Drivers (NRD)'!E82 -> -13480642 | F31: =-F10*'MC Drivers (NRD)'!F82 -> -23136148 | G31: =-G10*'MC Drivers (NRD)'!G82 -> -34349539 | H31: =-H10*'MC Drivers (NRD)'!H82 -> -46101658 | I31: =-I10*'MC Drivers (NRD)'!I82 -> -59243485 | J31: =-J10*'MC Drivers (NRD)'!J82 -> -76570127 | K31: =-K10*'MC Drivers (NRD)'!K82 -> -96016651 | ... N31: =-N10*'MC Drivers (NRD)'!N82 -> -1.571361e+08
B32: Legal & Permits | D32: =-'MC Drivers (NRD)'!D178 -> -1987142.9 | E32: =-'MC Drivers (NRD)'!E178 -> -2185857.1 | F32: =-'MC Drivers (NRD)'!F178 -> -2404442.9 | G32: =-'MC Drivers (NRD)'!G178 -> -2644887.1 | H32: =-'MC Drivers (NRD)'!H178 -> -2909375.9 | I32: =-'MC Drivers (NRD)'!I178 -> -3200313.4 | J32: =-'MC Drivers (NRD)'!J178 -> -3520344.8 | K32: =-'MC Drivers (NRD)'!K178 -> -3872379.3 | ... N32: =-'MC Drivers (NRD)'!N178 -> -5154136.8
B33: Dues & Subscriptions | D33: =-'MC Drivers (NRD)'!D179 -> -1339285.7 | E33: =-'MC Drivers (NRD)'!E179 -> -1473214.3 | F33: =-'MC Drivers (NRD)'!F179 -> -1620535.7 | G33: =-'MC Drivers (NRD)'!G179 -> -1782589.3 | H33: =-'MC Drivers (NRD)'!H179 -> -1960848.2 | I33: =-'MC Drivers (NRD)'!I179 -> -2156933 | J33: =-'MC Drivers (NRD)'!J179 -> -2372626.3 | K33: =-'MC Drivers (NRD)'!K179 -> -2609889 | ... N33: =-'MC Drivers (NRD)'!N179 -> -3473762.2
B34: Repairs & Maintenance | D34: =-'MC Drivers (NRD)'!D180 -> -189000 | E34: =-'MC Drivers (NRD)'!E180 -> -207900 | F34: =-'MC Drivers (NRD)'!F180 -> -228690 | G34: =-'MC Drivers (NRD)'!G180 -> -251559 | H34: =-'MC Drivers (NRD)'!H180 -> -276714.9 | I34: =-'MC Drivers (NRD)'!I180 -> -304386.39 | J34: =-'MC Drivers (NRD)'!J180 -> -334825.03 | K34: =-'MC Drivers (NRD)'!K180 -> -368307.53 | ... N34: =-'MC Drivers (NRD)'!N180 -> -490217.33
B35: Office Expenses | D35: =-'MC Drivers (NRD)'!D181 -> -500000 | E35: =-'MC Drivers (NRD)'!E181 -> -550000 | F35: =-'MC Drivers (NRD)'!F181 -> -605000 | G35: =-'MC Drivers (NRD)'!G181 -> -665500 | H35: =-'MC Drivers (NRD)'!H181 -> -732050 | I35: =-'MC Drivers (NRD)'!I181 -> -805255 | J35: =-'MC Drivers (NRD)'!J181 -> -885780.5 | K35: =-'MC Drivers (NRD)'!K181 -> -974358.55 | ... N35: =-'MC Drivers (NRD)'!N181 -> -1296871.2
B36: Total Operating Expenses | D36: =SUM(D24:D35) -> -81008074 | E36: =SUM(E24:E35) -> -99808866 | F36: =SUM(F24:F35) -> -1.2591067e+08 | G36: =SUM(G24:G35) -> -1.5431905e+08 | H36: =SUM(H24:H35) -> -1.8943533e+08 | I36: =SUM(I24:I35) -> -2.2381759e+08 | J36: =SUM(J24:J35) -> -2.6830874e+08 | K36: =SUM(K24:K35) -> -3.1650355e+08 | ... N36: =SUM(N24:N35) -> -4.860912e+08
B38: EBITDA | D38: =D20+D36 -> 93524353 | E38: =E20+E36 -> 2.8241631e+08 | F38: =F20+F36 -> 5.5513942e+08 | G38: =G20+G36 -> 8.845568e+08 | H38: =H20+H36 -> 1248482719 | I38: =I20+I36 -> 1674805691 | J38: =J20+J36 -> 2215968440 | K38: =K20+K36 -> 2847806885 | ... N38: =N20+N36 -> 5032264445
B39: Depreciation & Amortization | D39: ='MC Drivers (NRD)'!D200+'MC Drivers (NRD)'!D220+'MC Drivers (NRD)'!D239+'MC Drivers (NRD)'!D304 -> 15339921 | E39: ='MC Drivers (NRD)'!E200+'MC Drivers (NRD)'!E220+'MC Drivers (NRD)'!E239+'MC Drivers (NRD)'!E304 -> 52870495 | F39: ='MC Drivers (NRD)'!F200+'MC Drivers (NRD)'!F220+'MC Drivers (NRD)'!F239+'MC Drivers (NRD)'!F304 -> 1.0673013e+08 | G39: ='MC Drivers (NRD)'!G200+'MC Drivers (NRD)'!G220+'MC Drivers (NRD)'!G239+'MC Drivers (NRD)'!G304 -> 1.7952727e+08 | H39: ='MC Drivers (NRD)'!H200+'MC Drivers (NRD)'!H220+'MC Drivers (NRD)'!H239+'MC Drivers (NRD)'!H304 -> 2.6883256e+08 | I39: ='MC Drivers (NRD)'!I200+'MC Drivers (NRD)'!I220+'MC Drivers (NRD)'!I239+'MC Drivers (NRD)'!I304 -> 3.7401099e+08 | J39: ='MC Drivers (NRD)'!J200+'MC Drivers (NRD)'!J220+'MC Drivers (NRD)'!J239+'MC Drivers (NRD)'!J304 -> 502319966 | K39: ='MC Drivers (NRD)'!K200+'MC Drivers (NRD)'!K220+'MC Drivers (NRD)'!K239+'MC Drivers (NRD)'!K304 -> 6.583493e+08 | ... N39: ='MC Drivers (NRD)'!N200+'MC Drivers (NRD)'!N220+'MC Drivers (NRD)'!N239+'MC Drivers (NRD)'!N304 -> 1237227626
B40: OPERATING INCOME (EBIT) | D40: =D38-D39 -> 78184431 | E40: =E38-E39 -> 2.2954582e+08 | F40: =F38-F39 -> 4.4840929e+08 | G40: =G38-G39 -> 7.0502953e+08 | H40: =H38-H39 -> 9.7965015e+08 | I40: =I38-I39 -> 1300794703 | J40: =J38-J39 -> 1713648474 | K40: =K38-K39 -> 2189457583 | ... N40: =N38-N39 -> 3795036819
B41: EBITDA margin | D41: =D38/D10 -> 0.26808353 | E41: =E38/E10 -> 0.41899534 | F41: =F38/F10 -> 0.47988923 | G41: =G38/G10 -> 0.5150327 | H41: =H38/H10 -> 0.54162161 | I41: =I38/I10 -> 0.56539743 | J41: =J38/J10 -> 0.57880757 | K41: =K38/K10 -> 0.59319022 | ... N41: =N38/N10 -> 0.64049756
B42: Interest Expense | D42: =-'MC Drivers (NRD)'!D323 -> 0 | E42: =-'MC Drivers (NRD)'!E323 -> 0 | F42: =-'MC Drivers (NRD)'!F323 -> 0 | G42: =-'MC Drivers (NRD)'!G323 -> 0 | H42: =-'MC Drivers (NRD)'!H323 -> 0 | I42: =-'MC Drivers (NRD)'!I323 -> 0 | J42: =-'MC Drivers (NRD)'!J323 -> 0 | K42: =-'MC Drivers (NRD)'!K323 -> 0 | ... N42: =-'MC Drivers (NRD)'!N323 -> 0
B43: EBT (Pre-tax Income) | D43: =D40+D42 -> 78184431 | E43: =E40+E42 -> 2.2954582e+08 | F43: =F40+F42 -> 4.4840929e+08 | G43: =G40+G42 -> 7.0502953e+08 | H43: =H40+H42 -> 9.7965015e+08 | I43: =I40+I42 -> 1300794703 | J43: =J40+J42 -> 1713648474 | K43: =K40+K42 -> 2189457583 | ... N43: =N40+N42 -> 3795036819
B44: Income Tax (no tax if EBT<0) | D44: =-MAX(D43,0)*'MC Drivers (NRD)'!D315 -> -19546108 | E44: =-MAX(E43,0)*'MC Drivers (NRD)'!E315 -> -57386455 | F44: =-MAX(F43,0)*'MC Drivers (NRD)'!F315 -> -1.1210232e+08 | G44: =-MAX(G43,0)*'MC Drivers (NRD)'!G315 -> -1.7625738e+08 | H44: =-MAX(H43,0)*'MC Drivers (NRD)'!H315 -> -2.4491254e+08 | I44: =-MAX(I43,0)*'MC Drivers (NRD)'!I315 -> -3.2519868e+08 | J44: =-MAX(J43,0)*'MC Drivers (NRD)'!J315 -> -4.2841212e+08 | K44: =-MAX(K43,0)*'MC Drivers (NRD)'!K315 -> -5.473644e+08 | ... N44: =-MAX(N43,0)*'MC Drivers (NRD)'!N315 -> -9.487592e+08
...

Sheet RideBox Energy P&L
B2: RIDEBOX ENERGY - PROFIT & LOSS
B3: All figures in PHP Millions (unless noted)
D4: 2026 | E4: 2027 | F4: 2028 | G4: 2029 | H4: 2030 | I4: 2031 | J4: 2032 | K4: 2033 | L4: 2034 | M4: 2035 | N4: 2036
B5: REVENUE
B6: Battery Subscription (leased users) | D6: ='MC Drivers (NRD)'!D15*'Energy Drivers (RideBox)'!D11*12 -> 65292857 | E6: ='MC Drivers (NRD)'!E15*'Energy Drivers (RideBox)'!E11*12 -> 1.5834107e+08 | F6: ='MC Drivers (NRD)'!F15*'Energy Drivers (RideBox)'!F11*12 -> 2.9134286e+08 | G6: ='MC Drivers (NRD)'!G15*'Energy Drivers (RideBox)'!G11*12 -> 4.6309018e+08 | H6: ='MC Drivers (NRD)'!H15*'Energy Drivers (RideBox)'!H11*12 -> 6.6035357e+08 | I6: ='MC Drivers (NRD)'!I15*'Energy Drivers (RideBox)'!I11*12 -> 8.8973304e+08 | J6: ='MC Drivers (NRD)'!J15*'Energy Drivers (RideBox)'!J11*12 -> 1174534821 | K6: ='MC Drivers (NRD)'!K15*'Energy Drivers (RideBox)'!K11*12 -> 1507481250 | ... N6: ='MC Drivers (NRD)'!N15*'Energy Drivers (RideBox)'!N11*12 -> 2651137500
B7: Load / Prepaid (owner + L2O users) | D7: =('MC Drivers (NRD)'!D17*'Energy Drivers (RideBox)'!D12)*12 -> 11314286 | E7: =('MC Drivers (NRD)'!E17*'Energy Drivers (RideBox)'!E12)*12 -> 18102857 | F7: =('MC Drivers (NRD)'!F17*'Energy Drivers (RideBox)'!F12)*12 -> 28964571 | G7: =('MC Drivers (NRD)'!G17*'Energy Drivers (RideBox)'!G12)*12 -> 40552286 | H7: =('MC Drivers (NRD)'!H17*'Energy Drivers (RideBox)'!H12)*12 -> 50688000 | I7: =('MC Drivers (NRD)'!I17*'Energy Drivers (RideBox)'!I12)*12 -> 60823714 | J7: =('MC Drivers (NRD)'!J17*'Energy Drivers (RideBox)'!J12)*12 -> 76032000 | K7: =('MC Drivers (NRD)'!K17*'Energy Drivers (RideBox)'!K12)*12 -> 91240286 | ... N7: =('MC Drivers (NRD)'!N17*'Energy Drivers (RideBox)'!N12)*12 -> 121638000
B8: Total Revenue | D8: =SUM(D6:D7) -> 76607143 | E8: =SUM(E6:E7) -> 1.7644393e+08 | F8: =SUM(F6:F7) -> 3.2030743e+08 | G8: =SUM(G6:G7) -> 5.0364246e+08 | H8: =SUM(H6:H7) -> 7.1104157e+08 | I8: =SUM(I6:I7) -> 950556750 | J8: =SUM(J6:J7) -> 1250566821 | K8: =SUM(K6:K7) -> 1598721536 | ... N8: =SUM(N6:N7) -> 2772775500
B10: COST OF SALES (battery depr & insurance are in NRD)
B11: Locker Insurance | D11: =-'Energy Drivers (RideBox)'!D123 -> -822251.42 | E11: =-'Energy Drivers (RideBox)'!E123 -> -2036374.7 | F11: =-'Energy Drivers (RideBox)'!F123 -> -3837173.3 | G11: =-'Energy Drivers (RideBox)'!G123 -> -6190669.8 | H11: =-'Energy Drivers (RideBox)'!H123 -> -9001727.7 | I11: =-'Energy Drivers (RideBox)'!I123 -> -12324711 | J11: =-'Energy Drivers (RideBox)'!J123 -> -16467680 | K11: =-'Energy Drivers (RideBox)'!K123 -> -21387598 | ... N11: =-'Energy Drivers (RideBox)'!N123 -> -39080727
B12: Locker Connectivity | D12: =-'Energy Drivers (RideBox)'!D8*'Energy Drivers (RideBox)'!D30*12 -> -388928.57 | E12: =-'Energy Drivers (RideBox)'!E8*'Energy Drivers (RideBox)'!E30*12 -> -963214.29 | F12: =-'Energy Drivers (RideBox)'!F8*'Energy Drivers (RideBox)'!F30*12 -> -1815000 | G12: =-'Energy Drivers (RideBox)'!G8*'Energy Drivers (RideBox)'!G30*12 -> -2928214.3 | H12: =-'Energy Drivers (RideBox)'!H8*'Energy Drivers (RideBox)'!H30*12 -> -4257857.1 | I12: =-'Energy Drivers (RideBox)'!I8*'Energy Drivers (RideBox)'!I30*12 -> -5829642.9 | J12: =-'Energy Drivers (RideBox)'!J8*'Energy Drivers (RideBox)'!J30*12 -> -7789285.7 | K12: =-'Energy Drivers (RideBox)'!K8*'Energy Drivers (RideBox)'!K30*12 -> -10116429 | ... N12: =-'Energy Drivers (RideBox)'!N8*'Energy Drivers (RideBox)'!N30*12 -> -18485357
B13: Locker Maintenance | D13: =-'Energy Drivers (RideBox)'!D8*'Energy Drivers (RideBox)'!D31*12 -> -777857.14 | E13: =-'Energy Drivers (RideBox)'!E8*'Energy Drivers (RideBox)'!E31*12 -> -1926428.6 | F13: =-'Energy Drivers (RideBox)'!F8*'Energy Drivers (RideBox)'!F31*12 -> -3630000 | G13: =-'Energy Drivers (RideBox)'!G8*'Energy Drivers (RideBox)'!G31*12 -> -5856428.6 | H13: =-'Energy Drivers (RideBox)'!H8*'Energy Drivers (RideBox)'!H31*12 -> -8515714.3 | I13: =-'Energy Drivers (RideBox)'!I8*'Energy Drivers (RideBox)'!I31*12 -> -11659286 | J13: =-'Energy Drivers (RideBox)'!J8*'Energy Drivers (RideBox)'!J31*12 -> -15578571 | K13: =-'Energy Drivers (RideBox)'!K8*'Energy Drivers (RideBox)'!K31*12 -> -20232857 | ... N13: =-'Energy Drivers (RideBox)'!N8*'Energy Drivers (RideBox)'!N31*12 -> -36970714
B14: Locker Electricity (kWh-based) | D14: =-'Energy Drivers (RideBox)'!D8*'Energy Drivers (RideBox)'!D26*365*'Energy Drivers (RideBox)'!D19 -> -12975939 | E14: =-'Energy Drivers (RideBox)'!E8*'Energy Drivers (RideBox)'!E26*365*'Energy Drivers (RideBox)'!E19 -> -42848006 | F14: =-'Energy Drivers (RideBox)'!F8*'Energy Drivers (RideBox)'!F26*365*'Energy Drivers (RideBox)'!F19 -> -80739179 | G14: =-'Energy Drivers (RideBox)'!G8*'Energy Drivers (RideBox)'!G26*365*'Energy Drivers (RideBox)'!G19 -> -1.3025984e+08 | H14: =-'Energy Drivers (RideBox)'!H8*'Energy Drivers (RideBox)'!H26*365*'Energy Drivers (RideBox)'!H19 -> -1.894082e+08 | I14: =-'Energy Drivers (RideBox)'!I8*'Energy Drivers (RideBox)'!I26*365*'Energy Drivers (RideBox)'!I19 -> -2.5932814e+08 | J14: =-'Energy Drivers (RideBox)'!J8*'Energy Drivers (RideBox)'!J26*365*'Energy Drivers (RideBox)'!J19 -> -346501671 | K14: =-'Energy Drivers (RideBox)'!K8*'Energy Drivers (RideBox)'!K26*365*'Energy Drivers (RideBox)'!K19 -> -4.5002322e+08 | ... N14: =-'Energy Drivers (RideBox)'!N8*'Energy Drivers (RideBox)'!N26*365*'Energy Drivers (RideBox)'!N19 -> -822309949
B15: Battery Connectivity | D15: =-'MC Drivers (NRD)'!D15*2*'Energy Drivers (RideBox)'!D14*12 -> -4748571.4 | E15: =-'MC Drivers (NRD)'!E15*2*'Energy Drivers (RideBox)'!E14*12 -> -11515714 | F15: =-'MC Drivers (NRD)'!F16*2*'Energy Drivers (RideBox)'!F14*12 -> -16352143 | G15: =-'MC Drivers (NRD)'!G16*2*'Energy Drivers (RideBox)'!G14*12 -> -27433929 | H15: =-'MC Drivers (NRD)'!H16*2*'Energy Drivers (RideBox)'!H14*12 -> -40852500 | I15: =-'MC Drivers (NRD)'!I16*2*'Energy Drivers (RideBox)'!I14*12 -> -56366786 | J15: =-'MC Drivers (NRD)'!J16*2*'Energy Drivers (RideBox)'!J14*12 -> -75064286 | K15: =-'MC Drivers (NRD)'!K16*2*'Energy Drivers (RideBox)'!K14*12 -> -97527857 | L15: =-'MC Drivers (NRD)'!L16*2*'Energy Drivers (RideBox)'!L14*12 -> -1.2263786e+08 | M15: =-'MC Drivers (NRD)'!M16*2*'Energy Drivers (RideBox)'!M14*12 -> -149512500 | N15: =-'MC Drivers (NRD)'!N16*2*'Energy Drivers (RideBox)'!N14*12 -> -1.7809714e+08
B16: Battery Payment Gateway | D16: =-D6*'Energy Drivers (RideBox)'!D13 -> -1958785.7 | E16: =-E6*'Energy Drivers (RideBox)'!E13 -> -4750232.1 | F16: =-F6*'Energy Drivers (RideBox)'!F13 -> -8740285.7 | G16: =-G6*'Energy Drivers (RideBox)'!G13 -> -13892705 | H16: =-H6*'Energy Drivers (RideBox)'!H13 -> -19810607 | I16: =-I6*'Energy Drivers (RideBox)'!I13 -> -26691991 | J16: =-J6*'Energy Drivers (RideBox)'!J13 -> -35236045 | K16: =-K6*'Energy Drivers (RideBox)'!K13 -> -45224438 | ... N16: =-N6*'Energy Drivers (RideBox)'!N13 -> -79534125
B17: Total Cost of Sales | D17: =SUM(D11:D16) -> -21672334 | E17: =SUM(E11:E16) -> -64039970 | F17: =SUM(F11:F16) -> -1.1511378e+08 | G17: =SUM(G11:G16) -> -1.8656179e+08 | H17: =SUM(H11:H16) -> -2.7184661e+08 | I17: =SUM(I11:I16) -> -372200558 | J17: =SUM(J11:J16) -> -4.9663754e+08 | K17: =SUM(K11:K16) -> -6.4451239e+08 | ... N17: =SUM(N11:N16) -> -1174478015
B18: GROSS PROFIT | D18: =D8+D17 -> 54934809 | E18: =E8+E17 -> 1.1240396e+08 | F18: =F8+F17 -> 2.0519365e+08 | G18: =G8+G17 -> 3.1708067e+08 | H18: =H8+H17 -> 4.3919496e+08 | I18: =I8+I17 -> 578356192 | J18: =J8+J17 -> 753929283 | K18: =K8+K17 -> 9.5420914e+08 | ... N18: =N8+N17 -> 1598297485
B19: GP margin | D19: =IFERROR(D18/D8,0) -> 0.71709774 | E19: =IFERROR(E18/E8,0) -> 0.63705201 | F19: =IFERROR(F18/F8,0) -> 0.6406147 | G19: =IFERROR(G18/G8,0) -> 0.62957494 | H19: =IFERROR(H18/H8,0) -> 0.61767832 | I19: =IFERROR(I18/I8,0) -> 0.60843941 | J19: =IFERROR(J18/J8,0) -> 0.60287005 | K19: =IFERROR(K18/K8,0) -> 0.59685763 | ... N19: =IFERROR(N18/N8,0) -> 0.57642513
B21: OPERATING EXPENSES
B22: Salaries | D22: =-'Energy Drivers (RideBox)'!D88 -> -17925674 | E22: =-'Energy Drivers (RideBox)'!E88 -> -20704153 | F22: =-'Energy Drivers (RideBox)'!F88 -> -23913297 | G22: =-'Energy Drivers (RideBox)'!G88 -> -27619858 | H22: =-'Energy Drivers (RideBox)'!H88 -> -31900936 | I22: =-'Energy Drivers (RideBox)'!I88 -> -36845582 | J22: =-'Energy Drivers (RideBox)'!J88 -> -42556647 | K22: =-'Energy Drivers (RideBox)'!K88 -> -49152927 | ... N22: =-'Energy Drivers (RideBox)'!N88 -> -75734774
B23: Employee Benefits | D23: =-'Energy Drivers (RideBox)'!D89 -> -1792567.4 | E23: =-'Energy Drivers (RideBox)'!E89 -> -2070415.3 | F23: =-'Energy Drivers (RideBox)'!F89 -> -2391329.7 | G23: =-'Energy Drivers (RideBox)'!G89 -> -2761985.8 | H23: =-'Energy Drivers (RideBox)'!H89 -> -3190093.6 | I23: =-'Energy Drivers (RideBox)'!I89 -> -3684558.2 | J23: =-'Energy Drivers (RideBox)'!J89 -> -4255664.7 | K23: =-'Energy Drivers (RideBox)'!K89 -> -4915292.7 | ... N23: =-'Energy Drivers (RideBox)'!N89 -> -7573477.4
B24: Locker Rent | D24: =-'Energy Drivers (RideBox)'!D8*'Energy Drivers (RideBox)'!D29*12 -> -19446429 | E24: =-'Energy Drivers (RideBox)'!E8*'Energy Drivers (RideBox)'!E29*12 -> -48160714 | F24: =-'Energy Drivers (RideBox)'!F8*'Energy Drivers (RideBox)'!F29*12 -> -90750000 | G24: =-'Energy Drivers (RideBox)'!G8*'Energy Drivers (RideBox)'!G29*12 -> -1.4641071e+08 | H24: =-'Energy Drivers (RideBox)'!H8*'Energy Drivers (RideBox)'!H29*12 -> -2.1289286e+08 | I24: =-'Energy Drivers (RideBox)'!I8*'Energy Drivers (RideBox)'!I29*12 -> -2.9148214e+08 | J24: =-'Energy Drivers (RideBox)'!J8*'Energy Drivers (RideBox)'!J29*12 -> -3.8946429e+08 | K24: =-'Energy Drivers (RideBox)'!K8*'Energy Drivers (RideBox)'!K29*12 -> -5.0582143e+08 | ... N24: =-'Energy Drivers (RideBox)'!N8*'Energy Drivers (RideBox)'!N29*12 -> -9.2426786e+08
B25: Total Operating Expenses | D25: =D22+D23+D24 -> -39164670 | E25: =E22+E23+E24 -> -70935283 | F25: =F22+F23+F24 -> -117054627 | G25: =G22+G23+G24 -> -1.7679256e+08 | H25: =H22+H23+H24 -> -2.4798389e+08 | I25: =I22+I23+I24 -> -3.3201228e+08 | J25: =J22+J23+J24 -> -436276597 | K25: =K22+K23+K24 -> -5.5988965e+08 | ... N25: =N22+N23+N24 -> -1007576109
B27: EBITDA | D27: =D18+D25 -> 15770139 | E27: =E18+E25 -> 41468676 | F27: =F18+F25 -> 88139021 | G27: =G18+G25 -> 1.4028812e+08 | H27: =H18+H25 -> 1.9121107e+08 | I27: =I18+I25 -> 2.4634391e+08 | J27: =J18+J25 -> 317652686 | K27: =K18+K25 -> 3.9431949e+08 | ... N27: =N18+N25 -> 5.9072138e+08
B28: Depreciation & Amortization | D28: ='Energy Drivers (RideBox)'!D121 -> 2055628.6 | E28: ='Energy Drivers (RideBox)'!E121 -> 7146565.4 | F28: ='Energy Drivers (RideBox)'!F121 -> 14683870 | G28: ='Energy Drivers (RideBox)'!G121 -> 25069608 | H28: ='Energy Drivers (RideBox)'!H121 -> 37980994 | I28: ='Energy Drivers (RideBox)'!I121 -> 53316096 | J28: ='Energy Drivers (RideBox)'!J121 -> 71980977 | K28: ='Energy Drivers (RideBox)'!K121 -> 94638194 | ... N28: ='Energy Drivers (RideBox)'!N121 -> 1.7735034e+08
B29: OPERATING INCOME (EBIT) | D29: =D27-D28 -> 13714511 | E29: =E27-E28 -> 34322110 | F29: =F27-F28 -> 73455151 | G29: =G27-G28 -> 1.1521851e+08 | H29: =H27-H28 -> 1.5323008e+08 | I29: =I27-I28 -> 1.9302781e+08 | J29: =J27-J28 -> 2.4567171e+08 | K29: =K27-K28 -> 2.996813e+08 | ... N29: =N27-N28 -> 4.1337103e+08
B30: EBITDA margin | D30: =D27/D8 -> 0.20585729 | E30: =E27/E8 -> 0.23502467 | F30: =IFERROR(F29/F8,0) -> 0.22932703 | G30: =IFERROR(G29/G8,0) -> 0.22877044 | H30: =IFERROR(H29/H8,0) -> 0.21550087 | I30: =IFERROR(I29/I8,0) -> 0.20306816 | J30: =IFERROR(J29/J8,0) -> 0.19644829 | K30: =IFERROR(K29/K8,0) -> 0.18745059 | L30: =IFERROR(L29/L8,0) -> 0.17441028 | M30: =IFERROR(M29/M8,0) -> 0.16143717 | N30: =IFERROR(N29/N8,0) -> 0.14908204
B31: Interest Expense | D31: =0 -> 0 | E31: =0 -> 0 | F31: =0 -> 0 | G31: =0 -> 0 | H31: =0 -> 0 | I31: =0 -> 0 | J31: =0 -> 0 | K31: =0 -> 0 | ... N31: =0 -> 0
B32: EBT (Pre-tax Income) | D32: =D29+D31 -> 13714511 | E32: =E29+E31 -> 34322110 | F32: =F29+F31 -> 73455151 | G32: =G29+G31 -> 1.1521851e+08 | H32: =H29+H31 -> 1.5323008e+08 | I32: =I29+I31 -> 1.9302781e+08 | J32: =J29+J31 -> 2.4567171e+08 | K32: =K29+K31 -> 2.996813e+08 | ... N32: =N29+N31 -> 4.1337103e+08
B33: Income Tax (no tax if EBT<0) | D33: =-MAX(D32,0)*'MC Drivers (NRD)'!D315 -> -3428627.6 | E33: =-MAX(E32,0)*'MC Drivers (NRD)'!E315 -> -8580527.6 | F33: =-MAX(F32,0)*'MC Drivers (NRD)'!F315 -> -18363788 | G33: =-MAX(G32,0)*'MC Drivers (NRD)'!G315 -> -28804627 | H33: =-MAX(H32,0)*'MC Drivers (NRD)'!H315 -> -38307520 | I33: =-MAX(I32,0)*'MC Drivers (NRD)'!I315 -> -48256953 | J33: =-MAX(J32,0)*'MC Drivers (NRD)'!J315 -> -61417927 | K33: =-MAX(K32,0)*'MC Drivers (NRD)'!K315 -> -74920325 | ... N33: =-MAX(N32,0)*'MC Drivers (NRD)'!N315 -> -103342758
B34: NET INCOME (NIAT) | D34: =D32+D33 -> 10285883 | E34: =E32+E33 -> 25741583 | F34: =F32+F33 -> 55091363 | G34: =G32+G33 -> 86413881 | H34: =H32+H33 -> 1.1492256e+08 | I34: =I32+I33 -> 1.4477086e+08 | J34: =J32+J33 -> 184253782 | K34: =K32+K33 -> 2.2476098e+08 | ... N34: =N32+N33 -> 3.1002827e+08
B35: Net margin | D35: =IFERROR(D34/D8,0) -> 0.13426794 | E35: =IFERROR(E34/E8,0) -> 0.14589101 | F35: =IFERROR(F34/F8,0) -> 0.17199527 | G35: =IFERROR(G34/G8,0) -> 0.17157783 | H35: =IFERROR(H34/H8,0) -> 0.16162566 | I35: =IFERROR(I34/I8,0) -> 0.15230112 | J35: =IFERROR(J34/J8,0) -> 0.14733621 | K35: =IFERROR(K34/K8,0) -> 0.14058794 | ... N35: =IFERROR(N34/N8,0) -> 0.11181153
B36: memo: Cash COGS+Opex (excl D&A) | D36: =-(D17+D25)-'Energy Drivers (RideBox)'!D121 -> 58781375 | E36: =-(E17+E25)-'Energy Drivers (RideBox)'!E121 -> 1.2782869e+08 | F36: =-(F17+F25)-'Energy Drivers (RideBox)'!F121 -> 2.1748454e+08 | G36: =-(G17+G25)-'Energy Drivers (RideBox)'!G121 -> 3.3828474e+08 | H36: =-(H17+H25)-'Energy Drivers (RideBox)'!H121 -> 4.818495e+08 | I36: =-(I17+I25)-'Energy Drivers (RideBox)'!I121 -> 6.5089674e+08 | J36: =-(J17+J25)-'Energy Drivers (RideBox)'!J121 -> 8.6093316e+08 | K36: =-(K17+K25)-'Energy Drivers (RideBox)'!K121 -> 1109763848 | ... N36: =-(N17+N25)-'Energy Drivers (RideBox)'!N121 -> 2004703780

Sheet NRD MC Balance Sheet
B2: NRD MOTORCYCLE - BALANCE SHEET
B3: All figures in PHP Millions (unless noted)
D4: 2026 | E4: 2027 | F4: 2028 | G4: 2029 | H4: 2030 | I4: 2031 | J4: 2032 | K4: 2033 | L4: 2034 | M4: 2035 | N4: 2036
B5: ASSETS
B6: Accounts Receivable | D6: ='MC Drivers (NRD)'!D309/365*'NRD MC P&L'!D10 -> 6690518.2 | E6: ='MC Drivers (NRD)'!E309/365*'NRD MC P&L'!E10 -> 12926643 | F6: ='MC Drivers (NRD)'!F309/365*'NRD MC P&L'!F10 -> 22185348 | G6: ='MC Drivers (NRD)'!G309/365*'NRD MC P&L'!G10 -> 32937914 | H6: ='MC Drivers (NRD)'!H309/365*'NRD MC P&L'!H10 -> 44207070 | I6: ='MC Drivers (NRD)'!I309/365*'NRD MC P&L'!I10 -> 56808821 | J6: ='MC Drivers (NRD)'!J309/365*'NRD MC P&L'!J10 -> 73423409 | K6: ='MC Drivers (NRD)'!K309/365*'NRD MC P&L'!K10 -> 92070761 | ... N6: ='MC Drivers (NRD)'!N309/365*'NRD MC P&L'!N10 -> 1.5067845e+08
B7: Inventory (MC sale COGS basis) | D7: ='MC Drivers (NRD)'!D311/365*'MC Drivers (NRD)'!D17*('MC Drivers (NRD)'!D53*'MC Drivers (NRD)'!D67+'MC Drivers (NRD)'!D54*'MC Drivers (NRD)'!D68) -> 14383415 | E7: ='MC Drivers (NRD)'!E311/365*'MC Drivers (NRD)'!E17*('MC Drivers (NRD)'!E53*'MC Drivers (NRD)'!E67+'MC Drivers (NRD)'!E54*'MC Drivers (NRD)'!E68) -> 23013464 | F7: ='MC Drivers (NRD)'!F311/365*'MC Drivers (NRD)'!F17*('MC Drivers (NRD)'!F53*'MC Drivers (NRD)'!F67+'MC Drivers (NRD)'!F54*'MC Drivers (NRD)'!F68) -> 36821542 | G7: ='MC Drivers (NRD)'!G311/365*'MC Drivers (NRD)'!G17*('MC Drivers (NRD)'!G53*'MC Drivers (NRD)'!G67+'MC Drivers (NRD)'!G54*'MC Drivers (NRD)'!G68) -> 51552556 | H7: ='MC Drivers (NRD)'!H311/365*'MC Drivers (NRD)'!H17*('MC Drivers (NRD)'!H53*'MC Drivers (NRD)'!H67+'MC Drivers (NRD)'!H54*'MC Drivers (NRD)'!H68) -> 64437698 | I7: ='MC Drivers (NRD)'!I311/365*'MC Drivers (NRD)'!I17*('MC Drivers (NRD)'!I53*'MC Drivers (NRD)'!I67+'MC Drivers (NRD)'!I54*'MC Drivers (NRD)'!I68) -> 77322841 | J7: ='MC Drivers (NRD)'!J311/365*'MC Drivers (NRD)'!J17*('MC Drivers (NRD)'!J53*'MC Drivers (NRD)'!J67+'MC Drivers (NRD)'!J54*'MC Drivers (NRD)'!J68) -> 96656548 | K7: ='MC Drivers (NRD)'!K311/365*'MC Drivers (NRD)'!K17*('MC Drivers (NRD)'!K53*'MC Drivers (NRD)'!K67+'MC Drivers (NRD)'!K54*'MC Drivers (NRD)'!K68) -> 1.1599025e+08 | ... N7: ='MC Drivers (NRD)'!N311/365*'MC Drivers (NRD)'!N17*('MC Drivers (NRD)'!N53*'MC Drivers (NRD)'!N67+'MC Drivers (NRD)'!N54*'MC Drivers (NRD)'!N68) -> 1.546337e+08
B8: Net PP&E (MC + batteries + L2O + opex) | D8: ='MC Drivers (NRD)'!D201+'MC Drivers (NRD)'!D222+'MC Drivers (NRD)'!D240+'MC Drivers (NRD)'!D306 -> 2.9145851e+08 | E8: ='MC Drivers (NRD)'!E201+'MC Drivers (NRD)'!E222+'MC Drivers (NRD)'!E240+'MC Drivers (NRD)'!E306 -> 6.8240105e+08 | F8: ='MC Drivers (NRD)'!F201+'MC Drivers (NRD)'!F222+'MC Drivers (NRD)'!F240+'MC Drivers (NRD)'!F306 -> 1209050606 | G8: ='MC Drivers (NRD)'!G201+'MC Drivers (NRD)'!G222+'MC Drivers (NRD)'!G240+'MC Drivers (NRD)'!G306 -> 1852086463 | H8: ='MC Drivers (NRD)'!H201+'MC Drivers (NRD)'!H222+'MC Drivers (NRD)'!H240+'MC Drivers (NRD)'!H306 -> 2546796622 | I8: ='MC Drivers (NRD)'!I201+'MC Drivers (NRD)'!I222+'MC Drivers (NRD)'!I240+'MC Drivers (NRD)'!I306 -> 3312811391 | J8: ='MC Drivers (NRD)'!J201+'MC Drivers (NRD)'!J222+'MC Drivers (NRD)'!J240+'MC Drivers (NRD)'!J306 -> 4236645221 | K8: ='MC Drivers (NRD)'!K201+'MC Drivers (NRD)'!K222+'MC Drivers (NRD)'!K240+'MC Drivers (NRD)'!K306 -> 5272728835 | ... N8: ='MC Drivers (NRD)'!N201+'MC Drivers (NRD)'!N222+'MC Drivers (NRD)'!N240+'MC Drivers (NRD)'!N306 -> 8403351278
