Workbook

Sheet PS
A1: s
D2: PICK SLIP
B3: REQUESTOR DETAILS: | H3: RS #:
B5: Date Requested:
B6: Requesting Dept:
B7: Requestor Name:
B8: Requestor Email:
B9: Purpose:
B10: REQUEST(S):
B12: No. | C12: E88-SKU | D12: Description | E12: Qty | F12: UoM | G12: Stock | H12: Allocation | I12: Remarks
B13: 1
B14: 2
B15: 3
B16: 4
B17: 5
B18: 6
B19: 7
B20: 8
B21: 9
B22: 10
B23: 11
B24: 12
B25: OTHER REQUEST(S):
B29: OVERALL REMARKS:
B33: PREPARED BY. | F33: APPROVED BY:
B35: Signature: | F35: Signature:
B36: Name: | D36: =D7 | F36: Name:
B37: Date: | F37: Date:

Sheet PS MC
A1: s
D2: PICK SLIP
B3: REQUESTOR DETAILS:
B5: Date Requested:
B6: Requesting Dept:
B7: Requestor Name:
B8: Requestor Email:
B9: Purpose:
B10: REQUEST(S):
B12: No. | C12: UNIT | D12: COLOR | E12: VIN / PLATE NO. | F12: BATTERY A | G12: BATTERY B | H12: CHARGER
B13: 1
B14: 2
B15: 3
B16: 4
B17: 5
B18: 6
B19: 7
B20: 8
B21: 9
B22: 10
B23: 11
B24: 12
B25: OTHER REQUEST(S):
B29: OVERALL REMARKS:
B33: PREPARED BY. | F33: APPROVED BY:
B35: Signature: | F35: Signature:
B36: Name: | D36: REYNAN LLANETA | F36: Name: | G36: ARBY MOSTRALES
B37: Date: | F37: Date:

Sheet Form Responses 1
A1: REQ NO. | B1: Timestamp | C1: Email Address | D1: Purpose of request | E1: Fulfillment Method | F1: Company / Client Name | G1: Delivery Address | H1: Pickup/Delivery Date | I1: Pickup/Delivery Time | J1: Recipient Name: | K1: Recipient Number: | L1: MC - R280 White | M1: MC - R280 Black | N1: MC - R280 Sport Red | O1: MC - R280 Sport Blue | P1: MC - D400 Red | Q1: MC - D400 Blue | R1: MC - D400 Black | S1: RideBox Battery | T1: RideBox Charger | U1: RideBox Locker | V1: RideBox Rack | W1: Battery & Charger | X1: Qty per set | Y1: Helmet | Z1: Charging Kit f | AA1: List of Spareparts/Qty | AB1: Overall Remarks | AC1: Requestor Name: | AD1: Department | AE1: If others, please specify | AF1: Charging Kit | AG1: Other items (please specify) | AH1: Column 33 | AI1: Status
A2: {=IF(LEN(B2:B1308), TEXT(YEAR(B2:B1308),"0000")&TEXT(SEQUENCE(COUNTA(B2:B1308),1),"0000000"), "" )} -> 20250000001 | B2: 46017.807 | C2: judy@nrdev.ph | D2: Assignment to Employee | E2: Pickup | F2: JJ's Company | G2: Batangas | H2: 46036 | I2: 0.084722222 | J2: JJ | K2: 09123456789 | L2: 10 | S2: 20 | T2: 10 | Y2: 10 | Z2: =AF2 -> 2 | AC2: JJ | AD2: Supply Chain Management | AF2: 2 | AI2: Test
A3: 20260000002 | B3: 46028.551 | C3: ijimenez@nrdev.ph | D3: Test / Demo Unit | E3: Pickup | F3: Internal | G3: E88 Warehouse | H3: 46028 | I3: 0.625 | J3: Emman Usi | K3: 09083187665 | Z3: =AF3 | AC3: Ian Jimenez | AD3: Tech | AG3: Canalyst-II - 2 pieces | AH3: Canalyst-II x 2 pieces | AI3: Cancel
A4: 20260000003 | B4: 46030.476 | C4: judy@nrdev.ph | D4: Sale to Client | E4: Delivery | F4: as | G4: as | H4: 46037 | I4: 0.18055556 | J4: a | K4: a | L4: 20 | S4: 40 | Z4: =AF4 | AC4: jj | AD4: Supply Chain Management | AE4: - | AH4: ajdbhjdsbfjjnal | AI4: Test
A5: 20260000004 | B5: 46031.723 | C5: rdelacruz@nrdev.ph | D5: Test / Demo Unit | E5: Pickup | F5: FLEXRIDE | G5: Marikina | H5: 46035 | I5: 0.54166667 | J5: Jerick Limoanco | K5: 09175645545 | L5: 3 | S5: 6 | T5: 3 | AC5: Ron Dela Cruz | AD5: Sales | AE5: N/A | AF5: 3 | AI5: Done
A6: 20260000005 | B6: 46031.731 | C6: rdelacryz@nrdev.ph | D6: Lease | E6: Delivery | F6: Dasma Village | G6: Dasma Village Makati | H6: 46036 | I6: 0.54166667 | J6: Orlando Bueno | K6: 09177005363 | Q6: 10 | S6: 20 | T6: 10 | AC6: Ron Dela Cruz | AD6: Sales | AE6: N/A | AI6: DONE
A7: 20260000006 | B7: 46032.482 | C7: cmendoza@nrdev.ph | D7: Inventory Transfer | E7: Delivery | F7: NRD SERVICE CENTER | G7: Unit 8 and 9 Ground Floor One Sta. Rosa Prime (Caltex) Brgy Dila City of Sta Rosa Laguna | H7: 46034 | I7: 0.45833333 | J7: Anne Estadilla | K7: +63 917 128 6414 | Z7: =AF7 | AA7: 2 pcs Front Tire 90/90-12 (R280/Sports) / 44701-ET01-A000 2 pcs Rear Tire 90/90-12 (R280/Sports) / 42701-ET01-A000 1 pc Rear Tire 110/80-14 (D400) / 42701-MX-A000 1 pc Front Tire 110-80-16 (D400) / 44701-MX-A000 3 pcs Head Light Guard (R280 Sports) / 1 pc Controller Assembly (D400) / 30100-MX-A001 2 pcs Speedometer (D400) / 37200-MX-A001 3 cans Brake cleaner | AC7: Christopher Mendoza | AD7: Product & Quality Management | AI7: Done
A8: 20260000007 | B8: 46034.44 | C8: samuel@nrdev.ph | D8: Others | E8: Not applicable | F8: E88V - Quality Management (c/o Criz) | G8: 174 Acacia St | H8: 46034 | I8: 0.4375 | J8: Criz Mendoza | K8: cmendoza@nrdev.ph | Z8: =AF8 | AA8: 3 Long Seats (R280) | AC8: samuel | AD8: Product & Quality Management | AE8: Swap with Regular Seat (R280) | AI8: Done
A9: 20260000008 | B9: 46035.447 | C9: samuel@nrdev.ph | D9: Test / Demo Unit | E9: Pickup | F9: asgard | G9: 174 acacia st | H9: 46036 | I9: 0.41666667 | J9: jervy / gerald | K9: xxxx | Q9: 1 | Y9: 2 | Z9: =AF9 | AC9: samuel kniazeff jr | AD9: Product & Quality Management | AH9: provide 2 helmets (not new) | AI9: DONE
A10: 20260000009 | B10: 46035.448 | C10: samuel@nrdev.ph | D10: Test / Demo Unit | E10: Pickup | F10: e88 ventures | G10: 174 acacia st | H10: 46037 | I10: 0.41666667 | J10: richard / jaycer | K10: xxxx | Q10: 1 | Y10: 2 | Z10: =AF10 | AC10: samuel kniazeff jr | AD10: Product & Quality Management | AI10: cancel
A11: 20260000010 | B11: 46035.676 | C11: cmendoza@nrdev.ph | D11: Replacemet for D400 Defective Speedometer | E11: Not applicable | F11: asgard | G11: asgard | H11: 46035 | I11: 0.54166667 | J11: christopher c mendoza | K11: 09608978870 | Z11: =AF11 | AC11: christopher c mendoza | AD11: Product & Quality Management | AE11: replacement for new unit to be released | AH11: D400 speedometer replacement for new unit to be released | AI11: DONE
A12: 20260000011 | B12: 46036.331 | C12: rdelacruz@nrdev.ph | D12: Sale to Client | E12: Pickup | F12: Forest Hill | G12: Rizal | H12: 46037 | I12: 0.54166667 | J12: Martin Limgenco | K12: 09173219779 | O12: 1 | S12: 2 | T12: 1 | Y12: 1 | AC12: ron dela cruz | AD12: Sales | AI12: DONE
A13: 20260000012 | B13: 46037.352 | C13: rdelacruz@nrdev.ph | D13: Test / Demo Unit | E13: Pickup | F13: Forest Hill | G13: Forest Hill Golf & Country Club Antipolo Rizal | H13: 46037 | I13: 0.54166667 | J13: Martin Limgenco | K13: 09173219779 | Q13: 1 | S13: 2 | T13: 1 | AC13: Ron Dela Cruz | AD13: Sales | AE13: N/A | AI13: DONE
A14: 20260000013 | B14: 46038.513 | C14: samuel@nrdev.ph | D14: Inventory Transfer | E14: Pickup | F14: samuel | G14: 174 acacia | H14: 46038 | I14: 0.47916667 | J14: samuel | K14: samuel@nrdev.ph | AA14: white front wings | AC14: samuel kniazeff jr | AD14: Product & Quality Management | AE14: install to sample unit in TCI | AH14: pair of front white wings | AI14: DONE
A15: 20260000014 | B15: 46038.639 | C15: judy@nrdev.ph | D15: Test / Demo Unit | E15: Pickup | F15: E88 | G15: Forest Hill Golf & Country Club Antipolo Rizal | H15: 46038 | I15: 0.25 | J15: Reynan Lllaneta | K15: +63 993 437 1465 | S15: 1 | AC15: Judy Joy Rosare | AD15: Supply Chain Management | AH15: Back up Battery for Forest Hills Demo unit | AI15: DONE
A16: 20260000015 | B16: 46043.666 | C16: ijimenez@nrdev.ph | D16: Others | E16: Pickup | F16: Various | G16: Various | H16: 46052 | I16: 0.41666667 | J16: Ian Jimenez | K16: 09062924124 | S16: 12 | U16: 3 | AC16: Ian Jimenez | AD16: Tech | AE16: Deployment | AH16: Booking 3 lockers and 12 batteries in advance for BSS Deploymeny | AI16: DONE
A17: 20260000016 | B17: 46044.449 | C17: jguce@nrdev.ph | D17: Lease to Client | E17: Pickup | F17: Wemove Technology Inc. | G17: UNIT 205, 1409 PABLO OCAMPO SR. EXT, MAKATI CITY, 1203 METRO MANILA | H17: 46045 | I17: 0.45833333 | J17: JJ Cabral | K17: 63 908 863 6620 | Q17: 1 | S17: 2 | T17: 1 | AB17: 2 Additional Battery | AC17: Judielle Guce | AD17: Project Management & Compliance | AE17: paid pilot for 1 month | AI17: DONE
A18: 20260000017 | B18: 46045.518 | C18: rdelacruz@nrdev.ph | D18: Others | E18: Pickup | F18: N/A | G18: N/A | H18: 46045 | I18: 0.52083333 | J18: Ron Dela Cruz | K18: 09177680944 | AC18: Ron Dela Cruz | AD18: Sales | AE18: N/A | AG18: r280sport side wing | AH18: for demo unit | AI18: DONE
A19: 20260000018 | B19: 46045.632 | C19: judy@nrdev.ph | D19: Others | E19: Not applicable | F19: E88 - Samuel Kniazeff | G19: E88 Ventures, Inc. | H19: 46045 | I19: 0.5 | J19: RJ Jardiniano | K19: +639171077992 | AA19: ESP00217 Left Combination Switch (D400) / 1 | AC19: Judy Joy Rosare | AD19: Supply Chain Management | AE19: Replacement of Left Combination Switch (D400) | AI19: DONE
A20: 20260000019 | B20: 46048.725 | C20: tmasiglat@nrdev.ph | D20: Test / Demo Unit | E20: Delivery | F20: Phoenix Petroleum Philippines, Inc. | G20: The Atrium at Enderun, 1100 Campus Avenue, McKinley Hill, Taguig City | H20: 46049 | I20: 0.54166667 | J20: Thea Masiglat | K20: 09171022450 | Q20: 1 | S20: 3 | U20: 1 | Y20: 1 | AC20: Thea Masiglat | AD20: Marketing | AG20: Yung booth namen heheh if nakapack jan, pasabay heheheh | AI20: DONE
A21: 20260000020 | B21: 46049.437 | C21: cmendoza@nrdev.ph | D21: Inventory Transfer | E21: Delivery | F21: NRD SERVICE CENTER | G21: Unit 8 and 9 Ground Floor One Sta. Rosa Prime (Caltex) Brgy Dila City of Sta Rosa Laguna | H21: 46050 | I21: 0.45833333 | J21: Anne Estadilla | K21: +63 917 128 6414 | AA21: SWITCH LOCK ASSY W/KEY 3PCS CONTROLLER 65A 1PC SPEEDOMETER(R280) 2PCS CUSHION SEAT LOCK CABLE 2PCS MAIN WIRING HARNESS 1PC SPEEDOMETER(D400) 1PC POWER TRAIN/MOTOR 1PC | AC21: Christopher C. Mendoza | AD21: Product & Quality Management | AI21: FOR WH
A22: 20260000021 | B22: 46049.711 | C22: cmendoza@nrdev.ph | D22: Others | E22: Not applicable | F22: NRD warehouse | G22: 174 Acacia st., octagogan vill. dela paz pasig | H22: 46049 | I22: 0.45833333 | J22: Christopher C Mendoza | K22: 09608978870 | AA22: Speedometer (D400) ESP00224 | AC22: Christopher C. Mendoza | AD22: Product & Quality Management | AE22: Replacement for the brandnew unit with faulty dashboard | AI22: FOR WH
A23: 20260000022 | B23: 46051.545 | C23: haide@nrdev.ph | D23: Assignment to Employee | E23: Pickup | F23: Ron Dela Cruz | G23: Pick up at Asgard | H23: 46051 | I23: 0.54166667 | J23: Ron Dela Cruz | K23: (0917) 768 0944 | P23: 1 | S23: 2 | T23: 1 | AC23: Haide Garcia | AD23: Human Resources | AI23: DONE
A24: 20260000023 | B24: 46052.533 | C24: tmasiglat@nrdev.ph | D24: Test / Demo Unit | E24: Delivery | F24: Premiere Southern Petroleum Corp. | G24: Pickup | H24: 46055 | I24: 0.41666667 | J24: Julius Aguas | K24: 09178465183 | P24: 1 | S24: 2 | T24: 1 | Y24: 1 | AC24: Thea Masiglat | AD24: Marketing | AE24: For 2 weeks | AH24: Not sure pa if Monday or Tuesday, but best prepared early for pilot testing. Thank you! | AI24: DONE
A25: 20260000024 | B25: 46052.91 | C25: jguce@nrdev.ph | D25: Test / Demo Unit | E25: Pickup | F25: QuadX | G25: Na | H25: 46053 | I25: 0.41666667 | J25: Toni Nodalo | K25: 09675019247 | Q25: 2 | S25: 4 total | T25: 2 | Y25: Na | AC25: Judielle Guce | AD25: Project Management & Compliance | AI25: DONE
A26: 20260000025 | B26: 46053.504 | C26: jguce@nrdev.ph | D26: Others | E26: Delivery | F26: Hitchpro Southside HQ | G26: 343 Poblete Compound (P7 warehouse) Sun Valley, Parañaque City | H26: 46055 | I26: 0.41666667 | J26: Kim | K26: +63 947 890 8545 | N26: 1 | Q26: 1 | S26: 4 | T26: 1 | AC26: Judielle Guce | AD26: Project Management & Compliance | AE26: prototypes for the rear top boxes | AI26: DONE
A27: 20260000026 | B27: 46055.444 | C27: judy@nrdev.ph | D27: Test / Demo Unit | E27: Pickup | F27: E88 Ventures, Inc. / Ronwaldo Dela Cruz | G27: E88 Asgard Warehouse | H27: 46055 | I27: 0.54166667 | J27: Ronwaldo Dela Cruz | K27: +639177680944 | O27: 1 | S27: 2 | T27: 1 | AC27: Judy Joy Rosare | AD27: Supply Chain Management | AH27: For testing c/o Ron - will return same day | AI27: DONE
A28: 20260000027 | B28: 46057.395 | C28: jysaac@nrdev.ph | D28: Others | E28: Pickup | F28: E88 Ventures, Inc | G28: TBA | H28: 46057 | I28: 0.4375 | J28: John Martin Ysaac | K28: 09062858290 | S28: 4 | AC28: John Martin Ysaac | AD28: Tech | AE28: Replacement for offline batteries | AH28: This is only for back-up once on-stie so replacements will be available. Please make sure batteries are online and whitelisted thank you | AI28: DONE
A29: 20260000028 | B29: 46057.448 | C29: judy@nrdev.ph | D29: Inventory Transfer | E29: Delivery | F29: OKLA / | G29: OKLA - China | H29: 46057 | I29: 0.45833333 | J29: Okla - Kamal | K29: - | AA29: PARTS-ESP00086-Controller Assembly 65A (R280 Sport) / 41 PARTS- ESP00097 / Left Rear Fork Cover (R280 White) / 2 PARTS-ESP00025 / Switch Lock Assy with Key (R280/Sport) / 2 PARTS- ESP00225 / Speedometer bracket (D400) / 2 PARTS- ESP00224 / Speedometer (D400) / 1 | AC29: Judy Joy Rosare | AD29: Supply Chain Management | AI29: DONE
A30: 20260000029 | B30: 46058.734 | C30: jysaac@nrdev.ph | D30: Others | E30: Delivery | F30: Cornerstone | G30: Cornerstone Building San Juan City https://share.google/tIUMZga7WRWKOCu96 | H30: 46060 | I30: 0.54166667 | J30: Engr. Rey | K30: 0925 716 3813 | S30: 4 | U30: 1 | AC30: John Martin Ysaac | AD30: Tech | AE30: For cornerstone | AI30: DONE
A31: 20260000030 | B31: 46059.72 | C31: jysaac@nrdev.ph | D31: Others | E31: Delivery | F31: Corinthian Hills | G31: Corinthian Hills Gate 1 | H31: 46060 | I31: 0.45833333 | J31: Engr. Murphy Pobocan Cabalquinto | K31: 0905 219 1125 | S31: 4 | U31: 1 | AC31: John Martin Ysaac | AD31: Tech | AE31: Asset | AI31: DONE
A32: 20260000031 | B32: 46063.457 | C32: jguce@nrdev.ph | D32: Donation | E32: Delivery | F32: Barangay San Antonio | G32: Gen. Malvar St., Barangay San Antonio, Pasig City | H32: 46065 | I32: 0.58333333 | J32: Raymond Lising | K32: n/a | O32: 1 | P32: 1 | S32: 4 | T32: 2 | AC32: Judielle Guce | AD32: Project Management & Compliance | AH32: 1 D400 Red and R280 Sport Blue | AI32: DONE
A33: 20260000032 | B33: 46063.459 | C33: jguce@nrdev.ph | D33: Donation | E33: Delivery | F33: BF Homes Paranaque | G33: BF Homes Paranaque | H33: 46065 | I33: 0.41666667 | J33: Check with Greg | K33: check with Greg | O33: 5 | P33: 5 | S33: 20 | T33: 10 | AC33: Judielle Guce | AD33: Project Management & Compliance | AH33: 5 D400 Red, and 5 R280 Sport Blue (whichever is higher in the inventory) | AI33: DONE
A34: 20260000033 | B34: 46064.745 | C34: jysaac@nrdev.ph | D34: Lease to Client | E34: Delivery | F34: Alfamart | G34: Alfamart Ibayo Tipaz Taguig | H34: 46065 | I34: 0.60416667 | J34: Dagz Cabangisan | K34: 0977 716 4472 | S34: 4 | U34: 1 | AC34: John Martin Ysaac | AD34: Tech | AI34: DONE
A35: 20260000034 | B35: 46065.413 | C35: cmendoza@nrdev.ph | D35: Others | E35: Not applicable | F35: Fidel Suarez | G35: Warehouse | H35: 46062 | I35: 0.45833333 | J35: Fidel Suarez | K35: 09176167757 | AA35: 1pc R280 Controller 50A | AC35: Christopher C. Mendoza | AD35: Product & Quality Management | AE35: Under warranty | AI35: DONE
A36: 20260000035 | B36: 46065.598 | C36: eusi@nrdev.ph | D36: Others | E36: Pickup | F36: Power Fill Barangka | G36: 349 Barangka Dr., Mandaluyong City, 1550 Kalakhang Maynila | H36: 46065 | I36: 0.60416667 | J36: Emman Usi | K36: 09083187665 | AC36: Emman Usi | AD36: Tech | AE36: Battery replacement for PF Barangka | AI36: DONE
A37: 20260000036 | B37: 46065.61 | C37: jguce@nrdev.ph | D37: Test / Demo Unit | E37: Delivery | F37: JRS | G37: 19 Brixton St, Pasig, 1603 Metro Manila | H37: 46066 | I37: 0.41666667 | J37: Joprang | K37: 09771975432 | Q37: 1 | S37: 2 | T37: 1 | AC37: Judielle Guce | AD37: Project Management & Compliance | AH37: Eto po yung D400 unit with the JRS Topbox. Thankies! | AI37: DONE
A38: 20260000037 | B38: 46065.725 | C38: jguce@nrdev.ph | D38: Donation | E38: Delivery | F38: Corinthian Garden | G38: Corinthian Garden - to follow exact location | H38: 46069 | I38: 0.54166667 | J38: Engr. Murphy | K38: 09062191125 | O38: 3 | P38: 2 | S38: 10 | T38: 5 | AC38: Judielle Guce | AD38: Project Management & Compliance | AI38: DONE
A39: 20260000038 | B39: 46067.385 | C39: jysaac@nrdev.ph | D39: Others | E39: Pickup | F39: Alfamart 1499 Jordan Planes QC | G39: 1011 F. Salvador Ave., Jordan Plaines Subd., Barangay Sta. Monica, Novaliches, Quezon City, 1123 | H39: 46080 | I39: 0.41666667 | J39: Eduard Pranada | K39: +63 917 954 9957 | S39: 4 | U39: 1 | AC39: John Martin Ysaac | AD39: Tech | AE39: Ridebox Dployment at alfamart | AI39: DONE
A40: 20260000039 | B40: 46069.435 | C40: jguce@nrdev.ph | D40: Test / Demo Unit | E40: Delivery | F40: Pilipinas Messerve | G40: 90 Congressional Ave., Brgy. Bahay Toro Project 8, Quezon City | H40: 46071 | I40: 0.625 | J40: Jaylord Duhaylungsod | K40: +639392535263 | P40: 2 | S40: 4 | T40: 2 | AC40: Judielle Guce | AD40: Project Management & Compliance | AI40: DONE
...

Sheet RS for Spare
D2: REQUISITION SLIP
B3: REQUESTOR DETAILS: | H3: RS #: | I3: 20260000203
B5: Date Requested: | D5: =VLOOKUP($I$3,'Form Responses 1'!$A$2:$AH$308,2,FALSE()) -> 46226.489
B6: Requesting Dept: | D6: =VLOOKUP($I$3,'Form Responses 1'!$A$2:$AH$308,30,FALSE()) -> Product & Quality Management
B7: Requestor Name: | D7: =VLOOKUP($I$3,'Form Responses 1'!$A$2:$AH$308,29,FALSE()) -> Christopher Mendoza
B8: Requestor Email: | D8: =VLOOKUP($I$3,'Form Responses 1'!$A$2:$AH$308,3,FALSE()) -> cmendoza@nrdev.ph
B9: Purpose: | D9: =VLOOKUP($I$3,'Form Responses 1'!$A$2:$AH$308,4,FALSE()) -> Others
B10: REQUEST(S):
B12: No. | C12: ITEM CODE | E12: Description | G12: Qty | H12: UoM | I12: Stock
B13: 1 | C13: ESP00005 | E13: Speedomoter Panel (R280/Sport) | G13: 1 | H13: =IFNA(VLOOKUP($C13,'Item Code E88'!$D$2:$E$405,2,FALSE),"") -> pc | I13: Available
B14: 2 | I14: =IF(H14<>"","Available","")
B15: 3 | I15: =IF(H15<>"","Available","")
B16: 4 | I16: =IF(H16<>"","Available","")
B17: 5 | H17: =IFNA(VLOOKUP($C17,'Item Code E88'!$D$2:$E$405,2,FALSE),"") | I17: =IF(H17<>"","Available","")
B18: 6 | H18: =IFNA(VLOOKUP($C18,'Item Code E88'!$D$2:$E$405,2,FALSE),"") | I18: =IF(H18<>"","Available","")
B19: 7 | H19: =IFNA(VLOOKUP($C19,'Item Code E88'!$D$2:$E$405,2,FALSE),"") | I19: =IF(H19<>"","Available","")
B20: 8 | H20: =IFNA(VLOOKUP($C20,'Item Code E88'!$D$2:$E$405,2,FALSE),"") | I20: =IF(H20<>"","Available","")
B21: 9 | H21: =IFNA(VLOOKUP($C21,'Item Code E88'!$D$2:$E$405,2,FALSE),"") | I21: =IF(H21<>"","Available","")
B22: 10 | H22: =IFNA(VLOOKUP($C22,'Item Code E88'!$D$2:$E$405,2,FALSE),"") | I22: =IF(H22<>"","Available","")
B23: 11 | H23: =IFNA(VLOOKUP($C23,'Item Code E88'!$D$2:$E$405,2,FALSE),"") | I23: =IF(H23<>"","Available","")
B24: 12 | H24: =IFNA(VLOOKUP($C24,'Item Code E88'!$D$2:$E$405,2,FALSE),"") | I24: =IF(H24<>"","Available","")
B25: 13 | H25: =IFNA(VLOOKUP($C25,'Item Code E88'!$D$2:$E$405,2,FALSE),"") | I25: =IF(H25<>"","Available","")
B26: 14 | H26: =IFNA(VLOOKUP($C26,'Item Code E88'!$D$2:$E$405,2,FALSE),"") | I26: =IF(H26<>"","Available","")
B27: 15 | H27: =IFNA(VLOOKUP($C27,'Item Code E88'!$D$2:$E$405,2,FALSE),"") | I27: =IF(H27<>"","Available","")
B28: 16
B29: 17
B30: OTHER REQUEST(S):
B32: =VLOOKUP($I$3,'Form Responses 1'!$A$2:$AI$308,31,FALSE()) -> Replacement for Meserve unit
B34: OVERALL REMARKS:
B36: =VLOOKUP($I$3,'Form Responses 1'!$A$2:$AH$308,34,FALSE())
B38: DELIVERY DETAILS:
B40: Delivery Address: | D40: =VLOOKUP($I$3,'Form Responses 1'!$A$2:$AB$308,7,FALSE()) -> 90 Congressional Ave. Brgy. Bahay Toro Proj8 QC
B41: Delivery Date: | D41: =VLOOKUP($I$3,'Form Responses 1'!$A$2:$AB$308,8,FALSE()) -> 46226
B42: Delivery Time: | D42: =VLOOKUP($I$3,'Form Responses 1'!$A$2:$AB$308,9,FALSE()) -> 0.625
B43: Recipient Name: | D43: =VLOOKUP($I$3,'Form Responses 1'!$A$2:$AB$308,10,FALSE()) -> Christopher C. Mendoza
B44: Recipient Number: | D44: =VLOOKUP($I$3,'Form Responses 1'!$A$2:$AB$308,11,FALSE()) -> 09608978870
B45: Recipient Email: | D45: =VLOOKUP($I$3,'Form Responses 1'!$A$2:$AB$308,3,FALSE()) -> cmendoza@nrdev.ph
B46: REQUESTED BY: | E46: APPROVED BY: (REQUESTOR DEPT HEAD) | H46: APPROVED BY: (SUPPLY CHAIN HEAD)
B48: Signature: | E48: Signature: | G48: Signature:
B49: Name: | D49: =VLOOKUP($I$3,'Form Responses 1'!$A$2:$AG$308,29,FALSE()) -> Christopher Mendoza | E49: Name: | F49: =VLOOKUP($D$49,'Item Code E88'!$G$2:$J$1000,3,FALSE()) -> Mac Fernando Lubi | G49: Name: | H49: Judy Joy Rosare
...

Sheet RS
D2: REQUISITION SLIP
B3: REQUESTOR DETAILS: | H3: RS #: | I3: 20260000206
B5: Date Requested: | D5: =VLOOKUP($I$3,'Form Responses 1'!$A$2:$AH$308,2,FALSE()) -> 46230.686
B6: Requesting Dept: | D6: =VLOOKUP($I$3,'Form Responses 1'!$A$2:$AH$308,30,FALSE()) -> Sales
B7: Requestor Name: | D7: =VLOOKUP($I$3,'Form Responses 1'!$A$2:$AH$308,29,FALSE()) -> Emmanuele Rapatan
B8: Requestor Email: | D8: =VLOOKUP($I$3,'Form Responses 1'!$A$2:$AH$308,3,FALSE()) -> erapatan@nrdev.ph
B9: Purpose: | D9: =VLOOKUP($I$3,'Form Responses 1'!$A$2:$AH$308,4,FALSE()) -> Test / Demo Unit
B10: REQUEST(S):
B12: No. | C12: ITEM CODE | E12: Description | G12: Qty | H12: UoM | I12: Stock
B13: 1 | C13: =IFERROR(VLOOKUP(E13, 'Item Code E88'!$C$1:$D$1000, 2, FALSE), "") -> D400BLU4000 | E13: =IFERROR(__xludf.DUMMYFUNCTION("TRANSPOSE( FILTER(Formula!C3:Z3, (Formula!C4:Z4<>"""")*(Formula!C4:Z4<>0)))"),"MC - D400 Blue") -> MC - D400 Blue | G13: =IFERROR(__xludf.DUMMYFUNCTION("TRANSPOSE( FILTER(Formula!C4:Z4, (Formula!C4:Z4<>"""")*(Formula!C4:Z4<>0)))"),10.0) -> 10 | H13: =IFNA(VLOOKUP($C13,'Item Code E88'!$D$2:$E$405,2,FALSE),"") -> unit | I13: =IF(H13<>"","Available","") -> Available
B14: 2 | C14: =IFERROR(VLOOKUP(E14, 'Item Code E88'!$C$1:$D$1000, 2, FALSE), "") -> ESP00263 | E14: =IFERROR(__xludf.DUMMYFUNCTION("""COMPUTED_VALUE"""),"RideBox Battery") -> RideBox Battery | G14: =IFERROR(__xludf.DUMMYFUNCTION("""COMPUTED_VALUE"""),20.0) -> 20 | H14: =IFNA(VLOOKUP($C14,'Item Code E88'!$D$2:$E$405,2,FALSE),"") -> pc | I14: =IF(H14<>"","Available","") -> Available
B15: 3 | C15: =IFERROR(VLOOKUP(E15, 'Item Code E88'!$C$1:$D$1000, 2, FALSE), "") -> BATCH8A | E15: =IFERROR(__xludf.DUMMYFUNCTION("""COMPUTED_VALUE"""),"RideBox Charger") -> RideBox Charger | G15: =IFERROR(__xludf.DUMMYFUNCTION("""COMPUTED_VALUE"""),10.0) -> 10 | H15: =IFNA(VLOOKUP($C15,'Item Code E88'!$D$2:$E$405,2,FALSE),"") -> pc | I15: =IF(H15<>"","Available","") -> Available
B16: 4 | C16: =IFERROR(VLOOKUP(E16, 'Item Code E88'!$C$1:$D$1000, 2, FALSE), "") | H16: =IFNA(VLOOKUP($C16,'Item Code E88'!$D$2:$E$405,2,FALSE),"") | I16: =IF(H16<>"","Available","")
B17: 5 | C17: =IFERROR(VLOOKUP(E17, 'Item Code E88'!$C$1:$D$1000, 2, FALSE), "") | H17: =IFNA(VLOOKUP($C17,'Item Code E88'!$D$2:$E$405,2,FALSE),"") | I17: =IF(H17<>"","Available","")
B18: 6 | C18: =IFERROR(VLOOKUP(E18, 'Item Code E88'!$C$1:$D$1000, 2, FALSE), "") | H18: =IFNA(VLOOKUP($C18,'Item Code E88'!$D$2:$E$405,2,FALSE),"") | I18: =IF(H18<>"","Available","")
B19: 7 | C19: =IFERROR(VLOOKUP(E19, 'Item Code E88'!$C$1:$D$1000, 2, FALSE), "") | H19: =IFNA(VLOOKUP($C19,'Item Code E88'!$D$2:$E$405,2,FALSE),"") | I19: =IF(H19<>"","Available","")
B20: 8 | C20: =IFERROR(VLOOKUP(E20, 'Item Code E88'!$C$1:$D$1000, 2, FALSE), "") | H20: =IFNA(VLOOKUP($C20,'Item Code E88'!$D$2:$E$405,2,FALSE),"") | I20: =IF(H20<>"","Available","")
B21: 9 | C21: =IFERROR(VLOOKUP(E21, 'Item Code E88'!$C$1:$D$1000, 2, FALSE), "") | H21: =IFNA(VLOOKUP($C21,'Item Code E88'!$D$2:$E$405,2,FALSE),"") | I21: =IF(H21<>"","Available","")
B22: 10 | C22: =IFERROR(VLOOKUP(E22, 'Item Code E88'!$C$1:$D$1000, 2, FALSE), "") | H22: =IFNA(VLOOKUP($C22,'Item Code E88'!$D$2:$E$405,2,FALSE),"") | I22: =IF(H22<>"","Available","")
B23: 11 | C23: =IFERROR(VLOOKUP(E23, 'Item Code E88'!$C$1:$D$1000, 2, FALSE), "") | H23: =IFNA(VLOOKUP($C23,'Item Code E88'!$D$2:$E$405,2,FALSE),"") | I23: =IF(H23<>"","Available","")
B24: 12 | C24: =IFERROR(VLOOKUP(E24, 'Item Code E88'!$C$1:$D$1000, 2, FALSE), "") | H24: =IFNA(VLOOKUP($C24,'Item Code E88'!$D$2:$E$405,2,FALSE),"") | I24: =IF(H24<>"","Available","")
B25: OTHER REQUEST(S):
B27: =VLOOKUP($I$3,'Form Responses 1'!$A$2:$AI$308,31,FALSE())
B29: OVERALL REMARKS:
B31: =VLOOKUP($I$3,'Form Responses 1'!$A$1:$AI$308,34,FALSE())
B33: FULFILLMENT DETAILS:
B35: Fulfillment Method: | D35: =VLOOKUP($I$3,'Form Responses 1'!$A$2:$AB$308,5,FALSE()) -> Pickup
B36: Company/Client: | D36: =VLOOKUP($I$3,'Form Responses 1'!A1:AB2139,6,FALSE()) -> Angkas
B37: Address: | D37: =VLOOKUP($I$3,'Form Responses 1'!$A$2:$AB$308,7,FALSE()) -> Pick up at E88 Ventures Asgard Warehouse
B38: Delivery/Pick up Date: | D38: =VLOOKUP($I$3,'Form Responses 1'!$A$2:$AB$308,8,FALSE()) -> 46234
B39: Delivery/Pick up Time: | D39: =VLOOKUP($I$3,'Form Responses 1'!$A$2:$AB$308,9,FALSE()) -> 0.375
B40: Recipient Name: | D40: =VLOOKUP($I$3,'Form Responses 1'!$A$2:$AB$308,10,FALSE()) -> Ron Dela Cruz
B41: Recipient Number: | D41: =VLOOKUP($I$3,'Form Responses 1'!$A$2:$AB$308,11,FALSE()) -> +639177680944
B42: REQUESTED BY: | E42: APPROVED BY: (REQUESTOR DEPT HEAD) | G42: APPROVED BY: (SUPPLY CHAIN HEAD)
B44: Signature: | E44: Signature: | G44: Signature:
B45: Name: | D45: =VLOOKUP($I$3,'Form Responses 1'!$A$2:$AG$308,29,FALSE()) -> Emmanuele Rapatan | E45: Name: | F45: =VLOOKUP(D45,'Item Code E88'!$G$1:$I$900,3,FALSE()) -> Samuel Kniazeff Jr | G45: Name: | H45: Judy Joy Rosare
B46: Position: | D46: =VLOOKUP(D45,'Item Code E88'!$G$1:$I$900,2,FALSE()) -> Sales Admin | E46: Position: | F46: =VLOOKUP(F45,'Item Code E88'!$I$1:$J$900,2,FALSE()) -> Operations & Product Director | G46: Position: | H46: Logistics Expert
B47: Date: | D47: =D5 -> 46230.686 | E47: Date: | G47: Date:

Sheet Item Code  E88
A1: ITEM CODE | B1: ITEM DESCRIPTION | C1: REQUISITION | D1: ITEM CODE | E1: UOM | G1: Employee | H1: Position | I1: Manager | J1: Position
A2: R280SPRED2500 | B2: R280 Sport 2500W Red | C2: MC - R280 Sport Red | D2: R280SPRED2500 | E2: unit | G2: Ian Gabrielle Jimenez | H2: Senior IoT Engineer | I2: Ferdinand Yanto III | J2: Chief Technology Officer
A3: R280SPBLU2500 | B3: R280 Sport 2500W Blue | C3: MC - R280 Sport Blue | D3: R280SPBLU2500 | E3: unit | G3: John Martin Ysaac | H3: IoT Engineer | I3: Ferdinand Yanto III | J3: Chief Technology Officer
A4: R280WHI2000 | B4: R280 2000W White | C4: MC - R280 White | D4: R280WHI2000 | E4: unit | G4: Haide Garcia | H4: HR Manager
A5: R280BLA2000 | B5: R280 2000W Black | C5: MC - R280 Black | D5: R280BLA2000 | E5: unit | G5: Samuel Kniazeff Jr | H5: Operations & Product Director
A6: D400RED4000 | B6: D400 4000W Red | C6: MC - D400 Red | D6: D400RED4000 | E6: unit | G6: Christopher Mendoza | H6: Sr. Mechanic | I6: Mac Fernando Lubi | J6: After Sales Manager
A7: D400BLU4000 | B7: D400 4000W Blue | C7: MC - D400 Blue | D7: D400BLU4000 | E7: unit | G7: Judielle Guce | H7: Project Management Officer
A8: D400BLK4000 | B8: D400 4000W Black | C8: MC - D400 Black | D8: D400BLK4000 | E8: unit | G8: Jhon Emmanuel Usi | H8: IoT Engineer | I8: Ferdinand Yanto III | J8: Chief Technology Officer
A9: R280V2WHI2000 | B9: R280 2000W White V2 | C9: MC - R280 White | D9: R280V2WHI2000 | E9: unit | G9: Crisanta Pagador | H9: Sales Admin | I9: Samuel Kniazeff Jr | J9: Operations & Product Director
A10: ESP00291 | B10: RideBox Rack | C10: RideBox Rack | D10: ESP00291 | E10: pc | G10: Arby Mostrales | H10: Warehouse Expert
A11: ESP00262 | B11: RideBox Locker | C11: RideBox Locker | D11: ESP00262 | E11: pc | G11: Erwin Javillonar | H11: CS Supervisor | I11: Samuel Kniazeff Jr | J11: Operations & Product Director
A12: ESP00263 | B12: RideBox Battery (Ampace) | C12: RideBox Battery | D12: ESP00263 | E12: pc | G12: Emmanuele Rapatan | H12: Sales Admin | I12: Samuel Kniazeff Jr | J12: Operations & Product Director
A13: ESP00073 | B13: Glove Box (R280/Sport) | D13: ESP00073 | E13: pc | G13: Mac Fernando Lubi | H13: After Sales Manager | I13: Samuel Kniazeff Jr | J13: Operations & Product Director
A14: ESP00104 | B14: Rear Bottom cover (R280/Sport) | D14: ESP00104 | E14: pc | G14: Sam Lim Jr. | H14: Sales & Marketing Manager | I14: Samuel Kniazeff Jr | J14: Operations & Product Director
A15: ESP00120 | B15: Central Cover (R280/Sport) | D15: ESP00120 | E15: pc | G15: Roy Patrick Nepomuceno | H15: RideBox Manager
A16: ESP00103 | B16: Head Light (R280/Sport) | D16: ESP00103 | E16: pc
A17: ESP00124 | B17: Front Panel (R280 Black) | D17: ESP00124 | E17: pc
A18: ESP00125 | B18: Front Panel (R280 White) | D18: ESP00125 | E18: pc
A19: ESP00123 | B19: Front Panel (R280 Sport Blue) | D19: ESP00123 | E19: pc
A20: ESP00122 | B20: Front Panel (R280 Sport Red) | D20: ESP00122 | E20: pc
A21: ESP00276 | B21: Front Panel v2(R280 White) | D21: ESP00276 | E21: pc
A22: ESP00113 | B22: Seat (R280/Sport) | D22: ESP00113 | E22: pc
A23: ESP00281 | B23: Seat v2 (R280/Sports) | D23: ESP00281 | E23: pc
A24: ESP00178 | B24: Front Panel (D400) | D24: ESP00178 | E24: pc
A25: ESP00167 | B25: Right Decorative Panel (D400 Blue) | D25: ESP00167 | E25: pc
A26: ESP00169 | B26: Left Decorative Panel (D400 Blue) | D26: ESP00169 | E26: pc
A27: ESP00173 | B27: Left Front Protective Panel (D400 Blue) | D27: ESP00173 | E27: pc
... A51: ESP00246 | B51: Hub Motor (R280 Sport) - 75KM/H | D51: ESP00246 | E51: pc
A52: BATCH8A | B52: Battery Charger 8A | C52: RideBox Charger | D52: BATCH8A | E52: pc
A53: EFS00009 | B53: Helmet | C53: Helmet | D53: EFS00009 | E53: pc
A54: EFS00014 | B54: Acrylic temporary plate -OKLA | D54: EFS00014 | E54: pc
A55: ESP00137 | B55: Rear Tire 110/80-14 (D400) | D55: ESP00137 | E55: pc
A56: ESP00138 | B56: Front Tire 110-80-16 (D400) | D56: ESP00138 | E56: pc
A57: ESP00149 | B57: Front Wheel (D400) | D57: ESP00149 | E57: pc
A58: ESP00150 | B58: Rear Wheel (D400) | D58: ESP00150 | E58: pc
A59: ESP00139 | B59: Side Motor (D400) | D59: ESP00139 | E59: pc
A60: ESP00151 | B60: Foot Pedal (D400) | D60: ESP00151 | E60: pc
A61: ESP00141 | B61: Tool Box (D400) | D61: ESP00141 | E61: pc
A62: ESP00142 | B62: Rear Luggage Carrier Protective Part (D400) | D62: ESP00142 | E62: pc
A63: ESP00145 | B63: Right Side Body Protective Cover (D400) | D63: ESP00145 | E63: pc
...

Sheet CO
D2: CHANGE ORDER
B3: REQUESTOR DETAILS: | H3: CO #:
B5: Date Requested:
B6: Requesting Dept:
B7: Requestor Name:
B8: Requestor Email:
B9: Purpose:
B10: CHANGE REQUEST(S):
E11: Original | F11: Proposed
C12: Change Item Code
C13: Change Description
C14: Change Quantity
C15: Change Fulfillment Method
C16: Change Fulfillment Date
C17: Change Address
B20: OTHER REQUEST(S):
B24: OVERALL REMARKS:
B28: REQUESTED BY: | E28: APPROVED BY (DEPT HEAD): | G28: APPROVED BY:
B30: Signature: | E30: Signature: | G30: Signature:
B31: Name: | E31: Name: | G31: Name: | H31: GREG RIVERA
B32: Position: | E32: Position: | G32: Position: | H32: CHIEF COMMERCIAL OFFICER
B33: Date: | D33: =D5 | E33: Date: | G33: Date:

Sheet Formula
A1: REQ ID | B1: =RS!I3 -> 20260000206
B2: Code
A3: REQUESTS | B3: Unit | C3: MC - R280 White | D3: MC - R280 Black | E3: MC - R280 Sport Red | F3: MC - R280 Sport Blue | G3: MC - D400 Red | H3: MC - D400 Blue | I3: MC - D400 Black | J3: RideBox Battery | K3: RideBox Charger | L3: RideBox Locker | M3: RideBox Rack | N3: Battery & Charger | O3: Qty per set | P3: Helmet | Q3: Charging Kit | R3: Spareparts/Qty
B4: Qty | C4: =IFERROR(__xludf.DUMMYFUNCTION("FILTER('Form Responses 1'!L2:AA1001,'Form Responses 1'!A2:A1001 = $B1) "),"") | H4: =IFERROR(__xludf.DUMMYFUNCTION("""COMPUTED_VALUE"""),10.0) -> 10 | J4: =IFERROR(__xludf.DUMMYFUNCTION("""COMPUTED_VALUE"""),20.0) -> 20 | K4: =IFERROR(__xludf.DUMMYFUNCTION("""COMPUTED_VALUE"""),10.0) -> 10
